Workbook

Sheet Read Me
A1: SHOULDER ASSESSMENT & MANAGEMENT PROGRAMME
A2: Screen → clear the neck → pain, stiffness or instability? → cluster → load by irritability → discharge on capacity and control.
A4: SHEET | B4: WHAT IT DOES | C4: WHEN TO USE IT | D4: SOURCE
A5: Master Matrix | B5: 40 conditions built on your diagnostics algorithm's exact column structure (Region → Activity Level → Symptoms → Age → Onset → Predominance → Condition → High-Yield Question → Special Test + Imaging → Biomechanical Cause → Desired Activity Goal → Physiotherapy Specific Exercise), then extended with pain mechanism, classification, red-flag status, management emphasis, loading dose, biomechanical corrections, adjuncts, advanced options, outcomes, markers, timeline and referral triggers. | C5: The core reference. Filter column A by region or column O by red-flag status. | D5: Your algorithm (27 rows) + Course Manual (13 added)
A6: Rx Generator | B6: Pick a condition from the dropdown and the full prescription is pulled live from the Master Matrix. | C6: In clinic, or to print a plan into the patient file. | D6: Live INDEX/MATCH
A7: Assessment Roadmap | B7: The manual's five-gate sequence, built around the pain / stiffness / instability triage at Gate 3. | C7: Every new patient, in order. | D7: Course Manual Module 9
A8: Subjective Exam | B8: Fillable history template with the manual's screening questions built in. | C8: First consultation. | D8: Module 4
A9: Objective Exam | B9: Fillable examination template: observation, palpation map, range, cuff strength, scapula, instability, cervical screen. | C9: First consultation and every re-assessment. | D9: Module 5
A10: Special Tests | B10: 30 tests with what a positive means and how much weight to give it. | C10: During the physical examination. | D10: Module 6
A11: Clusters & Classification | B11: The three clusters, the one-line differentiators, and the RCRSP umbrella, Stanmore poles, frozen-shoulder stages and tendinopathy continuum. | C11: When the picture is not yet clear, and when choosing a management pathway. | D11: Modules 6 and 7
A12: Imaging Guide | B12: When to image, which modality answers which question, and the interpretation traps. | C12: Before requesting or when reading a report. | D12: Module 8
A13: Phased Programme | B13: Phase 0-4 with goals, content, markers and exit criteria, plus the master treatment sequence. | C13: Building and progressing every plan. | D13: Modules 11 and 15
A14: Exercise & Dosage | B14: Loading library with dose and indication, including motor-control retraining for Polar III. | C14: Writing the actual programme. | D14: Module 11 and Appendix B
A15: Adjuncts & Advanced | B15: Education, manual therapy, taping, ESWT, barbotage, hydrodilatation, injection and surgery, with the sequencing rule. | C15: When loading alone is not enough. | D15: Modules 12 and 13
... A24: References | B24: Guideline and trial sources. | C24: Verifying or citing. | D24: Manual reference list
A26: WHAT CHANGED IN THIS UPDATE
A27: • YOUR ALGORITHM IS THE SPINE. The Master Matrix keeps your 27 conditions in your original order and column structure. The two columns you left blank — "Desired activity goal" and "Physiotherapy specific exercise" — are now populated for every row, as is "Activity Level" and the incomplete "Underlying biomechanical cause" column.
A28: • 13 conditions from the Course Manual have been added below your 27: calcific tendinopathy, acute traumatic cuff tear, subscapularis tear, post-traumatic/post-surgical stiffness, Stanmore Polar II and Polar III instability, neuralgic amyotrophy, thoracic outlet syndrome, referred visceral/malignant pain, septic arthritis, proximal humeral fracture, GIRD and clavicle fracture. Added rows are marked ADD in the SOURCE column.
A29: • TERMINOLOGY UPDATED: your "Subacromial Impingement" row is retitled RCRSP, following the manual's shift to the rotator cuff-related shoulder pain umbrella — subacromial space size correlates poorly with pain, and decompression is no better than placebo (CSAW).
A30: • THE DEFINING SHOULDER TRAP: pain NOT reproducible on examination is a referral, not a rehabilitation problem. THE SECOND: screen the cervical spine in every shoulder presentation.
A31: • THE MOST USEFUL SINGLE DISCRIMINATOR: a true capsular block to passive external rotation WITH AN INTACT CUFF is frozen shoulder or OA, not RCRSP.
A32: • READ IRRITABILITY: load RCRSP into acceptable pain (<=5/10 settling within 24 h), but do not force an irritable capsule. Getting this wrong is the commonest management error in the shoulder.
A33: • Yellow cells are inputs. Green text is pulled from another sheet. Do not overwrite formula cells.

Sheet Master Matrix
A1: MASTER DIAGNOSTIC & MANAGEMENT MATRIX — 40 SHOULDER CONDITIONS
A2: Columns B–M follow your diagnostics algorithm exactly, with Activity Level, Biomechanical Cause, Desired Activity Goal and Physiotherapy Specific Exercise now completed. Columns N–Z add the management programme.
A3: Source | B3: Region | C3: Activity Level | D3: Common Symptoms | E3: Age Group | F3: Onset | G3: Predominance | H3: Condition | I3: High-Yield Diagnostic Question | J3: Special Test + Imaging | K3: Underlying Biomechanical Cause | L3: DESIRED ACTIVITY GOAL | M3: PHYSIOTHERAPY SPECIFIC EXERCISE | N3: Pain Mechanism | O3: Classification / Cluster | P3: Red Flag Status | Q3: MANAGEMENT EMPHASIS | R3: Loading Stage & Entry Dose | S3: BIOMECHANICAL CORRECTIONS & KINETIC CHAIN | T3: Manual Therapy, Taping & Adjuncts | U3: Advanced / Surgical Options | V3: Outcome Measures | W3: Re-testable Markers | X3: Expected Timeline | Y3: Referral / Surgical Trigger | Z3: Evidence Anchor
A4: SRC | B4: Anterior | C4: Overhead worker, painter, gym lifter, swimmer; also sedentary after a sudden load spike | D4: Pain lifting arm overhead | E4: 20-60 | F4: Slow | G4: Equal | H4: Subacromial Impingement (now: RCRSP) | I4: Does lifting the arm overhead increase pain? | J4: Neer/Hawkins + MRI | K4: Supraspinatus weak, scapular dyskinesis, posterior capsule tightness, hooked acromion, thoracic kyphosis, poor overhead mechanics | L4: Pain-free overhead reach and sustained above-shoulder work; return to pressing and swimming volume | M4: Isometric cuff holds 5 x 30-45 s for analgesia; band external and internal rotation 3-4 sets 8-12 RM 3x/week; full can in the scapular plane; serratus wall slides and punches; prone Y and T for lower trapezius; thoracic extension over a roller; progressive overhead press and scaption loading | N4: Nociceptive (load-related); nociplastic overlay if persistent beyond 6 months | O4: Cluster 1 - RCRSP umbrella (replaces 'impingement'). Subacromial space size correlates poorly with pain | P4: No | Q4: Education + progressive cuff and scapular loading is first-line (GRASP). Load into acceptable pain (<=5/10 settling within 24 h) - pain-free is not required. Avoid routine decompression surgery (CSAW); corticosteroid gives short-term benefit only | R4: Stage 1-2. Isometric/low-load cuff activation for irritability, then heavy slow resistance 3-4 sets 8-12 RM, 3 s up / 3 s down, 2-3x/week; progress to functional and overhead loading | S4: Restore the elevation chain: thoracic extension and rotation, scapular upward rotation and posterior tilt (serratus anterior, lower trapezius), cuff endurance not just peak strength; modify overhead work volume, bench and pressing technique, and workstation height | T4: Scapular taping or cueing to unlock better movement; manual therapy as an adjunct only; activity and ergonomic modification is central | U4: If stalled beyond 12 weeks: guided subacromial corticosteroid injection to enable loading; NMES where activation is poor. Decompression is NOT indicated | V4: SPADI; QuickDASH; Oxford Shoulder Score; night-pain score | W4: Pain-free elevation range; painful arc; night pain score; external rotation strength; overhead tolerance | X4: 12 weeks for meaningful change; 3-6 months for full overhead capacity | Y4: True weakness with a lag sign; trauma; no response to 12 weeks of well-delivered loading | Z4: GRASP (Lancet 2021); CSAW (Lancet 2018); Lewis RCRSP
A5: SRC | B5: Anterior | C5: Manual worker or older adult; often after a fall or a sudden lift | D5: Night pain and weakness | E5: 40-70 | F5: Sudden | G5: Male | H5: Rotator Cuff Tear | I5: Do you have difficulty lifting the arm with night pain? | J5: Empty Can + MRI | K5: Degenerative tendon change plus a load event; loss of the cuff force couple allowing superior humeral migration; deltoid over-dominance; scapular and thoracic contribution | L5: Restore active elevation and the ability to lift and carry; sleep on the affected side again | M5: Supported (supine then inclined) cuff and deltoid activation; NMES if voluntary activation is poor; band external and internal rotation progressing to 3-4 sets 8-12 RM; anterior deltoid retraining for elevation; serratus and lower trapezius loading; graded upright and overhead progression | N5: Nociceptive - structural; nociplastic overlay in long-standing cases | O5: Rotator cuff group. Classify by size, retraction, muscle quality (Goutallier) and whether traumatic or degenerative | P5: Screen: SUDDEN significant weakness after trauma = acute traumatic tear, a time-sensitive surgical referral. Do not simply wait and see | Q5: For a DEGENERATIVE tear: structured loading is first-line and many do well without surgery. For an ACUTE TRAUMATIC tear: timely surgical assessment - a repair window exists and outcomes decline with delay | R5: Stage 1-2 in supported positions first; progressive cuff, deltoid and scapular loading 3x/week; graded elevation range as strength allows. Post-repair: follow the surgeon's protocol (see Post-Surgical Guide) | S5: Rebuild the compensatory strategy: anterior deltoid as elevator, scapular upward rotators, thoracic extension, remaining cuff endurance to keep the head centred; modify overhead demands at home and work | T5: Sling only post-operatively; taping for feedback; activity modification; sleep positioning for night pain | U5: Guided corticosteroid injection for short-term relief to enable loading; surgical repair for an acute traumatic tear or a selected functionally limiting tear; reverse arthroplasty for a massive irreparable tear with arthropathy | V5: ASES; Constant-Murley; SPADI; night-pain score | W5: Active elevation range; lag signs; external rotation and abduction strength LSI; night pain frequency | X5: 12 weeks conservative trial; 6-9 months post repair | Y5: Sudden weakness after trauma; progressive weakness; failure of a well-delivered 12-week programme | Z5: Manual Module 10 (#5-6); Kuhn/MOON conservative pathway
A6: SRC | B6: Anterior | C6: Overhead thrower, volleyball, tennis, cricket; also a fall on an outstretched hand | D6: Pain during throwing | E6: 15-35 | F6: Sudden/Slow | G6: Male athletes | H6: SLAP Lesion | I6: Do you feel deep shoulder pain during throwing? | J6: O'Brien test + MR Arthrogram | K6: Peel-back of the superior labrum in late cocking from repetitive traction and torsion; GIRD and posterior capsule tightness, scapular dyskinesis, and a poor kinetic chain increase the load reaching the labrum | L6: Return to full-velocity throwing or serving with restored control and velocity | M6: Sleeper and cross-body stretches for GIRD (technique matters); posterior cuff eccentric loading; scapular retraining (serratus, lower trapezius); thoracic and hip rotation mobility; trunk and lower-body drive work; medicine-ball plyometrics; staged interval throwing programme | N6: Nociceptive - mechanical | O6: Overhead athlete group; assess alongside GIRD, internal impingement and scapular dyskinesis - they travel together | P6: No | Q6: Rehabilitation of the cuff, scapula and kinetic chain is first-line for most - these are usually the actual drivers. Surgical opinion selectively; SLAP repair has inconsistent results in throwers and tenodesis is often preferred over 35 | R6: Stage 1-2 addressing GIRD and scapular control; avoid provocative late-cocking positions early; progress to plyometric loading then an interval throwing programme | S6: Fix the throwing chain: correct GIRD and posterior capsule tightness, restore scapular upward rotation and posterior tilt, build posterior cuff and periscapular endurance, restore thoracic and hip rotation, and increase lower-body and trunk contribution to the throw | T6: Manual therapy for the posterior capsule; scapular taping for feedback | U6: Arthroscopic SLAP repair (6 weeks protection; return to sport 6-9 months) or biceps tenodesis in the over-35s and non-throwers | V6: KJOC; ASES; WOSI; throwing velocity and control | W6: O'Brien response; internal rotation range and GIRD; total rotational arc; throwing tolerance | X6: 12 weeks conservative trial; 6-9 months to competitive throwing post-surgery | Y6: Failure of a well-delivered 3-month programme addressing GIRD and the kinetic chain; mechanical block | Z6: Manual Module 10 (#17); SLAP repair outcome literature
A7: SRC | B7: Anterior | C7: Gym lifter with heavy pressing and curling volume; overhead athlete | D7: Pain in front of shoulder | E7: 20-50 | F7: Slow | G7: Male | H7: Biceps Tendinopathy | I7: Is pain located in the front groove of the shoulder? | J7: Speed/Yergason + Ultrasound | K7: Repetitive tensile load on a tendon stabilised by the biceps pulley; often coexists with cuff or subscapularis pathology; scapular and thoracic deficits raise the demand | L7: Return to pressing, curling and overhead lifting without anterior pain | M7: Isometric elbow flexion and shoulder elevation holds; progressive isotonic biceps loading 3-4 sets 8-12 RM 3x/week; cuff external and internal rotation loading; serratus and lower trapezius work; thoracic extension mobility; graded overhead and pressing reintroduction | N7: Nociceptive - tensile tendon load | O7: AC/clavicle/biceps group; rarely isolated - always screen the cuff, pulley and labrum | P7: No | Q7: Load management and cuff/scapular rehabilitation; treat the underlying cuff or pulley pathology, because isolated biceps treatment usually fails. Surgical opinion (tenotomy or tenodesis) selectively | R7: Stage 1-2. Isometric for analgesia, then progressive isotonic biceps and cuff loading; then overhead and sport-specific loading | S7: Reduce the demand on the tendon: scapular upward rotation and posterior tilt, thoracic extension, cuff endurance; correct pressing and overhead technique and weekly volume distribution | T7: Short-term activity modification; taping; manual therapy as an adjunct | U7: Guided injection into the sheath (not the tendon substance); biceps tenodesis (4-6 weeks protection) or tenotomy (1-2 weeks) if refractory or with a pulley/subscapularis lesion | V7: SPADI; QuickDASH; ASES | W7: Bicipital groove tenderness; resisted elevation pain; pressing and overhead load tolerance | X7: 12 weeks minimum | Y7: Failure after 12 weeks of correct loading; suspected pulley lesion or subscapularis tear | Z7: Manual Module 10 (#19)
A8: SRC | B8: Anterior | C8: Middle-aged lifter or manual worker; usually on a background of chronic tendinopathy | D8: Sudden deformity | E8: 20-50 | F8: Sudden | G8: Male | H8: Long Head Biceps Rupture | I8: Did you notice a sudden pop with bulging arm muscle? | J8: Clinical + Ultrasound | K8: Failure of a chronically degenerate tendon under load; the underlying problem is usually cuff and pulley pathology, not the biceps itself | L8: Return to normal lifting and gym activity; accept the cosmetic change | M8: Progressive elbow flexion and supination loading from comfort; full loading by 6 weeks; cuff external and internal rotation strengthening; scapular and thoracic work to address the underlying driver | N8: Nociceptive - acute rupture, then largely resolved | O8: AC/clavicle/biceps group; the key clinical task is assessing the CUFF, not the biceps | P8: Screen: the associated cuff tear matters far more than the rupture itself | Q8: Reassure - functional loss is minimal in most patients and conservative management is standard. Rehabilitate the cuff and scapula. Tenodesis for cosmesis, cramping, or a young high-demand patient | R8: No protection required. Progressive elbow flexion, supination and cuff loading from comfort; full loading from 6 weeks | S8: Address the underlying cuff and scapular deficits that caused the rupture; restore thoracic extension and overhead capacity | T8: Analgesia and reassurance; compression for ecchymosis | U8: Biceps tenodesis for cosmesis or persistent cramping; cuff repair where the associated tear is significant | V8: QuickDASH; ASES; elbow flexion and supination strength | W8: Elbow flexion and supination strength LSI; cramping frequency | X8: 6-12 weeks conservatively | Y8: Young or high-demand patient; significant associated cuff tear | Z8: Manual Module 10 (#19 group)
A9: SRC | B9: Anterior | C9: Any activity level - frequently no precipitating load event at all; often sedentary | D9: Painful stiffness | E9: 40-65 | F9: Slow | G9: Female | H9: Frozen Shoulder (Adhesive Capsulitis) | I9: Is shoulder movement restricted in all directions? | J9: ROM exam + X-ray/MRI | K9: NOT a load problem - a capsular fibrotic and inflammatory process. Coracohumeral ligament and rotator interval contracture drives the early external rotation loss. Diabetes and thyroid disease are strongly associated | L9: Restore functional reach - dressing, hair, hand behind back - then full range and strength; understand and tolerate the months-long trajectory | M9: STAGE-DEPENDENT. Painful stage: gentle pain-guided pendulum and active-assisted range, low-load isometrics, elbow/wrist/thoracic mobility - do NOT stretch aggressively. Freezing/frozen: progressive end-range stretching in all planes, sustained holds, mobilisation, loaded stretch. Thawing: full range restoration plus progressive cuff and scapular strengthening | N9: Nociceptive - inflammatory in the painful stage; high irritability; nociplastic features common given the duration | O9: Cluster 2 - frozen shoulder. Stage it: (1) painful/pre-adhesive, (2) freezing, (3) frozen, (4) thawing. Stage and irritability direct treatment intensity | P9: Screen: exclude glenohumeral OA, locked posterior dislocation and, rarely, tumour. SCREEN FOR UNDIAGNOSED DIABETES AND THYROID DISEASE | Q9: Stage- and irritability-based care. Painful stage: pain control and gentle range - aggressive stretching backfires. Freezing/frozen: progressive stretching and loading within tolerance. Corticosteroid and hydrodilatation are useful adjuncts, especially early. MUA or capsular release for refractory cases | R9: Match effort to irritability. High irritability: pain-free range only, 5 x 30-45 s low-load isometrics. Low irritability: sustained end-range stretch 3-5 x 30 s several times daily, progressing to loaded stretch and full cuff/scapular strengthening | S9: Preserve and then rebuild: maintain thoracic extension and rotation, scapular mobility and control, and elbow/wrist function; prevent secondary deconditioning; restore scapulohumeral rhythm rather than a shrugging compensation as range returns | T9: Mobilisation and gentle range in the painful stage (low grades only); end-range mobilisation once settled; heat before stretching; sleeping position advice for night pain | U9: Guided intra-articular corticosteroid injection (best evidence EARLY); hydrodilatation for a plateaued shoulder; MUA or arthroscopic capsular release - both followed by IMMEDIATE motion | V9: SPADI; Oxford Shoulder Score; QuickDASH; passive external rotation in degrees | W9: Passive external rotation range; passive elevation; night pain score; functional reach tasks | X9: Painful stage 2-9 months; total course commonly 12-30 months (longer in diabetes) | Y9: Diagnostic uncertainty; plateaued range despite correct stage-based care - consider hydrodilatation or release | Z9: Kelley JOSPT 2013 adhesive capsulitis CPG; Manual Module 10 (#9)
A10: SRC | B10: Anterior | C10: Gym lifter - bench press, dips; also contact sport | D10: Pain after gym/bench press | E10: 20-40 | F10: Sudden | G10: Male | H10: Pectoralis Major Strain / Rupture | I10: Did pain start during pushing or bench press? | J10: MRI | K10: Eccentric overload of the pectoralis major at the musculotendinous junction or humeral insertion during the bottom of a heavy bench press; anabolic steroid use, inadequate warm-up, excessive bar depth and rapid load progression are contributors | L10: Return to full pressing capacity and symmetrical chest contour and strength | M10: Early: pain-free range and isometric adduction holds. Then progressive isotonic pressing and adduction loading 3-4 sets 8-12 RM; scapular and cuff loading throughout; graded return to bench press starting with reduced depth and load; full pressing volume last | N10: Nociceptive - acute muscle/tendon strain or rupture | O10: AC/clavicle/biceps and anterior group; a complete rupture (visible defect, axillary fold change) is a surgical presentation in an active patient | P10: Screen: a complete tendinous rupture in an active patient warrants prompt surgical opinion - outcomes decline with delay | Q10: Partial strain: conservative - relative rest, progressive loading and technique correction. COMPLETE RUPTURE in an active patient: prompt surgical repair; delay compromises the result | R10: Grade-dependent. Partial: isometrics from comfort, progressive isotonic loading from 2-4 weeks. Post-repair: sling 4-6 weeks with protected range, progressive loading 6-12 weeks, full pressing from 12 weeks | S10: Correct the mechanism: reduce bench press depth and load, avoid rapid load progression, improve scapular retraction and set during pressing, balance pushing with pulling volume, and address warm-up practice | T10: Sling short-term post-repair; taping; activity modification | U10: Surgical repair for a complete tendinous rupture (protection 4-6 weeks; return to sport 6-9 months) | V10: QuickDASH; ASES; pressing strength LSI | W10: Adduction strength LSI; pressing load tolerance; contour symmetry | X10: 6-12 weeks for a partial strain; 6-9 months post repair | Y10: Palpable defect, loss of the axillary fold, or marked adduction weakness - refer promptly | Z10: Manual Module 10 (anterior group); pectoralis major repair literature
A11: SRC | B11: Anterior | C11: Contact sport, cycling crash, fall onto the point of the shoulder | D11: Localized joint pain | E11: 20-50 | F11: Sudden | G11: Male | H11: AC Joint Sprain | I11: Does pain increase when bringing arm across chest? | J11: Cross-body adduction + X-ray | K11: Direct force to the acromion driving it inferiorly while the clavicle is held by its sternal attachment, injuring the AC then the coracoclavicular ligaments in sequence | L11: Return to contact sport, overhead work and pressing without pain on top of the shoulder | M11: Early: pain-free range avoiding cross-body adduction; scapular setting. Then progressive scapular retraction and upward rotation loading, cuff external and internal rotation 3-4 sets 8-12 RM, thoracic extension; overhead and pressing load from 6-8 weeks with modified depth | N11: Nociceptive - traumatic | O11: AC group; grade by Rockwood I-VI. I-II conservative, III controversial, IV-VI surgical | P11: Screen: grades IV-VI (posterior, superior or inferior displacement) are surgical. Check skin integrity and neurovascular status | Q11: Grades I-II: conservative - sling for comfort, early range, progressive scapular and cuff loading. Grade III: conservative first-line for most, surgery for high-demand overhead workers who fail. Grades IV-VI: surgical referral | R11: Sling for comfort 1-2 weeks; pain-free range early avoiding cross-body adduction; progressive scapular and cuff loading from 2-4 weeks; overhead and pressing from 6-8 weeks; contact sport 6-12 weeks by grade | S11: Rebuild the girdle around the joint: scapular upward rotators and retractors, cuff capacity, thoracic extension; modify cross-body and overhead loading; correct bench press and dip technique, which load the AC joint heavily | T11: AC joint offloading tape (practically effective for return to sport); sling short-term; avoid prolonged immobilisation | U11: Guided AC joint injection for persistent pain; AC reconstruction for Rockwood IV-VI (6 weeks protection) or coracoclavicular ligament reconstruction for chronic instability | V11: SPADI; QuickDASH; Oxford Shoulder Score | W11: AC tenderness; cross-body adduction pain; overhead and pressing tolerance; step deformity | X11: Grade I 2-4 weeks; grade II 4-6 weeks; grade III 6-12 weeks | Y11: Rockwood IV-VI; grade III in a high-demand overhead worker; persistent pain after 3 months | Z11: Rockwood classification; Manual Module 10 (#18)
A12: SRC | B12: Posterior | C12: Baseball and cricket pitching, tennis serve, volleyball spike, javelin | D12: Pain during follow-through | E12: 15-35 | F12: Slow | G12: Male athletes | H12: Internal Impingement | I12: Do throwing movements cause deep back shoulder pain? | J12: Posterior impingement sign + MRI | K12: Physiological contact of the undersurface cuff against the posterosuperior labrum in extreme external rotation, becoming pathological when GIRD, scapular dyskinesis, poor kinetic-chain sequencing or excessive throwing volume increase the load and duration of that contact | L12: Return to full-velocity throwing with restored control and velocity, and pain-free late cocking | M12: Sleeper and cross-body stretches for the posterior capsule; posterior cuff eccentric loading (prone external rotation, side-lying); scapular retraining (serratus, lower trapezius); thoracic and hip rotation mobility; trunk and lower-body drive; medicine-ball plyometrics; staged interval throwing programme | N12: Nociceptive - mechanical and compressive | O12: Overhead athlete group; assess alongside GIRD, SLAP and scapular dyskinesis | P12: No | Q12: Correct the drivers rather than the contact: address GIRD and posterior capsule tightness, restore scapular upward rotation and posterior tilt, build posterior cuff eccentric capacity, correct throwing mechanics and kinetic-chain sequencing, and manage throwing volume. Surgery has poor results in throwers | R12: Stage 1-2 with posterior capsule mobility and posterior cuff eccentric work; avoid provocative late-cocking positions early; then plyometric loading and a structured interval throwing programme | S12: Fix the whole throw: correct GIRD, restore thoracic and hip rotation, increase lower-body and trunk contribution so less load reaches the shoulder, correct excessive horizontal abduction and a low elbow position, and cap throw counts with mandatory rest days | T12: Manual therapy for the posterior capsule; scapular taping for feedback | U12: Rarely surgical. Debridement outcomes in throwers are inconsistent - exhaust the load and mechanics route first | V12: KJOC; ASES; SANE; throwing velocity and control | W12: Pain in late cocking; internal rotation range and GIRD; total rotational arc; throwing tolerance | X12: 12 weeks minimum; often a full off-season | Y12: Failure after a well-delivered programme addressing GIRD, scapula and mechanics | Z12: Burkhart, Morgan & Kibler - the disabled throwing shoulder
A13: SRC | B13: Posterior | C13: Overhead athlete, desk worker, anyone with a sustained protracted posture | D13: Scapular pain | E13: 20-50 | F13: Slow | G13: Female | H13: Scapular Dyskinesis | I13: Does the shoulder blade move abnormally during lifting? | J13: Scapular assistance test | K13: Weakness or altered timing of serratus anterior and lower trapezius with upper trapezius and pectoralis minor dominance; thoracic kyphosis and stiffness; sustained postural loading; fatigue in overhead sport | L13: Restore efficient scapulohumeral rhythm so overhead work and lifting are sustainable without periscapular fatigue | M13: Scapular setting and control without load first; serratus anterior (wall slides, punches, protraction with load, push-up plus) 3-4 sets 10-15 reps 3-5x/week; lower trapezius (prone Y, prone horizontal abduction with external rotation, side-lying forward flexion); pectoralis minor lengthening; thoracic extension and rotation mobility; then integrate into overhead loading | N13: Not a pain generator in itself - a contributor to whatever else is going on | O13: Scapular group; treat as a modifiable impairment WITHIN another diagnosis, rarely as the whole diagnosis. Kibler classification | P13: Screen: distinguish from a true nerve palsy (long thoracic, spinal accessory) - a nerve palsy shows profound weakness and a characteristic winging pattern | Q13: Scapular and kinetic-chain retraining as part of the wider plan. A positive scapular assistance or retraction test tells you it is worth targeting | R13: Stage 1-2. Control work without load, then progressive serratus and lower trapezius loading 3-5x/week, then integration into functional and overhead loading | S13: Restore the platform the arm moves on: serratus anterior and lower trapezius capacity, reduce upper trapezius and pectoralis minor dominance, restore thoracic extension and rotation, correct workstation and overhead work posture, address fatigue-related loss of control in sport | T13: Scapular taping for proprioceptive feedback; manual therapy for thoracic and pectoralis minor mobility | U13: Not applicable - this is a rehabilitation target, not a surgical one | V13: SPADI; QuickDASH (measured through the primary diagnosis) | W13: Scapular assistance test; winging under load and at fatigue; serratus and lower trapezius endurance | X13: 6-12 weeks alongside the primary diagnosis | Y13: Suspected nerve palsy; failure of the primary condition despite correct scapular work | Z13: Kibler Scapular Summit consensus 2013; Manual Module 10 (#25)
A14: SRC | B14: Posterior | C14: Volleyball spiker, overhead thrower; also secondary to a spinoglenoid notch cyst | D14: Weakness and wasting | E14: 20-50 | F14: Slow | G14: Male | H14: Suprascapular Neuropathy | I14: Do you notice weakness during external rotation? | J14: EMG + MRI | K14: Traction on the nerve during the follow-through of overhead sport, or compression by a paralabral cyst arising from a labral tear; the pattern of wasting localises the level of entrapment | L14: Restore external rotation strength and return to overhead sport without fatigue or weakness | M14: Progressive external rotator loading respecting fast fatigability of a denervated muscle (start low volume, build gradually); scapular retraining; posterior cuff endurance; avoid provocative follow-through positions early; graded return to overhead sport with volume capped | N14: Neuropathic | O14: Neural/referred group; isolated infraspinatus wasting = spinoglenoid notch; both supraspinatus and infraspinatus = suprascapular notch | P14: YES - isolated infraspinatus wasting demands imaging to exclude a compressive cyst | Q14: Image to identify a cyst. If present, treat the labral tear that produced it - decompression alone often recurs. If not, conservative: technique modification, cuff and scapular strengthening, load reduction of the provocative action | R14: Progressive external rotator and scapular loading, respecting that a denervated muscle fatigues fast; graded volume increase; sport-specific reintroduction last | S14: Reduce traction on the nerve: modify the follow-through and deceleration phase, build posterior cuff and scapular capacity, restore thoracic rotation, cap overhead volume during recovery | T14: Load and technique modification; taping for scapular feedback | U14: Cyst aspiration or arthroscopic decompression with labral repair; arthroscopic suprascapular nerve release for non-cystic entrapment (minimal restriction post-operatively) | V14: KJOC; ASES; external rotation strength; serial nerve conduction studies | W14: Infraspinatus bulk; external rotation strength LSI; overhead sport tolerance | X14: 3-6 months conservatively; longer where a cyst requires surgery | Y14: Isolated infraspinatus wasting or a cyst on MRI - refer | Z14: Manual Module 10 (#22)
... A43: ADD | B43: AC / Clavicle | C43: Contact sport, cycling crash, fall onto the shoulder | D43: Obvious deformity over the collarbone after a fall | E43: 15-40 | F43: Sudden | G43: Male | H43: Clavicle Fracture (mid-shaft) | I43: Did you fall on the shoulder and is there an obvious lump or step in the collarbone? | J43: X-ray (AP and 15 deg cephalic tilt); assess shortening and displacement | K43: Direct impact or a fall onto the shoulder transmitting force through the clavicle - the mid-shaft is the mechanically weakest point | L43: Return to contact sport, overhead work and carrying with radiographic union and full strength | M43: Sling 2-4 weeks; pendulum, elbow and hand work IMMEDIATELY; active-assisted range from 2-4 weeks; active range from 4-6 weeks; progressive scapular, cuff and thoracic loading from 6-8 weeks; contact sport at 12 weeks with union | N43: Nociceptive - acute fracture | O43: AC/clavicle group; management driven by displacement, shortening (typically over 2 cm) and comminution | P43: YES - skin tenting, an open fracture, or any neurovascular compromise is an urgent surgical referral | Q43: Minimally displaced: conservative - sling then early range and progressive loading. Significantly displaced or shortened over 2 cm: surgical fixation gives lower non-union rates and better function in active patients | R43: Sling 2-4 weeks; early elbow and hand movement; graded range 2-6 weeks; progressive loading from 6-8 weeks; contact sport at 12 weeks with union | S43: Restore the girdle after union: scapular upward rotation and retraction, cuff capacity, thoracic extension; reverse the deconditioning of the immobilisation period; address the fall or crash mechanism | T43: Sling (a figure-of-eight brace offers no advantage); analgesia; early elbow and hand movement | U43: Open reduction and internal fixation for significant displacement, shortening over 2 cm, open fracture, skin tenting or neurovascular compromise | V43: QuickDASH; Constant-Murley; Oxford Shoulder Score | W43: Radiographic union; active range; strength LSI; loading tolerance | X43: 6-12 weeks to union; 12 weeks to contact sport | Y43: Skin tenting, open fracture, neurovascular compromise, displacement or shortening over 2 cm | Z43: Clavicle fracture management trials

Sheet Rx Generator
A1: PRESCRIPTION GENERATOR
A2: Select a condition in the yellow cell. Every field below is pulled live from the Master Matrix.
A4: SELECT CONDITION → | B4: Biceps Tendinopathy
A6: Region | B6: =IFERROR(INDEX('Master Matrix'!B$4:B$43,MATCH($B$4,'Master Matrix'!$H$4:$H$43,0)),"") -> Anterior
A7: Activity level | B7: =IFERROR(INDEX('Master Matrix'!C$4:C$43,MATCH($B$4,'Master Matrix'!$H$4:$H$43,0)),"") -> Gym lifter with heavy pressing and curling volume; overhead athlete
A8: Common symptoms | B8: =IFERROR(INDEX('Master Matrix'!D$4:D$43,MATCH($B$4,'Master Matrix'!$H$4:$H$43,0)),"") -> Pain in front of shoulder
A9: Age group | B9: =IFERROR(INDEX('Master Matrix'!E$4:E$43,MATCH($B$4,'Master Matrix'!$H$4:$H$43,0)),"") -> 20-50
A10: Onset | B10: =IFERROR(INDEX('Master Matrix'!F$4:F$43,MATCH($B$4,'Master Matrix'!$H$4:$H$43,0)),"") -> Slow
A11: Predominance | B11: =IFERROR(INDEX('Master Matrix'!G$4:G$43,MATCH($B$4,'Master Matrix'!$H$4:$H$43,0)),"") -> Male
A12: High-yield diagnostic question | B12: =IFERROR(INDEX('Master Matrix'!I$4:I$43,MATCH($B$4,'Master Matrix'!$H$4:$H$43,0)),"") -> Is pain located in the front groove of the shoulder?
A13: Special test + imaging | B13: =IFERROR(INDEX('Master Matrix'!J$4:J$43,MATCH($B$4,'Master Matrix'!$H$4:$H$43,0)),"") -> Speed/Yergason + Ultrasound
A14: Underlying biomechanical cause | B14: =IFERROR(INDEX('Master Matrix'!K$4:K$43,MATCH($B$4,'Master Matrix'!$H$4:$H$43,0)),"") -> Repetitive tensile load on a tendon stabilised by the biceps pulley; often coexists with cuff or subscapularis pathology; scapular and thoracic deficits raise the demand
A15: DESIRED ACTIVITY GOAL | B15: =IFERROR(INDEX('Master Matrix'!L$4:L$43,MATCH($B$4,'Master Matrix'!$H$4:$H$43,0)),"") -> Return to pressing, curling and overhead lifting without anterior pain
A16: PHYSIOTHERAPY SPECIFIC EXERCISE | B16: =IFERROR(INDEX('Master Matrix'!M$4:M$43,MATCH($B$4,'Master Matrix'!$H$4:$H$43,0)),"") -> Isometric elbow flexion and shoulder elevation holds; progressive isotonic biceps loading 3-4 sets 8-12 RM 3x/week; cuff external and internal rotation loading; serratus and lower trapezius work; thoracic extension mobility; graded overhead and pressing reintroduction
A17: Pain mechanism | B17: =IFERROR(INDEX('Master Matrix'!N$4:N$43,MATCH($B$4,'Master Matrix'!$H$4:$H$43,0)),"") -> Nociceptive - tensile tendon load
A18: Classification / cluster | B18: =IFERROR(INDEX('Master Matrix'!O$4:O$43,MATCH($B$4,'Master Matrix'!$H$4:$H$43,0)),"") -> AC/clavicle/biceps group; rarely isolated - always screen the cuff, pulley and labrum
A19: RED FLAG STATUS | B19: =IFERROR(INDEX('Master Matrix'!P$4:P$43,MATCH($B$4,'Master Matrix'!$H$4:$H$43,0)),"") -> No
A20: MANAGEMENT EMPHASIS | B20: =IFERROR(INDEX('Master Matrix'!Q$4:Q$43,MATCH($B$4,'Master Matrix'!$H$4:$H$43,0)),"") -> Load management and cuff/scapular rehabilitation; treat the underlying cuff or pulley pathology, because isolated biceps treatment usually fails. Surgical opinion (tenotomy or tenodesis) selectively
A21: Loading stage & entry dose | B21: =IFERROR(INDEX('Master Matrix'!R$4:R$43,MATCH($B$4,'Master Matrix'!$H$4:$H$43,0)),"") -> Stage 1-2. Isometric for analgesia, then progressive isotonic biceps and cuff loading; then overhead and sport-specific loading
A22: BIOMECHANICAL CORRECTIONS & KINETIC CHAIN | B22: =IFERROR(INDEX('Master Matrix'!S$4:S$43,MATCH($B$4,'Master Matrix'!$H$4:$H$43,0)),"") -> Reduce the demand on the tendon: scapular upward rotation and posterior tilt, thoracic extension, cuff endurance; correct pressing and overhead technique and weekly volume distribution
A23: Manual therapy, taping & adjuncts | B23: =IFERROR(INDEX('Master Matrix'!T$4:T$43,MATCH($B$4,'Master Matrix'!$H$4:$H$43,0)),"") -> Short-term activity modification; taping; manual therapy as an adjunct
A24: Advanced / surgical options | B24: =IFERROR(INDEX('Master Matrix'!U$4:U$43,MATCH($B$4,'Master Matrix'!$H$4:$H$43,0)),"") -> Guided injection into the sheath (not the tendon substance); biceps tenodesis (4-6 weeks protection) or tenotomy (1-2 weeks) if refractory or with a pulley/subscapularis lesion
A25: Outcome measures | B25: =IFERROR(INDEX('Master Matrix'!V$4:V$43,MATCH($B$4,'Master Matrix'!$H$4:$H$43,0)),"") -> SPADI; QuickDASH; ASES
A26: Re-testable markers | B26: =IFERROR(INDEX('Master Matrix'!W$4:W$43,MATCH($B$4,'Master Matrix'!$H$4:$H$43,0)),"") -> Bicipital groove tenderness; resisted elevation pain; pressing and overhead load tolerance
A27: Expected timeline | B27: =IFERROR(INDEX('Master Matrix'!X$4:X$43,MATCH($B$4,'Master Matrix'!$H$4:$H$43,0)),"") -> 12 weeks minimum
A28: Referral / surgical trigger | B28: =IFERROR(INDEX('Master Matrix'!Y$4:Y$43,MATCH($B$4,'Master Matrix'!$H$4:$H$43,0)),"") -> Failure after 12 weeks of correct loading; suspected pulley lesion or subscapularis tear
A29: Evidence anchor | B29: =IFERROR(INDEX('Master Matrix'!Z$4:Z$43,MATCH($B$4,'Master Matrix'!$H$4:$H$43,0)),"") -> Manual Module 10 (#19)
A31: NOTES
A32: • Green text is pulled from the Master Matrix — edit the matrix, not this sheet.
A33: • Check RED FLAG STATUS first. A crimson entry means screen or refer before rehabilitating.
A34: • The DESIRED ACTIVITY GOAL and PHYSIOTHERAPY SPECIFIC EXERCISE rows are written to be handed straight to the patient.
A35: • Print this sheet (portrait, fit to one page wide) for the patient file.

Sheet Assessment Roadmap
A1: FIVE-GATE ASSESSMENT ROADMAP
A2: Work top to bottom. Gate 3 — pain, stiffness or instability — does most of the diagnostic work.
A3: Gate | B3: Purpose | C3: What You Assess | D3: Findings That Matter | E3: Decision Rule
A4: GATE 1 | B4: Screen for serious pathology | C4: Malignancy (incl. Pancoast, metastasis); acute traumatic cuff tear; fracture or unreduced dislocation; septic joint; cardiac or visceral referral | D4: Constant or night pain unrelated to movement, systemic features, weight loss, cancer history, Horner's signs or hand/arm neurology. Sudden significant weakness or loss of active elevation after trauma. Trauma with deformity, marked loss of movement or neurovascular compromise. Hot, painful, systemically unwell shoulder. Exertional pain with cardiovascular risk | E4: If present -> investigate or refer BEFORE local treatment
A5: GATE 2 | B5: Screen the cervical spine | C5: Cervical range, Spurling's test, distraction, neurodynamic tests and a neurological examination | D5: The neck commonly refers to the shoulder. Wainner cluster: Spurling positive + distraction relief + upper limb neurodynamic test positive + cervical rotation under 60 degrees. Pain below the elbow with paraesthesia. Symptoms changed more by neck than by shoulder movement | E5: Clear the neck BEFORE committing to a shoulder diagnosis
A6: GATE 3 | B6: Pain, stiffness or instability? | C6: The three master pathways - established before any special test | D6: STIFFNESS (a true capsular BLOCK to passive range) -> frozen shoulder or glenohumeral OA. INSTABILITY (slipping or apprehension) -> Stanmore pole. PAIN with preserved passive range -> RCRSP. The single most useful discriminator in the stiff shoulder is a capsular block to passive external rotation WITH AN INTACT CUFF | E6: This branch does most of the diagnostic work
A7: GATE 4 | B7: Cluster to a working diagnosis | C7: History + palpation + special-test cluster | D7: Cluster 1 RCRSP: anterolateral pain with elevation and night pain, painful arc, pain-limited but preserved passive range. Cluster 2 Frozen shoulder: insidious painful-then-stiff, global loss of PASSIVE range especially early external rotation, intact cuff, diabetes/thyroid link. Cluster 3 Traumatic anterior instability (Polar I): significant trauma with dislocation, apprehension in abduction-external rotation, positive relocation, often a Bankart lesion | E7: Clustering beats any single test. Many named 'impingement' tests are sensitive but not specific - read them as symptom provocation, not structure identification
A8: GATE 5 | B8: Quantify impairments and capacity | C8: ROM (especially passive external rotation); cuff strength (PAIN versus TRUE WEAKNESS); scapular control; irritability | D8: Passive and active elevation and rotation; resisted cuff testing distinguishing pain-limited from truly weak; lag signs; scapular assistance and retraction tests; total rotational arc in throwers; irritability grading to set treatment intensity | E8: These become the baseline re-testable markers that drive the plan and, for athletes, return-to-sport testing
A10: DIAGNOSTIC ALGORITHM — NARRATIVE FLOW
A11: • Shoulder pain → Red flags? YES: image or refer. NO ↓
A12: • Referred from the neck? YES: treat the cervical source. NO ↓
A13: • Is the dominant problem PAIN, STIFFNESS or INSTABILITY?
A14: • STIFFNESS (capsular block to passive range) → early marked loss of external rotation with an intact cuff = frozen shoulder (STAGE IT). Older adult with crepitus and radiographic change = glenohumeral OA.
A15: • INSTABILITY (slipping or apprehension) → traumatic + Bankart = Polar I. Atraumatic + structural = Polar II. Non-structural muscle patterning = Polar III. Consider MDI.
A16: • PAIN with preserved passive range → anterolateral, overhead, painful arc, night pain = RCRSP (± cuff tear if TRUE weakness). Calcific deposit on imaging = calcific tendinopathy. AC point pain on cross-body = AC joint. Anterior groove pain = biceps.
A17: • Confirm with the impairment and capacity profile → set baseline markers → enter the Phased Programme.
A19: CLINICAL PEARL
A20: • Convert every diagnosis into two or three re-testable markers BEFORE you treat — pain-free elevation, passive external rotation, cuff strength, or a night-pain score.
A21: • If those markers do not improve over 4-6 weeks of appropriate loading (or stage-based care for frozen shoulder), revisit the diagnosis rather than simply adding modalities.

Sheet Subjective Exam
A1: SUBJECTIVE EXAMINATION TEMPLATE
A2: Yellow column is the input column. A structured history alone points to the diagnosis in most shoulder presentations.
A3: Domain | B3: What to Ask | C3: Why It Matters | D3: Findings (fill in)
A4: Onset & mechanism | B4: Insidious/overuse or traumatic? Fall on an outstretched hand, forced abduction-external rotation, or a direct blow? | C4: Insidious points to RCRSP, tendinopathy or OA; traumatic to dislocation, acute cuff tear, fracture or AC injury | D4: e.g. insidious, 2 months after painting a ceiling
A5: Age & context | B5: Age; occupation; sport; gym content | C5: A first traumatic dislocation under 25 carries high re-dislocation risk; new significant weakness after trauma in an older adult suggests an acute cuff tear
A6: Pain location | B6: Point with one finger: anterolateral / on top / anterior groove / deep and global / posterior | C6: Anterolateral with overhead = RCRSP. On top with cross-body = AC. Anterior groove = biceps. Deep global stiffness = capsular
A7: PAIN, STIFFNESS OR INSTABILITY? | B7: Is the main problem pain, stiffness, or the shoulder feeling unstable? | C7: GATE 3 — the single question that organises the whole differential into three master pathways
A8: Load behaviour | B8: What can't you do — reach overhead, lie on it, throw, press? | C8: Overhead with night pain = RCRSP; loss of range = capsular; slipping = instability
A9: NIGHT PAIN | B9: Can you lie on it? How many times do you wake? | C9: Night pain is common, disabling, a major driver of distress — and one of the best re-test markers
A10: Irritability | B10: How easily does it flare, how bad does it get, and how long does it take to settle? | C10: Irritability sets treatment intensity. High irritability = gentler, pain-guided input. This is the key clinical skill in the shoulder
A11: Activity & load change | B11: Recent change in overhead work, gym volume, pressing content, throwing or serving volume | C11: Most atraumatic shoulder pain is a load change on an unprepared shoulder
A12: NECK SCREEN | B12: Any neck pain or stiffness? Does moving your neck change the shoulder pain? Any pain below the elbow or paraesthesia? | C12: GATE 2 — the neck commonly refers to the shoulder and is the commonest missed contributor
A13: RED FLAG SCREEN | B13: Constant or night pain unrelated to movement? Weight loss? Cancer history? Smoking? Fever or unwell? Exertional chest symptoms? Arm swelling or colour change? Sudden weakness after trauma? | C13: GATE 1 — malignancy, acute cuff tear, fracture, sepsis and cardiac/visceral referral all present as shoulder pain
A14: Metabolic & medical | B14: Diabetes? Thyroid disease? Previous shoulder surgery or dislocation? Hypermobility? Medication? | C14: Diabetes and thyroid disease are strongly associated with frozen shoulder and change the expected trajectory
A15: Prior episodes & treatment | B15: Previous episodes, imaging, injections, physiotherapy — and what happened | C15: Tells you what has genuinely been tried and at what dose
A16: Beliefs & expectations | B16: What do you think is wrong? What are you afraid of? How long do you expect this to take? | C16: Fear-avoidance and low self-efficacy predict poorer outcomes; mismatched timeline expectation causes disengagement
... A18: Baseline outcome measure | B18: Which PROM will you use? (see Outcome Measures sheet) | C18: One PROM plus two or three physical markers is the minimum dataset
A20: HOW TO FILL THIS SHEET
A21: • Row 4 shows an example entry in grey — overwrite it.
A22: • Three questions triage most shoulder pain fast: "Was there an injury — and if so, in what position?", "Is the main problem pain, stiffness, or the shoulder feeling unstable?", and "What can't you do — reach overhead, lie on it, throw?"
A23: • If nothing in the physical examination reproduces the pain the patient came in with, stop and refer.

Sheet Objective Exam
A1: PHYSICAL EXAMINATION TEMPLATE
A2: Yellow columns are input columns. Two distinctions organise the whole examination — see the note at the foot of the sheet.
A3: Section | B3: Item | C3: How to Test / What to Look For | D3: Involved (fill in) | E3: Uninvolved (fill in) | F3: Interpretation
A4: Observation | B4: Posture & scapular position | C4: Resting scapular position, winging, thoracic kyphosis, forward head | D4: e.g. protracted, kyphotic | E4: similar | F4: Postural contribution is modifiable and often central
A5: Observation | B5: Muscle bulk | C5: Supraspinatus and infraspinatus fossae; deltoid contour | F5: ISOLATED infraspinatus wasting = suprascapular nerve until proven otherwise
A6: Observation | B6: Movement quality | C6: Scapulohumeral rhythm, painful arc, willingness to move, symmetry | F6: Observe LOWERING as well as raising — it often reveals more
A7: Observation | B7: Deformity / swelling | C7: AC step, prominence, effusion after trauma | F7: A step at the AC joint grades the Rockwood injury
A8: Palpation | B8: AC joint | C8: Point tenderness | F8: AC joint sprain or OA
A9: Palpation | B9: Greater tuberosity / cuff insertion | C9: Tenderness | F9: Rotator cuff pathology
A10: Palpation | B10: Bicipital groove (LHB) | C10: Tenderness in a narrow strip | F10: Long head of biceps tendinopathy
A11: Palpation | B11: Subacromial region | C11: Tenderness | F11: Subacromial pain (RCRSP)
A12: Palpation | B12: Scapular border / periscapular | C12: Tenderness | F12: Scapulothoracic or cervical referral
A13: Palpation | B13: Sternoclavicular joint | C13: Tenderness, prominence or depression | F13: A DEPRESSION suggests posterior dislocation — a mediastinal emergency
A14: Range (active) | B14: Elevation (degrees) & painful arc | C14: Goniometry; record the arc where pain occurs | F14: Painful arc 60-120 degrees is part of the RCRSP cluster
A15: Range (passive) | B15: Elevation (degrees) | C15: Supine, scapula stabilised | F15: PASSIVE vs ACTIVE is the key comparison — see the note below
A16: Range (passive) | B16: External rotation at 0 deg abduction | C16: Elbow at the side, scapula stabilised | F16: THE most important single measurement — lost first and most in frozen shoulder
... A40: Function | B40: Functional reach tasks | C40: Hand to head, hand to opposite shoulder, hand behind back, overhead lift | F40: What the patient actually cares about — use as a re-test marker
A42: HOW TO FILL THIS SHEET
A43: • TWO DISTINCTIONS ORGANISE THE WHOLE EXAMINATION. First: pain-limited but FULL passive range (think RCRSP) versus a true CAPSULAR BLOCK to passive range (think frozen shoulder or OA). Second: weakness from PAIN versus weakness from a STRUCTURAL CUFF TEAR. Getting these two right routes the patient down the correct pathway.
A44: • Always stabilise the scapula when measuring rotation at 90 degrees abduction — without it the GIRD and total arc figures are worthless.
A45: • Transfer range and strength figures into the Progress Tracker, which calculates symmetry, the ER:IR ratio, GIRD and the total rotational arc automatically.
A46: • Row 4 shows an example entry in grey — overwrite it.

Sheet Special Tests
A1: SPECIAL TESTS
A2: No single shoulder test is definitive. Many named "impingement" tests are sensitive but not specific — read them as symptom provocation, not structure identification.
A3: Category | B3: Test | C3: Targets | D3: Positive Finding | E3: Clinical Note
A4: Subacromial / RCRSP | B4: Painful arc / Hawkins / Neer | C4: Subacromial structures | D4: Pain provoked | E4: Symptom provocation, NOT structure-specific - read as a cluster
A5: Cuff | B5: Empty can (Jobe) | C5: Supraspinatus | D5: Pain and/or weakness | E5: Distinguish pain-limited from truly weak
A6: Cuff | B6: Full can | C6: Supraspinatus | D6: Weakness on resisted scaption, thumb up | E6: Better tolerated than empty can for strength assessment
A7: Cuff | B7: External rotation resistance / lag sign | C7: Infraspinatus, teres minor | D7: Inability to hold passively placed external rotation | E7: A LAG SIGN SUGGESTS A TEAR - high specificity
A8: Cuff | B8: Drop arm sign | C8: Supraspinatus | D8: Inability to lower the arm smoothly from abduction | E8: High specificity for a large full-thickness tear
A9: Cuff | B9: Hornblower's sign | C9: Teres minor | D9: Inability to externally rotate at 90 degrees abduction | E9: Posterosuperior cuff involvement
A10: Subscapularis | B10: Lift-off | C10: Subscapularis (lower) | D10: Inability to lift the hand off the lower back | E10: Requires adequate internal rotation range
A11: Subscapularis | B11: Belly press | C11: Subscapularis (upper) | D11: Elbow drops back when pressing on the abdomen | E11: Best tolerated subscapularis test
A12: Subscapularis | B12: Bear hug | C12: Subscapularis (upper) | D12: Inability to resist the hand being lifted off the opposite shoulder | E12: Sensitive for an upper subscapularis tear
A13: Capsule | B13: Passive ROM (especially external rotation) | C13: Capsule | D13: Global restriction with a firm capsular end-feel | E13: THE key discriminator: capsular block + intact cuff = frozen shoulder or OA
A14: Instability | B14: Apprehension test | C14: Anterior instability | D14: APPREHENSION (not pain) in abduction-external rotation | E14: Apprehension, not pain, is the positive finding
... A33: Range | B33: GIRD / total rotational arc | C33: Overhead athlete screening | D33: Internal rotation at 90 deg abduction, scapula stabilised, both sides | E33: The TOTAL ARC deficit matters more than GIRD alone

Sheet Clusters & Classification
A1: DIAGNOSTIC CLUSTERS & CLASSIFICATION FRAMEWORKS
A2: Clustering beats any single test. Then match the label to a management pathway.
A3: Cluster | B3: Feature 1 | C3: Feature 2 | D3: Feature 3 | E3: Working Diagnosis
A4: CLUSTER 1 | B4: Anterolateral shoulder pain with elevation and overhead activity, and night pain | C4: Painful arc; positive provocation tests; pain-limited but relatively PRESERVED passive range | D4: Pain and/or weakness on resisted cuff tests WITHOUT a true capsular block | E4: Rotator cuff-related shoulder pain (RCRSP)
A5: CLUSTER 2 | B5: Insidious onset; painful then progressively stiff shoulder | C5: Global loss of PASSIVE range in a capsular pattern - early, marked loss of external rotation | D5: Intact rotator cuff; often diabetes or thyroid disease; disproportionate night pain in the painful stage | E5: Frozen shoulder (adhesive capsulitis)
A6: CLUSTER 3 | B6: Significant traumatic event with dislocation or subluxation (often abduction-external rotation) | C6: Apprehension in the abducted, externally rotated position; positive relocation | D6: Often a Bankart lesion; younger patients have high recurrence risk | E6: Traumatic anterior instability (Stanmore Polar I)
A8: THE ONE-LINE DIFFERENTIATORS
A9: • Overhead pain + painful arc + night pain, with preserved passive range = RCRSP
A10: • Global loss of PASSIVE range (especially early external rotation) with an intact cuff = frozen shoulder
A11: • Traumatic dislocation + apprehension = structural instability (Stanmore Polar I)
A12: • Non-structural, muscle-patterning instability = Polar III (retrain, do not operate)
A13: • Sudden weakness or loss of elevation after trauma = acute cuff tear (timely surgical assessment)
A14: • AC point pain on cross-body reach = AC joint
A15: • Constant or night pain unrelated to movement, with systemic features = screen for serious pathology
A17: Framework | B17: Category / Stage | C17: What It Means | D17: Management Implication
A18: RCRSP umbrella (contemporary terminology) | B18: Rotator cuff-related shoulder pain | C18: Encompasses cuff tendinopathy, subacromial pain and what was formerly called 'impingement' | D18: Subacromial space size and 'impingement' morphology correlate poorly with pain; decompression is no better than placebo (CSAW); progressive exercise is first-line (GRASP). Diagnose the pattern, not a mechanical pinch
A19: Stanmore (Bayley) instability | B19: Polar Type I - Traumatic structural | C19: Clear trauma, unidirectional, structural lesion (e.g. Bankart). Equivalent to TUBS | D19: Rehabilitation plus surgical stabilisation opinion, especially in the young contact athlete
A20: Stanmore (Bayley) instability | B20: Polar Type II - Atraumatic structural | C20: No significant trauma but structural or capsulolabral deficiency, often from repetitive microtrauma | D20: Progressive control and capacity rehabilitation; surgical opinion selectively
A21: Stanmore (Bayley) instability | B21: Polar Type III - Muscle patterning (non-structural) | C21: Abnormal muscle recruitment WITHOUT a structural lesion; may be positional or voluntary | D21: Specific motor-control retraining and biofeedback - NOT surgery (poorer surgical outcomes). Patients can move between poles over time
A22: Frozen shoulder staging | B22: Stage 1 - Painful / pre-adhesive | C22: Pain dominant, often severe night pain; range beginning to reduce | D22: Pain control and gentle pain-guided range; corticosteroid injection has its best effect here. Do NOT stretch aggressively
A23: Frozen shoulder staging | B23: Stage 2 - Freezing | C23: Increasing stiffness with continuing pain | D23: Progressive stretching and loading WITHIN tolerance; match effort to irritability
A24: Frozen shoulder staging | B24: Stage 3 - Frozen | C24: Stiffness dominant, pain settling | D24: Now stretch and load - end-range mobilisation, sustained stretch and progressive strengthening
A25: Frozen shoulder staging | B25: Stage 4 - Thawing | C25: Range gradually returning | D25: Restore full range and strength; reverse the deconditioning of the earlier stages
A26: Tendinopathy continuum (cuff) | B26: Reactive / Dysrepair / Degenerative | C26: As in other tendons - guides how aggressively to load | D26: Reactive: reduce peak load, isometrics for analgesia. Dysrepair/degenerative: heavy slow resistance to build capacity around the pathology
A27: Pain mechanism | B27: Nociceptive / Neuropathic / Nociplastic | C27: Nociceptive: clear load-pain relationship. Neuropathic: burning, paraesthesia, positive neural signs. Nociplastic: disproportionate, spreading, poor load-pain correlation | D27: Nociceptive responds to load management; neuropathic needs the neural source addressed; nociplastic needs pain education and graded exposure
A29: CLINICAL PEARL
A30: • Match the label to a management PATHWAY. RCRSP → progressive cuff and scapular loading. Frozen shoulder → stage- and irritability-based care. Instability → Stanmore pole (structural → consider surgery; muscle-patterning → control retraining).
A31: • Getting the framework right at the outset prevents the two commonest errors: loading a highly irritable frozen shoulder, and operating on a muscle-patterning instability.
A32: • Patients can MOVE BETWEEN Stanmore poles over time — the classification is a dynamic triangle, not a fixed label.

Sheet Imaging Guide
A1: IMAGING GUIDE
A2: Most shoulder pain is a clinical diagnosis. Image to answer a specific question — not to confirm an obvious RCRSP or frozen shoulder.
A3: Modality | B3: When to Request | C3: What It Answers | D3: Interpretation Caution
A4: Clinical examination alone | B4: The majority of atraumatic presentations | C4: RCRSP, frozen shoulder, AC joint pain, scapular dyskinesis | D4: Most shoulder pain is a clinical diagnosis. Image to answer a specific question, not to confirm an obvious RCRSP or frozen shoulder
