Workbook

Sheet Read Me
A1: ELBOW ASSESSMENT AND MANAGEMENT PROGRAMME
A2: Screen → clear the neck and shoulder → localise the quadrant → identify the tissue → load → discharge on grip, range and control.
A4: SHEET | B4: WHAT IT DOES | C4: WHEN TO USE IT | D4: SOURCE / FOCUS
A5: Master Matrix | B5: 38 elbow conditions on the established column structure: Region → Activity Level → Common Symptoms → Age → Onset → Predominance → Condition → High-Yield Question → Special Test + Imaging → Biomechanical Cause → Desired Activity Goal → Physiotherapy Specific Exercise, then pain mechanism, classification, red-flag status, management emphasis, loading dose, biomechanical corrections, adjuncts, advanced options, outcomes, markers, timeline and referral triggers. | C5: The core reference. Filter column B by region or column P by red-flag status. | D5: Your 23-row skeleton (SRC) + 15 added (ADD)
A6: Rx Generator | B6: Pick a condition from the dropdown and the full prescription is pulled live from the Master Matrix. | C6: In clinic, or to print a plan into the patient file. | D6: Live INDEX/MATCH
A7: Assessment Roadmap | B7: The five-gate sequence, built around the quadrant-then-tissue branch at Gate 4. | C7: Every new patient, in order. | D7: Clinical reasoning
A8: Subjective Exam | B8: Fillable history template with the elbow-specific and paediatric screening questions built in. | C8: First consultation. | D8: Fillable
A9: Objective Exam | B9: Fillable examination template: observation, palpation map by quadrant, range with end-feel, grip, resisted testing, stability, nerve and cervical screen. | C9: First consultation and every re-assessment. | D9: Fillable
A10: Special Tests | B10: 30 tests grouped by quadrant and tissue, with what a positive means and how much weight to give it. | C10: During the physical examination. | D10: Reference
A11: Clusters & Classification | B11: Seven diagnostic clusters, the one-line differentiators, and the tendinopathy continuum, valgus overload triad, instability spectrum and nerve grading systems. | C11: When the picture is not yet clear, and when choosing a pathway. | D11: Reference
A12: Imaging Guide | B12: When to image, which modality answers which question, and the traps — including comparison views in children. | C12: Before requesting or when reading a report. | D12: Reference
A13: Phased Programme | B13: Phase 0-4 with goals, content, markers and exit criteria, plus the master treatment sequence. | C13: Building and progressing every plan. | D13: Reference
A14: Exercise & Dosage | B14: Loading library with dose and indication, including heavy slow resistance, the Tyler twist, grip endurance and low-load prolonged stretch. | C14: Writing the actual programme. | D14: Reference
A15: Adjuncts & Advanced | B15: Education, bracing, night splinting, ergonomics, ESWT, PRP, injection and surgery, with the sequencing rule. | C15: When loading alone is not enough. | D15: Reference
... A24: References | B24: Guideline and trial sources. | C24: Verifying or citing. | D24: —
A26: CRITICAL POINTS FOR THE ELBOW
A27: • YOUR SKELETON IS THE SPINE. All 23 of your region-and-symptom rows appear in the Master Matrix in your original order, marked SRC in the Source column, with your exact symptom wording preserved in the Common Symptoms column. 15 conditions have been added to complete the differential and are marked ADD.
A28: • YOUR 20-SPORT TABLE is reproduced verbatim on the Sport Profiles sheet, with a fifth column added giving the return-to-sport and load considerations for each.
A29: • THE ELBOW'S DEFINING TRAP IS LOSS OF TERMINAL EXTENSION. It is the earliest and most sensitive sign of intra-articular pathology — OCD, loose body, arthritis, valgus extension overload. Never dismiss it as stiffness, and always note the END-FEEL.
A30: • THE SECOND TRAP IS THE MIMIC. When lateral elbow pain fails to respond to correct tendon loading, reconsider the diagnosis: radial tunnel (tender 4-5 cm distal, pain on resisted supination), radiocapitellar plica (clicking), PLRI (giving way on push-up), or intra-articular pathology.
A31: • THE THIRD TRAP IS SKELETAL MATURITY. In the growing athlete the APOPHYSIS FAILS BEFORE THE TENDON OR LIGAMENT. Medial pain in a young thrower is Little League elbow, not golfer's elbow. Image BOTH elbows.
A32: • MEASURE PAIN-FREE GRIP STRENGTH in every overuse presentation and record the figure — it is simultaneously a diagnostic test, the treatment target and the discharge criterion.
A33: • CORTICOSTEROID INJECTION for elbow tendinopathy gives short-term relief and WORSE 12-month outcomes than exercise or wait-and-see. It also risks LUCL attenuation and PLRI. Counsel against it explicitly.
A34: • THE ELBOW STIFFENS FASTER THAN ANY OTHER JOINT. Early motion is the default, and stiffness is treated with LOW-LOAD PROLONGED STRETCH — never aggressive passive forcing, which provokes heterotopic ossification.
A35: • Yellow cells are inputs. Green text is pulled from another sheet. Do not overwrite formula cells.

Sheet Master Matrix
A3: Region | B3: Activity Level | C3: Common Symptoms | D3: Age Group | E3: Onset | F3: Predominance | G3: Condition | H3: High-Yield Diagnostic Question | I3: Special Test + Imaging | J3: Underlying Biomechanical Cause | K3: DESIRED ACTIVITY GOAL | L3: PHYSIOTHERAPY SPECIFIC EXERCISE | M3: Pain Mechanism | N3: Classification / Cluster | O3: Red Flag Status | P3: MANAGEMENT EMPHASIS | Q3: Loading Stage & Entry Dose | R3: BIOMECHANICAL CORRECTIONS & KINETIC CHAIN | S3: Manual Therapy, Bracing & Adjuncts | T3: Advanced / Surgical Options | U3: Outcome Measures | V3: Re-testable Markers | W3: Expected Timeline | X3: Referral / Surgical Trigger | Y3: Evidence Anchor
A4: Lateral | B4: Manual worker, plumber, chef, keyboard user; also racquet athletes and lifters | C4: Pain gripping/lifting | D4: 35-55 | E4: Slow | F4: Equal | G4: Lateral Elbow Tendinopathy (Common Extensor / ECRB) | H4: Does it hurt at the outside of the elbow when you grip, lift a kettle or shake hands? | I4: Focal tenderness 1-2 cm distal to the lateral epicondyle over the ECRB origin; PAIN-FREE GRIP STRENGTH reduced versus the other side; positive Cozen and Mill tests; clinical diagnosis - ultrasound or MRI only if the picture is atypical or refractory | J4: Tensile overload of the ECRB origin from repetitive gripping and wrist extension exceeding tendon capacity; degenerative tendinosis rather than inflammation; wrist extensor and grip endurance deficits; SHOULDER GIRDLE AND SCAPULAR WEAKNESS transferring load distally; poor forearm rotation control; a sudden increase in gripping, lifting or racquet volume | K4: Grip, lift and carry through a full working day without lateral elbow pain | L4: ISOMETRIC wrist extension holds 5 x 30-45 s for analgesia in the irritable phase; then progressive HEAVY SLOW RESISTANCE wrist extension (or the Tyler twist with a flexbar) 3-4 sets 8-15 RM, 3 s up / 3 s down, 3x/week; supination and pronation loading; grip endurance work; scapular and rotator cuff strengthening (prone Y, external rotation, row); progressive return to gripping and lifting volume | M4: Nociceptive - tensile tendon load; nociplastic overlay common beyond 6 months | N4: Cluster 1 - Lateral elbow tendinopathy: focal ECRB tenderness + reduced pain-free grip + positive resisted wrist extension. Cook & Purdam continuum applies - stage reactivity | O4: No | P4: PROGRESSIVE LOADING AND EDUCATION is first-line. Corticosteroid injection gives short-term relief but WORSE outcomes at 12 months than exercise or wait-and-see - counsel against it. Most cases resolve over 6-12 months; the natural history is favourable but slow | Q4: Stage the tendon. Reactive: isometrics 5 x 30-45 s, 1-2x/day plus reduced peak grip load. Dysrepair/degenerative: heavy slow resistance 3-4 sets 8-15 RM 3x/week; then eccentric and functional gripping load; then sport or occupation-specific | R4: Look proximally - this is rarely just an elbow problem: build scapular and rotator cuff capacity so the forearm is not compensating, correct sustained gripping postures and tool design, review racquet grip size, string tension and backhand technique, reduce keyboard and mouse gripping load, and grade lifting and gripping volume rather than spiking it | S4: Counterforce brace or wrist extension splint for short-term symptom relief during loading; taping; ergonomic and tool modification (a high-yield practical change) | T4: If stalled beyond 12 weeks with correct loading: ESWT has reasonable support; PRP evidence is mixed but more favourable than corticosteroid; percutaneous or open ECRB debridement for genuinely refractory cases after 6-12 months | U4: PRTEE (Patient-Rated Tennis Elbow Evaluation); QuickDASH; PAIN-FREE GRIP STRENGTH is the single best objective marker | V4: Pain-free grip strength (dynamometer, both sides); ECRB tenderness; gripping and lifting tolerance; PRTEE score | W4: 6-12 months for full resolution; meaningful change by 12 weeks | X4: No response after 6-12 months of genuinely correct loading; suspected PIN entrapment or radiocapitellar pathology | Y4: Coombes/Bisset/Vicenzino corticosteroid versus exercise trials; Cook & Purdam continuum
A5: Lateral | B5: Tennis, badminton, table tennis, squash; high repetition racquet load | C5: Pain during racquet sports | D5: 20-45 | E5: Slow | F5: Equal | G5: Radiocapitellar Overload / Synovial Plica Syndrome | H5: Does the outside of the elbow catch or click during the shot, rather than just ache with gripping? | I5: Lateral joint line tenderness POSTERIOR to the ECRB origin; painful clicking on flexion-extension with forearm rotation; positive flexion-pronation test; MRI or arthroscopy - a thickened posterolateral synovial fringe | J5: Repetitive compressive and shear load across the radiocapitellar joint during racquet impact, with a thickened synovial fringe becoming entrapped between the radial head and capitellum; late ball contact and off-centre impact increase load; grip size and string tension errors; poor kinetic-chain transfer forcing the forearm to generate racquet-head speed | K5: Return to full racquet volume without lateral catching or clicking | L5: Wrist extensor and supinator loading 3-4 sets 8-15 RM 3x/week; forearm rotation control work; scapular and rotator cuff strengthening; kinetic-chain drills transferring drive from legs and trunk; avoid provocative repeated flexion-pronation early; graded return to racquet volume with technique review | M5: Nociceptive - mechanical impingement | N5: Lateral group; the key MIMIC of lateral elbow tendinopathy - suspect it when there is CLICKING and joint-line rather than ECRB-origin tenderness | O5: No | P5: Load management, forearm and kinetic-chain rehabilitation, and technique or equipment correction. Arthroscopic plica excision for genuinely refractory mechanical symptoms after a well-delivered programme | Q5: Stage 1-2. Isometric then progressive isotonic wrist extensor and supinator loading; then racquet-specific volume progression | R5: Take the load off the radiocapitellar joint: build scapular, cuff and trunk capacity so the arm is not generating all the racquet-head speed, review grip size and string tension, correct late or off-centre ball contact, and grade playing volume and session frequency | S5: Counterforce brace; equipment and technique review; activity modification | T5: Guided injection (diagnostic and therapeutic); arthroscopic plica excision or radiocapitellar debridement for refractory mechanical symptoms | U5: PRTEE; QuickDASH; MEPS; clicking and catching frequency | V5: Clicking frequency; lateral joint line tenderness; racquet volume tolerance; pain-free grip strength | W5: 8-12 weeks conservative; 6-12 weeks post arthroscopic excision | X5: Persistent mechanical clicking or catching after a genuine 3-month programme | Y5: Radiocapitellar plica literature; lateral elbow differential diagnosis
A6: Lateral | B6: Adolescent thrower, gymnast, racquet athlete; also adults with prior OCD | C6: Locking/catching elbow | D6: 12-25 | E6: Slow | F6: Male athletes | G6: Capitellar Osteochondritis Dissecans / Loose Body | H6: Does the elbow lock, catch or refuse to straighten fully, in a young thrower or gymnast? | I6: Lateral joint line tenderness; LOSS OF TERMINAL EXTENSION is the key early sign; positive active radiocapitellar compression test (pronation-supination with the elbow extended); AP, lateral and 45-degree flexion AP radiographs; MRI to assess lesion stability | J6: Repetitive compressive load across the radiocapitellar joint in a watershed vascular zone; VALGUS load during throwing compresses the lateral column while it distracts the medial; axial upper-limb weight bearing in gymnasts; high throwing or skill volume without recovery; the capitellum has a precarious end-arterial supply | K6: Return to throwing or gymnastics with a healed lesion, full extension and no mechanical symptoms | L6: NO throwing or upper-limb weight bearing during the healing phase. Maintain capacity with lower-body and trunk conditioning, scapular and cuff loading in non-provocative patterns; then progressive forearm and elbow loading; then a staged interval throwing or skill programme once cleared radiologically and clinically | M6: Nociceptive - subchondral bone and cartilage | N6: Lateral group - OCD. STABLE versus UNSTABLE lesion determines everything. Distinguish from PANNER DISEASE (younger, 7-12 years, self-limiting, whole-capitellum involvement) | O6: YES - a young thrower or gymnast with lateral elbow pain and loss of extension needs IMAGING AND REST, not a rehabilitation trial while continuing to load. An unstable lesion or loose body is a surgical presentation | P6: Orthopaedic co-management. STABLE lesion: complete rest from throwing and weight bearing for 3-6 months with serial imaging - many heal. UNSTABLE lesion or loose body: surgical management (drilling, fixation, or OATS depending on size) | Q6: No loading of the lateral column until cleared. Non-provocative conditioning throughout; graded reintroduction of forearm loading, then weight bearing or throwing only with radiological and clinical clearance | R6: Reduce lateral column compression on return: correct throwing mechanics that increase valgus load (late trunk rotation, dropped elbow, excessive elbow extension velocity), build lower-body and trunk contribution, cap pitch counts and skill repetitions, enforce rest days and a genuine off-season, and reduce upper-limb weight-bearing volume in gymnasts | S6: Complete load removal is the intervention; bracing per surgeon in selected cases; education for coach and parent | T6: Arthroscopic drilling for a stable lesion that fails to heal; fragment fixation, loose body removal, or OATS/osteochondral graft for an unstable or large lesion (see Post-Surgical Guide, category 6) | U6: MEPS; QuickDASH; OES; radiographic and MRI healing; extension range | V6: Terminal extension range; mechanical symptoms; radiocapitellar compression test; throwing or weight-bearing tolerance | W6: 3-6 months for a stable lesion; 6-12 months post cartilage surgery | X6: Loss of extension, locking, a loose body, or an unstable lesion on MRI - orthopaedic referral | Y6: Capitellar OCD management literature; ICRS OCD classification
A7: Lateral | B7: Gymnast, climber, thrower; also post-traumatic after dislocation or lateral surgery | C7: Instability during pushing | D7: 20-50 | E7: Slow/Sudden | F7: Male | G7: Posterolateral Rotatory Instability (PLRI) | H7: Does the elbow feel like it is going to give way when you push up out of a chair or off the floor? | I7: Positive lateral pivot-shift and posterolateral rotatory drawer tests (often needs examination under anaesthesia); POSITIVE CHAIR PUSH-UP AND TABLE-TOP RELOCATION TESTS are the most practical clinical signs; stress radiographs or MRI of the lateral ulnar collateral ligament | J7: Insufficiency of the LATERAL ULNAR COLLATERAL LIGAMENT - most often after an elbow dislocation, but also from repeated varus stress, cumulative attrition, iatrogenic injury during lateral tendon surgery, or repeated corticosteroid injection at the lateral epicondyle; deficient dynamic control from the extensor-supinator mass compounds it | K7: Push up out of a chair, weight-bear through the arm and return to sport without apprehension or giving way | L7: Extensor-supinator mass strengthening as dynamic stabilisers; progressive CLOSED-CHAIN loading (wall push-up, quadruped weight shift, progressing to table and floor) 3-4 sets 3x/week; rhythmic stabilisation and proprioceptive work; scapular and cuff capacity; AVOID varus stress and provocative supination-extension positions early; graded return to weight bearing | M7: Nociceptive with apprehension and fear components | N7: Lateral group - INSTABILITY. Frequently missed and mislabelled as refractory tennis elbow. A history of dislocation or repeated lateral injection is the giveaway | O7: Screen: ASK ABOUT PRIOR DISLOCATION AND PRIOR LATERAL INJECTIONS in any refractory lateral elbow presentation | P7: Rehabilitation of the dynamic stabilisers with closed-chain and proprioceptive loading for low-grade cases. LUCL reconstruction for significant symptomatic instability - rehabilitation cannot replace an incompetent ligament | Q7: Stage 1-3. Isometric and closed-chain work in protected range; progressive extensor-supinator and closed-chain loading; then weight bearing and sport-specific progression | R7: Build dynamic control and remove the provocation: strengthen the extensor-supinator mass, avoid varus and supination-extension loading, retrain push-up and weight-bearing mechanics, build scapular and trunk capacity, and STOP corticosteroid injections at the lateral epicondyle | S7: Hinged elbow brace blocking terminal extension and supination in the protected phase; activity modification | T7: LUCL reconstruction with a tendon graft (see Post-Surgical Guide, category 8) - protection 6 weeks in a hinged brace, return to sport 6-9 months | U7: MEPS; OES; QuickDASH; apprehension and giving-way frequency | V7: Chair push-up and table-top relocation tests; giving-way episodes; closed-chain loading tolerance | W7: 12 weeks conservative trial for low-grade; 6-9 months post reconstruction | X7: Significant symptomatic instability, recurrent giving way, or a positive pivot-shift - orthopaedic referral | Y7: O'Driscoll PLRI description; LUCL reconstruction outcomes
A8: Lateral | B8: Manual worker, cyclist, racquet athlete; repetitive forearm rotation | C8: Numbness and weakness | D8: 30-50 | E8: Slow | F8: Equal | G8: Radial Tunnel / Posterior Interosseous Nerve Syndrome | H8: Is the sore spot several centimetres BELOW the bony point, in the muscle, rather than on the bone itself? | I8: Tenderness 4-5 cm DISTAL to the lateral epicondyle over the supinator (not at the ECRB origin); pain on RESISTED SUPINATION and resisted middle finger extension; radial tunnel syndrome causes pain WITHOUT weakness, PIN syndrome causes MOTOR WEAKNESS (finger and thumb extension) WITHOUT sensory loss; nerve conduction studies and EMG | J8: Compression of the posterior interosseous nerve as it passes through the radial tunnel, most often at the arcade of Frohse at the proximal supinator edge; repetitive forceful forearm pronation-supination, sustained elbow extension with pronation, and a space-occupying lesion or ganglion are the drivers | K8: Resolve the forearm pain and restore finger and thumb extension strength; return to full manual or sporting load | L8: Radial nerve gliding within symptom tolerance; supinator and forearm load reduction initially; progressive wrist and finger extensor loading as symptoms allow (respecting that a denervated muscle fatigues quickly in PIN); scapular and cuff strengthening; graded return to forearm rotation load with technique and tool review | M8: Neuropathic | N8: Lateral group - PERIPHERAL NERVE. The key mimic of lateral elbow tendinopathy: tenderness is 4-5 cm DISTAL and resisted supination provokes it. PIN syndrome has WEAKNESS; radial tunnel syndrome does not | O8: YES for PIN SYNDROME - progressive finger and thumb extension weakness (finger drop) requires prompt nerve conduction studies and surgical opinion, and imaging to exclude a mass lesion | P8: Remove the compressive and repetitive load; neural mobilisation; progressive loading as symptoms allow. Surgical decompression of the radial tunnel for confirmed PIN weakness or genuinely refractory radial tunnel syndrome | Q8: Loading is guided by nerve irritability. Neural gliding first; low-load extensor work; progress as symptoms and strength allow. Do not fatigue a denervated muscle early | R8: Reduce the compression and traction: modify repetitive forceful supination and pronation tasks, review tool design and grip, avoid sustained elbow extension with pronation, build scapular and cuff capacity to reduce distal compensation, and review handlebar position in cyclists | S8: Activity and tool modification; splinting in selected cases; neural gliding education | T8: Nerve conduction studies and EMG; imaging to exclude a ganglion or mass; surgical radial tunnel decompression (see Post-Surgical Guide, category 3) | U8: QuickDASH; MEPS; grip and finger extension strength; symptom mapping | V8: Finger and thumb extension strength; resisted supination pain; tenderness location; grip strength | W8: 8-16 weeks conservatively; longer where decompression is needed | X8: Progressive motor weakness, finger drop, or suspected mass lesion - prompt referral | Y8: Radial tunnel and PIN syndrome literature
A9: Lateral | B9: Contact sport, fall onto an outstretched hand | C9: Lateral elbow pain and swelling after a fall, with painful forearm rotation | D9: 20-50 | E9: Sudden | F9: Equal | G9: Radial Head Fracture | H9: Since falling on the outstretched hand, is it painful and blocked to turn the palm up and down? | I9: Lateral joint line tenderness; painful and often BLOCKED forearm rotation; effusion with a positive fat pad sign; AP, lateral and radiocapitellar (Greenspan) radiographs; CT for comminution; MASON classification | J9: Axial load transmitted through the radial head during a fall onto the outstretched hand with the forearm pronated; associated injuries are common - assess the LUCL, the MCL, the coronoid and the distal radioulnar joint (Essex-Lopresti) | K9: Restore painless full forearm rotation and elbow extension; return to lifting and sport | L9: EARLY MOBILISATION is the priority in a stable Mason I fracture - the elbow stiffens fast. Active and active-assisted flexion-extension and forearm rotation from days 3-7; progressive isometric then isotonic forearm and elbow loading from 3-6 weeks; grip strengthening; scapular and cuff work; graded return to loading | M9: Nociceptive - acute fracture | N9: Lateral group - TRAUMA. Mason I (undisplaced) to Mason IV (with dislocation). ALWAYS screen the wrist and the whole forearm axis | O9: YES - a BLOCKED forearm rotation suggests a mechanical block needing surgical opinion. Screen for associated LUCL, coronoid and distal radioulnar joint injury | P9: Mason I: conservative with EARLY MOBILISATION - stiffness is the main complication, not displacement. Mason II-IV: orthopaedic opinion for fixation or radial head replacement. Aspiration with local anaesthetic can help early range | Q9: Early motion from days 3-7 in a stable fracture; progressive loading from 3-6 weeks; full loading by 8-12 weeks with union | R9: Prevent stiffness above all: early active range in all planes, avoid prolonged immobilisation, restore forearm rotation early, and rebuild grip, forearm and scapular capacity as range returns | S9: Sling for comfort only and for the shortest possible time; early range education | T9: Open reduction and internal fixation or radial head replacement for displaced or comminuted fractures; excision in selected low-demand cases | U9: MEPS; OES; QuickDASH; range in degrees | V9: Flexion-extension and forearm rotation range; grip strength LSI; radiographic union | W9: 6-12 weeks; longer if surgical | X9: Blocked rotation, displacement, or suspected associated ligament or wrist injury | Y9: Mason classification; early mobilisation evidence in radial head fracture
A10: Lateral | B10: Contact sport, fall onto an outstretched hand, gymnastics | C10: Acute lateral elbow pain after a varus force or dislocation | D10: 15-40 | E10: Sudden | F10: Male | G10: Lateral Collateral Ligament Complex Sprain | H10: Did the elbow take a force that pushed it outwards, or did it dislocate and go back in? | I10: Lateral tenderness over the LCL complex; pain and laxity on VARUS stress in 30 degrees flexion; assess for posterolateral rotatory instability with the chair push-up and table-top tests; radiographs to exclude fracture; MRI for the ligament complex | J10: Varus or posterolateral rotatory force disrupting the lateral collateral ligament complex, including the LUCL; commonly part of the dislocation spectrum; the extensor-supinator mass provides the dynamic backup that is often deconditioned | K10: Return to weight bearing and contact sport with a stable elbow and no apprehension | L10: Protected range early avoiding varus stress and supination-extension; isometric then progressive extensor-supinator loading; closed-chain and proprioceptive work; scapular and cuff capacity; graded return to weight bearing and contact | M10: Nociceptive - traumatic ligamentous | N10: Lateral group; low-grade sprains do well conservatively, but an unrecognised LUCL injury becomes chronic PLRI | O10: Screen: assess for PLRI - an untreated LUCL injury is the commonest route to chronic posterolateral rotatory instability | P10: Protected mobilisation with early range, then progressive dynamic stabiliser loading. Surgical repair or reconstruction where there is significant instability or an associated complex injury | Q10: Stage 1-3. Protected range 2-3 weeks avoiding varus and supination-extension; progressive extensor-supinator and closed-chain loading; then weight bearing and sport | R10: Build the dynamic backup: extensor-supinator mass strengthening, closed-chain proprioception, scapular and trunk capacity; avoid varus loading and terminal extension-supination during healing | S10: Hinged brace limiting terminal extension and supination in the protected phase | T10: LUCL repair or reconstruction for significant instability (see Post-Surgical Guide, category 8) | U10: MEPS; OES; QuickDASH | V10: Varus laxity; chair push-up test; range; weight-bearing tolerance | W10: 6-12 weeks for a low-grade sprain | X10: Significant laxity, recurrent instability, or a positive pivot-shift | Y10: Elbow instability spectrum literature
A11: Lateral | B11: Weightlifting, CrossFit, gymnastics; high axial and rotational load | C11: Deep lateral ache with pressing and weight bearing | D11: 25-45 | E11: Slow | F11: Male | G11: Radiocapitellar Chondral Lesion | H11: Does the outside of the elbow ache deeply after pressing or weight-bearing work, and swell afterwards? | I11: Lateral joint line tenderness; pain on axial loading and active radiocapitellar compression; effusion after loading; MRI with cartilage sequences; often coexists with prior OCD or loose bodies | J11: Repetitive compressive and shear load across the radiocapitellar joint from pressing, Olympic lifting and upper-limb weight bearing; prior OCD, loose bodies or valgus overload concentrate load laterally; poor kinetic-chain transfer increases elbow load in overhead lifts | K11: Return to pressing and weight-bearing training within a sustainable load ceiling, without swelling | L11: Non-provocative strengthening first (grip, forearm, scapular, cuff); progressive closed-chain loading; graded reintroduction of pressing and weight bearing using SWELLING as the tolerance signal; ongoing volume management | M11: Nociceptive - articular surface overload | N11: Lateral group; assess for the underlying driver - prior OCD, loose bodies or valgus overload | O11: Screen: mechanical locking with effusion warrants imaging for a loose body | P11: Load management and capacity building with a realistic long-term ceiling. Address any loose body or underlying OCD surgically where symptomatic | Q11: Stage 1-3. Non-provocative loading first; progressive closed-chain; graded impact and pressing reintroduction with effusion as the tolerance signal | R11: Lower the contact stress: build scapular, cuff and trunk capacity so the elbow is not the limiting link in overhead lifts, modify pressing volume and range, correct bar path and receiving position in Olympic lifts, and cap weight-bearing volume in gymnastics | S11: Activity and volume modification; taping for comfort | T11: Arthroscopic loose body removal or debridement; cartilage procedures for a focal defect (see Post-Surgical Guide, category 6) | U11: MEPS; OES; QuickDASH | V11: Effusion after loading; lateral joint line tenderness; pressing and weight-bearing tolerance | W11: 3-6 months conservative; longer post cartilage surgery | X11: Mechanical locking, persistent effusion, or a loose body on imaging | Y11: Elbow chondral lesion management literature
A12: Medial | B12: Golf, cricket, climbing, weightlifting, manual work; repetitive gripping and wrist flexion | C12: Pain during throwing | D12: 35-55 | E12: Slow | F12: Equal | G12: Medial Elbow Tendinopathy (Common Flexor-Pronator / Golfer's Elbow) | H12: Does it hurt at the inside of the elbow when you grip, throw or turn the palm down against resistance? | I12: Focal tenderness at the common flexor-pronator origin just distal to the medial epicondyle; pain on RESISTED WRIST FLEXION AND PRONATION; reduced pain-free grip; clinical diagnosis - ultrasound if atypical. ALWAYS test the ulnar nerve - the two coexist in a substantial proportion | J12: Tensile overload of the common flexor-pronator origin from repetitive gripping, wrist flexion and pronation exceeding capacity; degenerative tendinosis; the flexor-pronator mass is also the DYNAMIC STABILISER against valgus, so it is overloaded further in throwing athletes; scapular and trunk deficits transfer load distally | K12: Grip, throw, lift and swing through full volume without medial elbow pain | L12: ISOMETRIC wrist flexion and pronation holds 5 x 30-45 s for analgesia; then HEAVY SLOW RESISTANCE wrist flexion and pronation (or the reverse Tyler twist) 3-4 sets 8-15 RM, 3 s up / 3 s down, 3x/week; grip endurance; scapular and rotator cuff loading; trunk and lower-body kinetic-chain work; graded return to gripping, throwing or swing volume | M12: Nociceptive - tensile tendon load | N12: Cluster 2 - Medial elbow tendinopathy: flexor-pronator origin tenderness + pain on resisted wrist flexion and pronation. ALWAYS screen the ulnar nerve and the UCL alongside | O12: Screen: TEST THE ULNAR NERVE AND THE UCL in every medial elbow presentation - all three commonly coexist and the management differs | P12: Progressive loading and education, as for the lateral side. Corticosteroid injection carries the same poor long-term profile and additional ulnar nerve risk - avoid it. Address the kinetic chain in throwing and swinging athletes | Q12: Stage the tendon. Reactive: isometrics plus peak load reduction. Dysrepair/degenerative: heavy slow resistance 3-4 sets 8-15 RM 3x/week; then energy-storage and sport-specific loading | R12: Look proximally and distally: build scapular, cuff, trunk and lower-body capacity so the forearm is not generating all the force, correct golf swing mechanics (over-the-top downswing, ground strike), review racquet and club grip size, correct throwing mechanics, and grade gripping and swing volume | S12: Counterforce brace for short-term relief; taping; equipment and technique review; ergonomic modification | T12: If stalled beyond 12 weeks: ESWT or PRP as adjuncts while continuing to load; surgical debridement of the flexor-pronator origin for genuinely refractory cases | U12: PRTEE (adapted); QuickDASH; MEPS; PAIN-FREE GRIP STRENGTH | V12: Pain-free grip strength; resisted wrist flexion and pronation pain; throwing or swing volume tolerance | W12: 6-12 months for full resolution; meaningful change by 12 weeks | X12: No response after 6-12 months of correct loading; coexisting ulnar neuropathy or UCL insufficiency | Y12: Cook & Purdam continuum; medial epicondylalgia management literature
A13: Medial | B13: Baseball pitching, cricket bowling and throwing, javelin, tennis serve | C13: Pain during pitching | D13: 16-30 | E13: Slow | F13: Male athletes | G13: Ulnar Collateral Ligament (UCL) Injury - Partial / Attritional | H13: Does the inside of the elbow hurt specifically at the late cocking or acceleration phase of the throw? | I13: Medial joint line tenderness over the UCL (not the flexor origin); pain and laxity on VALGUS STRESS at 30 degrees; positive MOVING VALGUS STRESS TEST (pain reproduced between 120 and 70 degrees) - the most useful clinical test; MR ARTHROGRAM or dynamic ultrasound; stress radiographs for medial joint gapping | J13: Repetitive VALGUS TORQUE during the late cocking and acceleration phases exceeding UCL capacity; the flexor-pronator mass is the dynamic protector and fatigues; poor kinetic-chain sequencing means the arm generates force the legs and trunk should; excessive pitch counts, pitching on consecutive days, throwing while fatigued, and radar-gun-driven velocity chasing are the load errors | K13: Return to full-velocity throwing with a stable medial elbow and no loss of velocity or control | L13: Flexor-pronator mass strengthening as the dynamic valgus stabiliser (wrist flexion, pronation, grip) 3-4 sets 8-15 RM 3x/week; scapular and rotator cuff loading; posterior cuff eccentric capacity for deceleration; TRUNK AND LOWER-BODY kinetic-chain work; hip and thoracic rotation mobility; then a staged INTERVAL THROWING PROGRAMME | M13: Nociceptive - tensile ligamentous | N13: Cluster 3 - UCL injury: medial pain at late cocking or acceleration + UCL tenderness + positive moving valgus stress test. Distinguish from flexor-pronator tendinopathy, which is tender more anteriorly and distally | O13: Screen: assess the ULNAR NERVE and screen for VALGUS EXTENSION OVERLOAD posteriorly - the valgus overload triad travels together | P13: Rehabilitation first for a partial or low-grade injury: flexor-pronator strengthening, kinetic-chain correction and a staged interval throwing programme. PRP has emerging support for partial tears in throwers. UCL reconstruction or internal-brace repair for a complete tear or a failed programme | Q13: Stage 1-4. No throwing initially; flexor-pronator, scapular, cuff and kinetic-chain loading; then a staged interval throwing programme progressing distance then intensity then mound work | R13: Reduce the valgus torque reaching the ligament: build flexor-pronator capacity as the dynamic stabiliser, increase lower-body and trunk contribution to the throw, restore hip and thoracic rotation, correct a dropped elbow and late trunk rotation, and STRICTLY manage pitch counts, rest days and throwing while fatigued | S13: Activity modification; throwing volume monitoring; hinged brace in selected cases | T13: PRP for partial tears in throwers (emerging support); UCL RECONSTRUCTION (Tommy John) or UCL repair with internal brace for complete tears or failed rehabilitation (see Post-Surgical Guide, category 2) | U13: KJOC; MEPS; QuickDASH; throwing velocity and control | V13: Moving valgus stress test; medial joint gapping on stress ultrasound; flexor-pronator strength; throwing volume tolerance | W13: 3-6 months conservative; 9-12 months post reconstruction, 6-9 months post internal-brace repair | X13: Complete tear, valgus instability, or failure of a genuine 3-month programme in a throwing athlete | Y13: Moving valgus stress test (O'Driscoll); UCL reconstruction outcome literature
A14: Medial | B14: Cyclist, thrower, weightlifter, manual worker; also prolonged elbow flexion postures | C14: Numbness ring/little finger | D14: 30-55 | E14: Slow | F14: Male | G14: Cubital Tunnel Syndrome (Ulnar Neuropathy) | H14: Is the numbness in the little finger and half the ring finger, and worse when the elbow is bent for a while? | I14: Sensory change in the ulnar distribution (little finger and ulnar half of the ring finger); positive Tinel over the cubital tunnel; positive ELBOW FLEXION TEST held 60 seconds; intrinsic hand weakness, first dorsal interosseous wasting and a positive Froment sign in advanced cases; NERVE CONDUCTION STUDIES to localise and grade | J14: Compression or traction of the ulnar nerve at the cubital tunnel - between the medial epicondyle and olecranon, under Osborne's ligament, or at the arcade of Struthers; sustained elbow flexion (sleeping, phone use, cycling), repeated valgus load in throwers, direct pressure on the cubital tunnel, and nerve subluxation over the epicondyle | K14: Resolve the numbness and restore grip and pinch strength; sleep and cycle without symptoms | L14: Ulnar nerve gliding within symptom tolerance (avoid aggressive tensioning); NIGHT EXTENSION SPLINTING or a towel wrap to prevent sustained flexion - often the highest-yield single change; scapular and cuff strengthening; grip and intrinsic hand strengthening as symptoms allow; posture and equipment modification | M14: Neuropathic | N14: Medial group - PERIPHERAL NERVE. Grade it: intermittent sensory only (mild), persistent sensory (moderate), motor weakness and wasting (severe - refer) | O14: YES if there is INTRINSIC MUSCLE WASTING OR WEAKNESS - motor involvement means surgical decompression should not be delayed, as recovery of wasted intrinsics is poor | P14: Conservative first for sensory-only symptoms: activity and posture modification, NIGHT EXTENSION SPLINTING, nerve gliding, and removing direct pressure. This resolves a substantial proportion. Surgical decompression for motor involvement or genuine failure of 3 months of conservative care | Q14: Loading is guided by nerve irritability. Nerve gliding and postural change first; progressive grip and forearm loading as symptoms allow; avoid sustained end-range flexion | R14: Remove the flexion and the pressure: night splinting or towel wrap to keep the elbow under 45 degrees, avoid leaning on the elbow, modify phone and desk posture, raise handlebars and reduce elbow flexion in cyclists, and cap throwing volume where valgus load is the driver | S14: NIGHT EXTENSION SPLINT (the key adjunct); elbow padding; workstation, phone and handlebar modification | T14: Nerve conduction studies to grade; in-situ cubital tunnel decompression, or ulnar nerve transposition where the nerve subluxates or in throwing athletes (see Post-Surgical Guide, category 3) | U14: QuickDASH; MEPS; grip and pinch strength; symptom mapping and frequency | V14: Numbness frequency; elbow flexion test time to symptoms; grip and pinch strength; first dorsal interosseous bulk | W14: 8-12 weeks conservatively for sensory-only presentations | X14: Any intrinsic weakness or wasting; failure of 3 months of correct conservative care | Y14: Cubital tunnel management guidelines; McGowan grading
... A41: Neurological | B41: Any; immunosuppression, diabetes, penetrating injury or recent injection | C41: Hot, swollen, exquisitely painful elbow with fever | D41: Any | E41: Sudden | F41: Equal | G41: Septic Arthritis of the Elbow | H41: Did severe elbow pain and swelling come on quickly with fever, and is any movement excruciating? | I41: Marked pain limiting ALL active and passive movement; warmth, swelling and effusion; fever and systemic illness; URGENT ASPIRATION for cell count, Gram stain and culture; inflammatory markers and blood cultures | J41: Infective - haematogenous spread, penetrating injury, or contamination following injection or surgery. Not biomechanical. DISTINGUISH FROM SEPTIC OLECRANON BURSITIS, which is superficial with relatively preserved joint range | K41: Eradicate the infection, then restore range, strength and function | L41: NONE until medically cleared. Post-clearance: gentle range restoration (the elbow stiffens quickly), progressive strengthening, and graded return to function in a joint that may have sustained cartilage damage | M41: Inflammatory / infective | N41: Neurological/systemic group - EMERGENCY. Pain on ALL movement with systemic features distinguishes septic arthritis from septic bursitis, where range is relatively preserved | O41: YES - EMERGENCY. Cartilage destruction begins within days. Rehabilitation is contraindicated until the infection is managed | P41: URGENT medical and orthopaedic referral for aspiration, culture and intravenous antibiotics, with surgical washout as indicated. Do not treat locally under any circumstances | Q41: None until cleared. Post-clearance: early gentle range is the priority, then progressive strengthening | R41: Post-infection: restore range early because the elbow stiffens fast, reverse disuse deconditioning, rebuild grip, forearm and scapular capacity, and adapt for any residual joint damage | S41: None in the acute phase | T41: Urgent aspiration, intravenous antibiotics and surgical washout | U41: Medical markers (CRP, ESR, white cell count); post-recovery MEPS and range | V41: Post-recovery: range, strength, functional tasks | W41: Medical resolution first; rehabilitation over 3-6 months thereafter | X41: IMMEDIATE - emergency medical referral | Y41: Septic arthritis emergency pathways

Sheet Rx Generator
A1: PRESCRIPTION GENERATOR
A2: Select a condition in the yellow cell. Every field below is pulled live from the Master Matrix.
A4: SELECT CONDITION → | B4: Septic Arthritis of the Elbow
A6: Region | B6: =IFERROR(INDEX('Master Matrix'!A$4:A$41,MATCH($B$4,'Master Matrix'!$G$4:$G$41,0)),"") -> Neurological
A7: Activity level | B7: =IFERROR(INDEX('Master Matrix'!B$4:B$41,MATCH($B$4,'Master Matrix'!$G$4:$G$41,0)),"") -> Any; immunosuppression, diabetes, penetrating injury or recent injection
A8: Common symptoms | B8: =IFERROR(INDEX('Master Matrix'!C$4:C$41,MATCH($B$4,'Master Matrix'!$G$4:$G$41,0)),"") -> Hot, swollen, exquisitely painful elbow with fever
A9: Age group | B9: =IFERROR(INDEX('Master Matrix'!D$4:D$41,MATCH($B$4,'Master Matrix'!$G$4:$G$41,0)),"") -> Any
A10: Onset | B10: =IFERROR(INDEX('Master Matrix'!E$4:E$41,MATCH($B$4,'Master Matrix'!$G$4:$G$41,0)),"") -> Sudden
A11: Predominance | B11: =IFERROR(INDEX('Master Matrix'!F$4:F$41,MATCH($B$4,'Master Matrix'!$G$4:$G$41,0)),"") -> Equal
A12: High-yield diagnostic question | B12: =IFERROR(INDEX('Master Matrix'!H$4:H$41,MATCH($B$4,'Master Matrix'!$G$4:$G$41,0)),"") -> Did severe elbow pain and swelling come on quickly with fever, and is any movement excruciating?
A13: Special test + imaging | B13: =IFERROR(INDEX('Master Matrix'!I$4:I$41,MATCH($B$4,'Master Matrix'!$G$4:$G$41,0)),"") -> Marked pain limiting ALL active and passive movement; warmth, swelling and effusion; fever and systemic illness; URGENT ASPIRATION for cell count, Gram stain and culture; inflammatory markers and blood cultures
A14: Underlying biomechanical cause | B14: =IFERROR(INDEX('Master Matrix'!J$4:J$41,MATCH($B$4,'Master Matrix'!$G$4:$G$41,0)),"") -> Infective - haematogenous spread, penetrating injury, or contamination following injection or surgery. Not biomechanical. DISTINGUISH FROM SEPTIC OLECRANON BURSITIS, which is superficial with relatively preserved joint range
A15: DESIRED ACTIVITY GOAL | B15: =IFERROR(INDEX('Master Matrix'!K$4:K$41,MATCH($B$4,'Master Matrix'!$G$4:$G$41,0)),"") -> Eradicate the infection, then restore range, strength and function
A16: PHYSIOTHERAPY SPECIFIC EXERCISE | B16: =IFERROR(INDEX('Master Matrix'!L$4:L$41,MATCH($B$4,'Master Matrix'!$G$4:$G$41,0)),"") -> NONE until medically cleared. Post-clearance: gentle range restoration (the elbow stiffens quickly), progressive strengthening, and graded return to function in a joint that may have sustained cartilage damage
A17: Pain mechanism | B17: =IFERROR(INDEX('Master Matrix'!M$4:M$41,MATCH($B$4,'Master Matrix'!$G$4:$G$41,0)),"") -> Inflammatory / infective
A18: Classification / cluster | B18: =IFERROR(INDEX('Master Matrix'!N$4:N$41,MATCH($B$4,'Master Matrix'!$G$4:$G$41,0)),"") -> Neurological/systemic group - EMERGENCY. Pain on ALL movement with systemic features distinguishes septic arthritis from septic bursitis, where range is relatively preserved
A19: RED FLAG STATUS | B19: =IFERROR(INDEX('Master Matrix'!O$4:O$41,MATCH($B$4,'Master Matrix'!$G$4:$G$41,0)),"") -> YES - EMERGENCY. Cartilage destruction begins within days. Rehabilitation is contraindicated until the infection is managed
A20: MANAGEMENT EMPHASIS | B20: =IFERROR(INDEX('Master Matrix'!P$4:P$41,MATCH($B$4,'Master Matrix'!$G$4:$G$41,0)),"") -> URGENT medical and orthopaedic referral for aspiration, culture and intravenous antibiotics, with surgical washout as indicated. Do not treat locally under any circumstances
A21: Loading stage & entry dose | B21: =IFERROR(INDEX('Master Matrix'!Q$4:Q$41,MATCH($B$4,'Master Matrix'!$G$4:$G$41,0)),"") -> None until cleared. Post-clearance: early gentle range is the priority, then progressive strengthening
A22: BIOMECHANICAL CORRECTIONS & KINETIC CHAIN | B22: =IFERROR(INDEX('Master Matrix'!R$4:R$41,MATCH($B$4,'Master Matrix'!$G$4:$G$41,0)),"") -> Post-infection: restore range early because the elbow stiffens fast, reverse disuse deconditioning, rebuild grip, forearm and scapular capacity, and adapt for any residual joint damage
A23: Manual therapy, bracing & adjuncts | B23: =IFERROR(INDEX('Master Matrix'!S$4:S$41,MATCH($B$4,'Master Matrix'!$G$4:$G$41,0)),"") -> None in the acute phase
A24: Advanced / surgical options | B24: =IFERROR(INDEX('Master Matrix'!T$4:T$41,MATCH($B$4,'Master Matrix'!$G$4:$G$41,0)),"") -> Urgent aspiration, intravenous antibiotics and surgical washout
A25: Outcome measures | B25: =IFERROR(INDEX('Master Matrix'!U$4:U$41,MATCH($B$4,'Master Matrix'!$G$4:$G$41,0)),"") -> Medical markers (CRP, ESR, white cell count); post-recovery MEPS and range
A26: Re-testable markers | B26: =IFERROR(INDEX('Master Matrix'!V$4:V$41,MATCH($B$4,'Master Matrix'!$G$4:$G$41,0)),"") -> Post-recovery: range, strength, functional tasks
A27: Expected timeline | B27: =IFERROR(INDEX('Master Matrix'!W$4:W$41,MATCH($B$4,'Master Matrix'!$G$4:$G$41,0)),"") -> Medical resolution first; rehabilitation over 3-6 months thereafter
A28: Referral / surgical trigger | B28: =IFERROR(INDEX('Master Matrix'!X$4:X$41,MATCH($B$4,'Master Matrix'!$G$4:$G$41,0)),"") -> IMMEDIATE - emergency medical referral
A29: Evidence anchor | B29: =IFERROR(INDEX('Master Matrix'!Y$4:Y$41,MATCH($B$4,'Master Matrix'!$G$4:$G$41,0)),"") -> Septic arthritis emergency pathways
A31: NOTES
A32: • Green text is pulled from the Master Matrix — edit the matrix, not this sheet.
A33: • Check RED FLAG STATUS first. A crimson entry means screen or refer before rehabilitating.
A34: • The DESIRED ACTIVITY GOAL and PHYSIOTHERAPY SPECIFIC EXERCISE rows are written to be handed straight to the patient.
A35: • Print this sheet (portrait, fit to one page wide) for the patient file.

Sheet Assessment Roadmap
A1: FIVE-GATE ASSESSMENT ROADMAP
A2: Work top to bottom. Gate 4 — quadrant, then tissue — does most of the diagnostic work.
A3: Gate | B3: Purpose | C3: What You Assess | D3: Findings That Matter | E3: Decision Rule
A4: GATE 1 | B4: Screen for serious and time-critical pathology | C4: Compartment syndrome; septic arthritis; acute tendon rupture; fracture; neurovascular compromise; malignancy | D4: ESCALATING FOREARM PAIN OUT OF PROPORTION with pain on passive finger extension = COMPARTMENT SYNDROME (normal pulses do NOT exclude it). Hot swollen elbow with fever and pain on ALL movement = septic arthritis. Sudden inability to extend against gravity = triceps rupture. Pop with a positive hook test = distal biceps rupture. Deformity with inability to move after a fall = fracture. Any child with a displaced supracondylar fracture is an emergency | E4: Any positive -> refer BEFORE any local treatment
A5: GATE 2 | B5: Screen the cervical spine and the shoulder | C5: Cervical range, Spurling, distraction, neurodynamic tests; shoulder range and scapular control | D5: WAINNER CLUSTER: Spurling positive + distraction relief + upper limb neurodynamic test positive + cervical rotation under 60 degrees. Pain travelling past the elbow into the hand with dermatomal or myotomal signs. Symptoms changed more by neck than elbow movement. Also assess the SHOULDER - scapular and cuff deficits load the elbow distally in every throwing and gripping presentation | E5: The elbow is frequently the messenger, not the message - clear the neck and assess the shoulder before committing
A6: GATE 3 | B6: Traumatic or overuse? | C6: Mechanism, timing, and whether there was a discrete event | D6: TRAUMATIC: fall onto outstretched hand (radial head, supracondylar, capsular), a pop with bruising (biceps or triceps rupture), a dislocation (collateral ligaments, PLRI), forced hyperextension. OVERUSE: gradual onset with a load or volume change - tendinopathy, bone stress, apophysitis, nerve compression. SKELETAL IMMATURITY changes everything: the apophysis and physis fail before the tendon or ligament | E6: Traumatic weakness after a pop is a surgical question, not a rehabilitation one
A7: GATE 4 | B7: Which quadrant, and is it TENDON, LIGAMENT, NERVE, JOINT or BONE? | C7: Localise by quadrant, then by tissue - the branch that does most of the diagnostic work | D7: LATERAL: ECRB origin = tendinopathy; 4-5 cm distal with supination pain = radial tunnel; joint line with clicking = plica or chondral; locking with lost extension = OCD or loose body; giving way on push-up = PLRI. MEDIAL: flexor origin = tendinopathy; UCL with valgus pain in a thrower = UCL; ulnar distribution numbness = cubital tunnel; apophysis in a child = Little League elbow. POSTERIOR: tip swelling = bursitis; terminal extension pain in a thrower = valgus extension overload; extension weakness = triceps rupture. ANTERIOR: resisted supination pain = distal biceps; a pop with a positive hook test = rupture | E7: Quadrant plus tissue type gives the working diagnosis in most presentations
A8: GATE 5 | B8: Quantify range, strength and irritability | C8: Flexion-extension and forearm rotation; PAIN-FREE GRIP STRENGTH; valgus and varus stability; nerve status | D8: Flexion, extension (loss of TERMINAL EXTENSION is the earliest and most sensitive sign of intra-articular pathology), pronation and supination; PAIN-FREE GRIP with a dynamometer both sides; resisted wrist extension, flexion, pronation and supination; valgus and varus stress; moving valgus stress test in throwers; full peripheral nerve screen; irritability grading | E8: These become the baseline re-testable markers. LOSS OF TERMINAL EXTENSION and REDUCED PAIN-FREE GRIP are the two highest-yield objective measures in the elbow
A10: DIAGNOSTIC ALGORITHM — NARRATIVE FLOW
A11: • Elbow pain → Emergencies? (compartment syndrome, sepsis, acute rupture, fracture, neurovascular) → YES: refer. NO ↓
A12: • Referred from the neck, or driven by a weak shoulder girdle? → Treat the source; address the scapula and cuff regardless. ↓
A13: • Traumatic or overuse? A pop with weakness after trauma is a SURGICAL question. ↓
A14: • SKELETALLY IMMATURE? The apophysis and physis fail first — image BOTH elbows. ↓
A15: • LATERAL → ECRB origin tenderness with reduced pain-free grip = tendinopathy. Tender 4-5 cm distal with resisted supination pain = radial tunnel. Clicking at the joint line = plica or chondral. Locking with lost extension = OCD or loose body. Giving way on push-up = PLRI.
A16: • MEDIAL → flexor origin tenderness = tendinopathy. Valgus pain at late cocking with a positive moving valgus stress test = UCL. Ulnar numbness = cubital tunnel. Apophyseal tenderness in a child = Little League elbow.
A17: • POSTERIOR → tip swelling = bursitis. Terminal extension pain in a thrower = valgus extension overload. Extension weakness = triceps rupture. Locking = loose body.
A18: • ANTERIOR → resisted supination pain with an intact hook test = distal biceps tendinopathy. A pop with a POSITIVE hook test = rupture. Deep pain on resisted flexion in pronation = brachialis.
A19: • Then quantify range with END-FEEL, PAIN-FREE GRIP, resisted testing, stability and nerve status → set baseline markers → enter the Phased Programme.
A21: CLINICAL PEARL
A22: • Convert every diagnosis into two or three re-testable markers BEFORE you treat — PAIN-FREE GRIP, terminal extension range, and pain on the primary resisted test.
A23: • If those markers do not improve over 4-6 weeks of appropriate loading, RECONSIDER THE DIAGNOSIS rather than adding modalities. The elbow has more mimics than almost any other region.

Sheet Subjective Exam
A1: SUBJECTIVE EXAMINATION TEMPLATE
A2: Yellow column is the input column. In the elbow, the history plus quadrant localisation makes most of the diagnosis.
A3: Domain | B3: What to Ask | C3: Why It Matters | D3: Findings (fill in)
A4: Demographics & context | B4: Age; hand dominance; occupation (gripping, tools, vibration); sport and level; gym content | C4: Age and skeletal maturity change the differential completely; occupation is often the load driver | D4: e.g. 46 y, right dominant, plumber, tennis twice weekly
A5: SKELETAL MATURITY | B5: In anyone under about 18: are the growth plates closed? What sport and what volume? | C5: THE APOPHYSIS FAILS BEFORE THE TENDON OR LIGAMENT. This single question changes the diagnosis, the imaging and the management
A6: Onset & mechanism | B6: Traumatic (fall on outstretched hand, a pop, a dislocation, hyperextension) or gradual overuse? | C6: A pop with weakness is a surgical question; gradual onset with a load change is an overuse question
A7: Pain location | B7: Point with one finger: lateral / medial / posterior / anterior / deep and diffuse | C7: The quadrant is the first branch. Then ask whether it is ON the bony point, distal to it, or at the joint line
A8: Aggravating tasks | B8: Gripping, lifting, turning a screwdriver, shaking hands, throwing, racquet strokes, pressing, pulling | C8: Gripping and lifting = tendon. Throwing at late cocking = UCL. Push-up giving way = PLRI. Supination = biceps or radial tunnel
A9: MECHANICAL SYMPTOMS | B9: Does it lock, catch, click, or refuse to straighten fully? | C9: Locking with lost extension is an INTRA-ARTICULAR sign — OCD, loose body — and needs imaging, not stretching
A10: NERVE SYMPTOMS | B10: Numbness or tingling — and exactly WHICH fingers? Any weakness or dropping things? | C10: Little and ring = ulnar. Thumb and index = median. Finger drop = PIN. WEAKNESS changes urgency in every nerve presentation
A11: Instability | B11: Does it feel like it will give way pushing up from a chair or off the floor? Has it ever dislocated? | C11: Giving way on push-up = PLRI. Prior dislocation or repeated lateral injection is the giveaway history
A12: Load & training change | B12: Recent change in work tasks, tools, gym volume, throwing or racquet volume, climbing grade | C12: Most overuse elbow pain is a load change on an unprepared elbow — reconstruct the 8-12 weeks before onset
A13: Equipment | B13: Racquet grip size and string tension; club grip; tool handles; handlebar height; paddle use | C13: Equipment is frequently the modifiable driver and is often never asked about
A14: NECK & SHOULDER SCREEN | B14: Any neck pain? Does moving the neck change it? Does the pain travel past the elbow into the hand? | C14: GATE 2 — the neck refers to the elbow, and a weak shoulder girdle loads the forearm distally
A15: RED FLAG SCREEN | B15: Escalating pain with forearm tightness? Fever or feeling unwell? A pop with sudden weakness? Constant night pain unrelated to movement? A child unable to use the arm? | C15: GATE 1 — compartment syndrome, sepsis, tendon rupture, fracture and malignancy all present here
A16: Systemic tendon risk | B16: Anabolic steroid use? Corticosteroid exposure? Fluoroquinolones? Kidney disease? Diabetes? | C16: These raise biceps and triceps rupture risk substantially and change your counselling on injection
... A20: Baseline outcome measure | B20: Which PROM will you use? (see Outcome Measures sheet) | C20: One PROM plus PAIN-FREE GRIP and range is the minimum dataset
A22: HOW TO FILL THIS SHEET
A23: • Row 4 shows an example entry in grey — overwrite it.
A24: • Four questions triage most elbow pain fast: "Point to it with one finger", "Does it lock, catch or refuse to straighten?", "Which fingers go numb?", and "Was there a pop?"
A25: • In anyone under 18, establish skeletal maturity before anything else — it changes the entire pathway.
A26: • If nothing in the physical examination reproduces the presenting pain, stop and refer.

Sheet Objective Exam
A1: PHYSICAL EXAMINATION TEMPLATE
A2: Yellow columns are input columns. Terminal extension with end-feel, and pain-free grip, are the two highest-yield measures.
A3: Section | B3: Item | C3: How to Test / What to Look For | D3: Involved (fill in) | E3: Uninvolved (fill in) | F3: Interpretation
A4: Observation | B4: Carrying angle & deformity | C4: Compare both sides; note cubitus varus or valgus, swelling, bruising | D4: e.g. symmetrical | E4: symmetrical | F4: Cubitus varus follows malunited supracondylar fracture
A5: Observation | B5: Swelling & effusion | C5: Posterolateral triangle fullness; olecranon tip swelling | F5: Joint effusion = intra-articular. Tip swelling = bursa
A6: Observation | B6: Muscle bulk | C6: Forearm bulk; FIRST DORSAL INTEROSSEOUS bulk in the hand | F6: First dorsal interosseous wasting = significant ulnar motor involvement — refer
A7: Palpation | B7: Lateral epicondyle / ECRB origin | C7: Focal tenderness 1-2 cm distal to the epicondyle | F7: Lateral elbow tendinopathy
A8: Palpation | B8: 4-5 cm distal over the supinator | C8: Tenderness in the muscle belly, not on the bone | F8: RADIAL TUNNEL — the key tennis elbow mimic
A9: Palpation | B9: Lateral joint line / radiocapitellar | C9: Tenderness posterior to the ECRB origin | F9: Plica, chondral lesion or OCD
A10: Palpation | B10: Medial epicondyle / flexor origin | C10: Focal tenderness just distal to the epicondyle | F10: Medial elbow tendinopathy
A11: Palpation | B11: UCL / medial joint line | C11: Tenderness over the ligament, not the flexor origin | F11: UCL injury — confirm with the moving valgus stress test
A12: Palpation | B12: Cubital tunnel | C12: Tinel; palpate for nerve subluxation on flexion | F12: Cubital tunnel syndrome; a palpable snap suggests subluxation
A13: Palpation | B13: Olecranon tip & triceps insertion | C13: Swelling, fluctuance, defect, tenderness | F13: Bursitis; triceps tendinopathy or tear
A14: Palpation | B14: Antecubital fossa / distal biceps | C14: Tenderness; perform the HOOK TEST | F14: Distal biceps tendinopathy or rupture
A15: Range (active) | B15: Flexion (degrees) | C15: Goniometry both sides | F15: Functional arc is approximately 30-130 degrees
A16: Range (active) | B16: TERMINAL EXTENSION (degrees) & END-FEEL | C16: Goniometry; note whether the end-feel is HARD (bony) or springy/capsular | F16: THE earliest sign of intra-articular pathology. HARD end-feel = bony block, not stiffness
... A38: Function | B38: Functional task performance | C38: Grip and lift a kettle; turn a screwdriver; push up from a chair; throwing or racquet action | F38: What the patient actually cares about — use as a re-test marker
A40: HOW TO FILL THIS SHEET
A41: • THE TWO MEASURES THAT MATTER MOST: TERMINAL EXTENSION WITH END-FEEL (a hard end-feel means a bony block, not stiffness) and PAIN-FREE GRIP STRENGTH (the best objective marker in overuse presentations).
A42: • Localise tenderness precisely. ON the lateral epicondyle = tendon. 4-5 cm DISTAL in the muscle = radial tunnel. At the JOINT LINE = intra-articular. That single distinction redirects the whole plan.
