Workbook

Sheet Read Me
A1: HIP & GROIN ASSESSMENT AND MANAGEMENT PROGRAMME
A2: Screen → clear the lumbar spine → localise the region → cluster (Doha / Warwick) → load → discharge on capacity and control.
A4: SHEET | B4: WHAT IT DOES | C4: WHEN TO USE IT | D4: FOCUS
A5: Master Matrix | B5: 38 hip and groin conditions on the established column structure: Region → Activity Level → Common Symptoms → Age → Onset → Predominance → Condition → High-Yield Question → Special Test + Imaging → Biomechanical Cause → Desired Activity Goal → Physiotherapy Specific Exercise, then pain mechanism, classification, red-flag status, management emphasis, loading dose, biomechanical corrections, adjuncts, advanced options, outcomes, markers, timeline and referral triggers. | C5: The core reference. Filter column A by region or column O by red-flag status. | D5: All hip and groin pathology
A6: Rx Generator | B6: Pick a condition from the dropdown and the full prescription is pulled live from the Master Matrix. | C6: In clinic, or to print a plan into the patient file. | D6: Live INDEX/MATCH
A7: Assessment Roadmap | B7: The five-gate reasoning sequence, built around clearing the lumbar spine and then localising by region. | C7: Every new patient, in order. | D7: Clinical reasoning
A8: Subjective Exam | B8: Fillable history template with the hip-specific and paediatric screening questions built in. | C8: First consultation. | D8: Fillable
A9: Objective Exam | B9: Fillable examination template: observation, gait, palpation map, range, strength, squeeze test, special tests, lumbar screen. | C9: First consultation and every re-assessment. | D9: Fillable
A10: Special Tests | B10: 30 tests across intra-articular, groin, lateral, posterior, bone stress, paediatric and neural categories. | C10: During the physical examination. | D10: Reference
A11: Clusters & Doha | B11: Six diagnostic clusters, the one-line differentiators, and the Doha classification of athletic groin pain. | C11: When the picture is not yet clear, and in every athletic groin presentation. | D11: Doha 2015; Warwick 2016
A12: Imaging Guide | B12: When to image, which modality answers which question, and the traps. | C12: Before requesting or when reading a report. | D12: Reference
A13: Phased Programme | B13: Phase 0-4 with goals, content, markers and exit criteria, plus the master treatment sequence. | C13: Building and progressing every plan. | D13: Reference
A14: Exercise & Dosage | B14: Loading library with dose and indication, including the Copenhagen adduction programme and neutral-range abductor loading. | C14: Writing the actual programme. | D14: Reference
A15: Adjuncts & Advanced | B15: Education, positional modification, manual therapy, injection, ESWT and surgery, with the sequencing rule. | C15: When loading alone is not enough. | D15: Reference
... A23: References | B23: Guideline and trial sources. | C23: Verifying or citing. | D23: —
A25: CRITICAL POINTS FOR THE HIP
A26: • THE HIP'S DEFINING TRAP IS THE PAEDIATRIC ONE: an adolescent with hip OR KNEE pain and a limp has a slipped capital femoral epiphysis until proven otherwise. Knee pain is a classic presentation of hip pathology in children and is the commonest cause of delayed diagnosis.
A27: • THE SECOND TRAP: the lumbar spine. Screen it in every hip presentation and screen the hip in every lumbar presentation — hip-spine syndrome is common and both may need treating.
A28: • THE THIRD TRAP: measure the LATERAL CENTRE-EDGE ANGLE before anyone has a hip arthroscopy. Isolated labral surgery in a dysplastic hip can accelerate instability and degeneration.
A29: • MEASURE THE ADDUCTOR SQUEEZE in every groin presentation and record the figure — it is simultaneously a diagnostic test, the treatment target and the discharge criterion.
A30: • IN GTPS, REMOVING COMPRESSION MATTERS AS MUCH AS LOADING. Stop hip adduction postures, put a pillow between the knees at night, and do not roll the ITB or stretch into adduction.
A31: • Loss of hip INTERNAL ROTATION at 90 degrees flexion is the earliest measurable change in both FAI syndrome and hip osteoarthritis — measure it in every hip.
A32: • Yellow cells are inputs. Green text is pulled from another sheet. Do not overwrite formula cells.
A33: • This workbook supports clinical reasoning; it does not replace individualised assessment, local protocols or the operating surgeon's protocol.

Sheet Master Matrix
A1: MASTER DIAGNOSTIC & MANAGEMENT MATRIX — 38 HIP & GROIN CONDITIONS
A2: Columns A–L follow the established diagnostics-algorithm structure. Columns M–Y add the management programme. Crimson in column O marks a red-flag or time-sensitive presentation.
A3: Region | B3: Activity Level | C3: Common Symptoms | D3: Age Group | E3: Onset | F3: Predominance | G3: Condition | H3: High-Yield Diagnostic Question | I3: Special Test + Imaging | J3: Underlying Biomechanical Cause | K3: DESIRED ACTIVITY GOAL | L3: PHYSIOTHERAPY SPECIFIC EXERCISE | M3: Pain Mechanism | N3: Classification / Cluster | O3: Red Flag Status | P3: MANAGEMENT EMPHASIS | Q3: Loading Stage & Entry Dose | R3: BIOMECHANICAL CORRECTIONS & KINETIC CHAIN | S3: Manual Therapy, Positional & Adjuncts | T3: Advanced / Surgical Options | U3: Outcome Measures | V3: Re-testable Markers | W3: Expected Timeline | X3: Referral / Surgical Trigger | Y3: Evidence Anchor
A4: Anterior / Groin | B4: Football, ice hockey, dance, martial arts, deep-squat lifting; also sedentary with a sudden activity increase | C4: Anterior groin pain with deep flexion, prolonged sitting and pivoting; catching or clicking | D4: 18-45 | E4: Slow | F4: Male athletes | G4: Femoroacetabular Impingement Syndrome (FAIS) | H4: Do you grip the side of your hip with a C-shape when showing me where it hurts, and does deep squatting or long sitting bring it on? | I4: FADIR (anterior impingement) test + AP pelvis and Dunn lateral radiographs (alpha angle, LCEA); MR arthrogram if labral pathology is suspected | J4: Cam or pincer morphology producing abnormal femoroacetabular contact in flexion and internal rotation; compounded by restricted hip internal rotation, gluteal and deep rotator weakness, anterior pelvic tilt, poor lumbopelvic control, and repetitive deep-flexion loading in sport | K4: Return to deep squatting, pivoting sport and prolonged sitting without groin pain or catching | L4: Gluteus medius and maximus strengthening (side-lying abduction, banded lateral walk, hip thrust, split squat) 3-4 sets 8-12 RM 3x/week; deep external rotator activation; lumbopelvic control (dead bug, Pallof press); modify squat depth and hip flexion range early; posterior chain and hamstring loading; graded return to pivoting and cutting; core and trunk endurance | M4: Nociceptive - mechanical and compressive; nociplastic overlay common when longstanding | N4: Cluster 1 - FAIS (Warwick Agreement 2016): symptoms + clinical signs + imaging findings, ALL THREE required. Morphology alone is not a diagnosis | O4: No | P4: Physiotherapy-led rehabilitation is a legitimate first-line option and should be trialled properly (typically 3-6 months) before surgery. Focus on hip and lumbopelvic strengthening, movement retraining and activity modification. Arthroscopy shows benefit over physiotherapy in trials but the effect size is modest - discuss both pathways transparently | Q4: Stage 1-2. Isometric gluteal and hip work if irritable; progressive gluteal and deep rotator loading 3-4 sets 8-12 RM 3x/week within a non-impinging range; progress to functional and sport-specific loading | R4: Take the hip out of the impinging position: build gluteal and deep external rotator capacity, correct anterior pelvic tilt and lumbopelvic control, restore thoracic and lumbar rotation so the hip rotates less, cap squat depth and deep-flexion volume, correct sitting posture and seat height, and retrain cutting and pivoting mechanics | S4: Manual therapy for hip and lumbopelvic mobility as an adjunct; activity and seating modification; taping is of limited value here | T4: If a well-delivered 3-6 month programme fails: arthroscopic femoroplasty or acetabuloplasty with labral repair and capsular closure. Guided intra-articular injection is diagnostically useful | U4: iHOT-33; HAGOS; HOS; NPRS on the primary provocative task | V4: FADIR response; hip internal rotation range at 90 degrees flexion; sitting tolerance; squat depth before pain; gluteal strength LSI | W4: 3-6 months conservative trial; 6-9 months to sport post arthroscopy | X4: Failure of a genuinely well-delivered 3-6 month programme; mechanical locking; progressive loss of range | Y4: Warwick Agreement on FAI syndrome (BJSM 2016); UK FASHIoN trial
A5: Anterior / Groin | B5: Pivoting and deep-flexion sport; also dancers and those with hypermobility | C5: Sharp catching or clicking groin pain with pivoting, deep flexion or getting out of a car | D5: 18-45 | E5: Sudden/Slow | F5: Female | G5: Acetabular Labral Tear | H5: Does the hip catch, click or give a sharp sensation when you twist or come out of a deep position? | I5: FADIR and FABER; MR arthrogram is the imaging standard; intra-articular anaesthetic injection is a useful diagnostic test | J5: Shear and compressive load on the labrum from cam or pincer morphology, acetabular dysplasia, or capsular laxity and microinstability; repetitive end-range rotation in dance and pivoting sport; gluteal and deep rotator weakness allow uncontrolled femoral translation | K5: Return to pivoting, deep flexion and sport without catching or sharp groin pain | L5: Gluteal and deep external rotator strengthening 3-4 sets 8-12 RM 3x/week; lumbopelvic control work; avoid end-range rotation and deep flexion early; progressive loading through range as symptoms allow; single-leg control and landing retraining; sport-specific pivot progression | M5: Nociceptive - mechanical | N5: Hip-related groin pain (Doha agreement). Note labral change is common in ASYMPTOMATIC hips, especially in athletes - correlate with the clinical picture | O5: Screen: assess for underlying dysplasia (LCEA under 25 degrees) - it changes the surgical decision entirely | P5: Conservative rehabilitation first-line: gluteal and lumbopelvic strengthening, movement retraining and activity modification. Treat the DRIVER (FAI morphology, dysplasia or capsular laxity), not just the tear. Repair rather than debridement where surgery is indicated | Q5: Stage 1-2. Progressive gluteal and deep rotator loading within a non-provocative range; progress range and load as symptoms settle; then functional and sport-specific | R5: Address the mechanical driver: build gluteal and deep external rotator capacity to control femoral head translation, correct lumbopelvic control and anterior pelvic tilt, cap end-range rotation and deep-flexion volume, and retrain pivoting and landing mechanics | S5: Manual therapy as an adjunct; activity modification; avoid aggressive end-range stretching in a hypermobile hip | T5: Arthroscopic labral repair (preferred) or reconstruction with correction of the underlying morphology; NEVER isolated debridement in a dysplastic hip - it accelerates instability | U5: iHOT-33; HAGOS; HOS | V5: Catching frequency; FADIR response; internal rotation range; gluteal strength LSI; pivot tolerance | W5: 3-6 months conservative; 6-9 months to sport post repair | X5: Persistent mechanical symptoms after a well-delivered programme; underlying dysplasia requiring PAO rather than arthroscopy | Y5: Doha agreement (BJSM 2015); labral repair vs debridement literature
A6: Anterior / Groin | B6: Any activity level; walking, stairs and sit-to-stand loaded | C6: Deep groin pain with weight-bearing, morning stiffness under 60 minutes, progressive stiffness | D6: 50+ | E6: Slow | F6: Equal | G6: Hip Osteoarthritis | H6: Is the groin pain worse with walking and standing, and stiff for less than an hour in the morning? | I6: Restricted internal rotation and flexion; positive FABER; weight-bearing AP pelvis radiograph (Tonnis grade, joint space, osteophytes) | J6: Cumulative joint load with cartilage loss; prior FAI morphology, dysplasia or injury accelerate it. Reduced gluteal and quadriceps capacity increases the load the joint absorbs and produces a Trendelenburg gait pattern | K6: Walk, climb stairs and rise from a chair without limiting pain; maintain independence and delay or avoid arthroplasty | L6: Gluteus medius and maximus strengthening (side-lying abduction, bridge, hip thrust, sit-to-stand, step-up) 3-4 sets 8-12 RM 2-3x/week; quadriceps loading; hip range maintenance in flexion and internal rotation; aerobic conditioning 150 min/week (cycling, pool, walking); balance and gait retraining; weight management support | M6: Nociceptive with frequent nociplastic overlay in long-standing disease | N6: Hip-related group - degenerative. Tonnis grading on radiograph. Clinical diagnosis is reasonable without imaging in a typical older presentation | O6: No | P6: EXERCISE + EDUCATION + WEIGHT MANAGEMENT is first-line and strongly recommended (OARSI, NICE NG226, ACR). Reassure that loading is safe and does not wear the joint out. Expect and manage flares. Arthroplasty for end-stage disease after well-delivered conservative care | Q6: Stage 1-2 sustained. Strengthening 2-3x/week plus aerobic exercise plus neuromuscular training; acceptable symptom window of pain <=5/10 settling within 24 h; mode by patient preference | R6: Reduce the load the joint absorbs and improve distribution: gluteal (especially abductor) and quadriceps capacity to correct Trendelenburg gait, improve gait quality and step length, retrain sit-to-stand and stair strategy to a hip-hinge pattern, support weight management, and use a stick in the CONTRALATERAL hand where offloading is needed | S6: Walking aid in the contralateral hand; heat; manual therapy as an adjunct to exercise; footwear and task modification | T6: Guided intra-articular corticosteroid injection for short-term relief to enable loading; total hip arthroplasty for end-stage disease. Hip arthroscopy is NOT indicated in established OA | U6: HOOS; HOOS-12; Oxford Hip Score; 30-second sit-to-stand; 40 m fast-paced walk test; timed stair climb | V6: Internal rotation and flexion range; sit-to-stand repetitions; walking tolerance; abductor strength LSI; morning stiffness duration | W6: 12 weeks for meaningful change; ongoing lifelong self-management | X6: End-stage disease with failed well-delivered conservative care - arthroplasty opinion | Y6: OARSI 2019; NICE NG226 2022; ACR/AF 2019
A7: Anterior / Groin | B7: Football, dance, running, hurdling; repetitive hip flexion | C7: Anterior groin pain on resisted hip flexion, kicking and sprinting; may click deep in the groin | D7: 18-40 | E7: Slow | F7: Equal | G7: Iliopsoas-Related Groin Pain / Iliopsoas Tendinopathy | H7: Does the pain come on when you lift your knee against resistance, or kick? | I7: Pain on resisted hip flexion and on iliopsoas stretch (modified Thomas); local tenderness; ultrasound or MRI if characterising or guiding injection | J7: Repetitive hip flexion load exceeding iliopsoas capacity: kicking, sprinting and hurdling volume; anterior pelvic tilt and hip flexor dominance with gluteal underactivity; restricted hip extension; lumbopelvic control deficits; sudden increase in kicking or running volume | K7: Return to full kicking, sprinting and hurdling volume without anterior groin pain | L7: Isometric hip flexion holds for analgesia if irritable; progressive resisted hip flexion loading (band, cable, weighted straight-leg raise, standing hip flexion) 3-4 sets 8-12 RM 3x/week; eccentric hip flexor work; gluteal and posterior chain strengthening; hip extension mobility; lumbopelvic control; graded kicking and sprint volume progression | M7: Nociceptive - tensile tendon and muscle load | N7: Iliopsoas-related groin pain (Doha agreement) - one of the five defined groin entities | O7: No | P7: Progressive loading of the hip flexor complex plus load management. Address the anterior pelvic tilt and hip-flexor-dominant pattern that created it. Correct kicking and sprint volume | Q7: Stage 1-2. Isometric holds 5 x 30-45 s if irritable; progressive isotonic hip flexion loading 3-4 sets 8-12 RM 3x/week; then eccentric and sport-specific loading | R7: Change the pattern that overloads it: strengthen gluteus maximus so the hip flexors do not dominate, correct anterior pelvic tilt, restore hip extension range, build lumbopelvic control, and grade kicking and sprint volume rather than spiking it | S7: Manual therapy and soft-tissue work as short-term adjuncts; activity modification | T7: Guided injection into the bursa or sheath (not tendon substance) for refractory cases; iliopsoas fractional lengthening is rarely indicated and carries a hip flexor weakness cost | U7: HAGOS; iHOT-33; NPRS on resisted hip flexion | V7: Pain on resisted hip flexion; hip flexor strength LSI; kicking and sprint volume tolerance; hip extension range | W7: 8-12 weeks | X7: Failure after 12 weeks of correct loading; suspicion of intra-articular pathology driving secondary iliopsoas irritation | Y7: Doha agreement (BJSM 2015)
A8: Anterior / Groin | B8: Dancer, gymnast, footballer; often hypermobile | C8: Audible or palpable snap deep in the anterior groin with hip extension from flexion | D8: 15-35 | E8: Slow | F8: Female | G8: Internal Snapping Hip (Coxa Saltans Interna) | H8: Does something snap deep in the front of the hip when you straighten it from a bent position? | I8: Reproducible snap on moving from flexion-abduction-external rotation into extension; dynamic ultrasound confirms iliopsoas tendon snapping over the iliopectineal eminence | J8: The iliopsoas tendon snapping over the iliopectineal eminence or femoral head; driven by iliopsoas tightness or overactivity, anterior pelvic tilt, capsular laxity, and repetitive extreme hip range in dance and gymnastics | K8: Perform full dance or sport range without a painful snap | L8: Iliopsoas and rectus femoris lengthening only if genuinely short; gluteal and deep rotator strengthening 3-4 sets 8-12 RM 3x/week; lumbopelvic control; anterior pelvic tilt correction; movement retraining to reduce the snapping arc; progressive return to full range and sport volume | M8: Nociceptive - mechanical friction; often painless and needing no treatment at all | N8: Hip-related group; distinguish from external snapping (ITB over the greater trochanter, lateral and visible) and intra-articular causes | O8: No | P8: A PAINLESS snap needs no treatment - reassure. A painful snap: address iliopsoas overactivity or tightness, build gluteal control and lumbopelvic stability, and retrain the movement pattern. Surgery is rarely needed | Q8: Stage 1-2. Progressive gluteal and deep rotator loading; iliopsoas loading rather than only stretching; movement retraining through the snapping arc | R8: Reduce the friction mechanism: correct anterior pelvic tilt and hip flexor dominance, build gluteal capacity, address capsular laxity with control rather than stretching, and modify the extreme range positions in dance or gymnastics | S8: Manual therapy for the iliopsoas as an adjunct; activity modification | T8: Guided iliopsoas bursal injection for refractory pain; arthroscopic fractional lengthening is a last resort with a hip flexor weakness cost | U8: iHOT-33; HAGOS; snap frequency and pain | V8: Painful snap frequency; hip flexor and gluteal strength; dance or sport range tolerance | W8: 8-12 weeks | X8: Persistent painful snapping after a well-delivered programme; suspicion of an intra-articular cause | Y8: Doha agreement; snapping hip literature
A9: Anterior / Groin | B9: Football, ice hockey, Australian rules, martial arts - cutting and kicking sport | C9: Groin pain on kicking, cutting and sprinting; tenderness at the adductor origin | D9: 18-35 | E9: Sudden/Slow | F9: Male athletes | G9: Adductor-Related Groin Pain | H9: Is the groin pain reproduced when you squeeze your knees together against resistance? | I9: Adductor tenderness at the origin PLUS pain on resisted adduction (the defining combination); adductor squeeze test at 0, 45 and 90 degrees; imaging only if a significant tear is suspected | J9: Repetitive high-force adduction and eccentric loading during cutting, kicking and change of direction; low adduction:abduction strength ratio, adductor weakness relative to demand, poor lumbopelvic control, and a spike in cutting or kicking volume | K9: Return to full cutting, kicking and sprinting volume without groin pain and with a restored adduction:abduction ratio | L9: COPENHAGEN ADDUCTION EXERCISE is the primary intervention - progress from short-lever to long-lever, 2-3 sets building to 12-15 reps, 2-3x/week; adductor squeeze isometrics 5 x 30-45 s at 0, 45 and 90 degrees for analgesia; gluteal and abdominal loading; lumbopelvic control (Pallof press, dead bug); graded return-to-run and change-of-direction progression | M9: Nociceptive - tensile muscle and tendon load | N9: Cluster - ADDUCTOR-RELATED GROIN PAIN (Doha agreement 2015): the most common of the five defined groin entities | O9: No | P9: Progressive adductor loading, led by the Copenhagen adduction exercise, plus lumbopelvic and gluteal work and graded return to cutting. Adductor strength and the adduction:abduction ratio are BOTH the treatment target and the discharge criterion | Q9: Stage 1-2. Isometric adductor squeezes for analgesia; then Copenhagen adduction progression 2-3x/week; then eccentric and sport-specific change-of-direction loading | R9: Restore the force balance: raise the adduction:abduction strength ratio toward 0.9-1.0, build gluteal and abdominal capacity, improve lumbopelvic control, correct change-of-direction and kicking mechanics, and grade cutting and kicking volume rather than spiking it | S9: Manual therapy and soft-tissue work as short-term adjuncts; compression shorts for comfort | T9: Guided injection is rarely indicated; adductor tenotomy or longus repair only for a complete avulsion or genuinely refractory cases | U9: HAGOS; adductor squeeze force (kg or mmHg); NPRS on cutting | V9: Adductor squeeze force at 0/45/90; ADDUCTION:ABDUCTION RATIO; cutting and kicking tolerance; local tenderness | W9: 6-12 weeks for most; longer for a significant tear | X9: Complete avulsion; failure after 12 weeks of correct loading; suspicion of another Doha entity coexisting | Y9: Doha agreement (BJSM 2015); Copenhagen adduction exercise (Harøy BJSM 2019)
A10: Anterior / Groin | B10: Football, running, Australian rules; high change-of-direction and kicking volume | C10: Central pubic pain with kicking, sprinting and sit-ups; tenderness over the pubic symphysis | D10: 18-35 | E10: Slow | F10: Male athletes | G10: Pubic-Related Groin Pain / Osteitis Pubis | H10: Is the pain right in the middle at the pubic bone, and does it hurt to do a sit-up as well as to kick? | I10: Local tenderness over the pubic symphysis and adjacent bone; MRI shows pubic bone marrow oedema; radiograph may show symphyseal irregularity in chronic cases | J10: Repetitive shear across the pubic symphysis from asymmetric adductor and abdominal forces during kicking and cutting; adductor-abdominal force imbalance, poor lumbopelvic control, restricted hip internal rotation transferring load to the pelvis, and a volume spike | K10: Return to full kicking, sprinting and change-of-direction volume without central pubic pain | L10: Isometric adductor squeezes for analgesia; progressive adductor loading (Copenhagen adduction) 2-3x/week; abdominal and oblique loading; lumbopelvic control work (Pallof press, dead bug, side plank progressions); restore hip internal rotation range; graded return-to-run then change-of-direction then kicking | M10: Nociceptive - bone stress and shear at the symphysis | N10: PUBIC-RELATED GROIN PAIN (Doha agreement). Frequently coexists with adductor-related groin pain - screen for both | O10: Screen: exclude a pubic ramus stress fracture, and in the older or systemically unwell patient exclude infection and inflammatory disease | P10: Load management with progressive adductor and abdominal loading and lumbopelvic control. Restore hip internal rotation, because a stiff hip transfers load to the pelvis. Slow condition - set expectations for 3-6 months | Q10: Stage 1-2. Isometric adductor and abdominal loading for analgesia; progressive adductor and trunk loading 2-3x/week; graded return to run, cut and kick in that order | R10: Rebalance the forces across the symphysis: raise adductor and abdominal capacity together, restore hip internal rotation so the hip absorbs rotation instead of the pelvis, improve lumbopelvic control, correct kicking mechanics, and grade change-of-direction and kicking volume | S10: Compression shorts; manual therapy for hip and lumbopelvic mobility; activity modification | T10: Guided symphyseal injection for refractory cases; surgery (symphyseal curettage or fusion) is rarely indicated | U10: HAGOS; NPRS on kicking and sit-ups; adductor squeeze force | V10: Symphyseal tenderness; adductor squeeze force; hip internal rotation range; kicking tolerance | W10: 3-6 months - a notoriously slow condition | X10: Failure after 3 months; suspicion of a pubic ramus stress fracture, infection or inflammatory disease | Y10: Doha agreement (BJSM 2015)
A11: Anterior / Groin | B11: Football, rugby, ice hockey; high cutting and twisting volume | C11: Diffuse groin and lower abdominal pain with sprinting, cutting, coughing and sneezing; no palpable hernia | D11: 18-35 | E11: Slow | F11: Male athletes | G11: Inguinal-Related Groin Pain (Sportsman's Groin) | H11: Does the groin pain also come on when you cough, sneeze or do a sit-up, without any lump being present? | I11: Tenderness over the inguinal canal and conjoint tendon; pain on resisted sit-up and on Valsalva; NO palpable hernia; MRI to exclude other causes; ultrasound for dynamic posterior wall assessment | J11: Weakness or attenuation of the posterior inguinal wall under repetitive shear from cutting and twisting; abdominal-adductor force imbalance, poor lumbopelvic control, restricted hip range transferring load to the abdominal wall | K11: Return to full sprinting, cutting and contact sport without groin or lower abdominal pain | L11: Progressive abdominal and oblique loading (dead bug, Pallof press, side plank progression, cable chops) 3x/week; adductor loading (Copenhagen adduction); gluteal strengthening; hip mobility work; graded return-to-run and change-of-direction progression before contact | M11: Nociceptive - shear and tensile load on the inguinal wall | N11: INGUINAL-RELATED GROIN PAIN (Doha agreement). A clinical diagnosis of exclusion - no true hernia is present | O11: Screen: exclude a true hernia, intra-abdominal pathology and hip-related causes | P11: Trial progressive abdominal, adductor and lumbopelvic loading for 8-12 weeks. Surgical opinion (posterior wall repair or 'core muscle' surgery) for genuinely refractory cases in athletes - outcomes are good in correctly selected patients | Q11: Stage 1-2. Progressive abdominal, oblique, adductor and gluteal loading 3x/week; graded return to run, cut and contact | R11: Rebalance the abdominal wall load: build abdominal and oblique capacity relative to adductor pull, improve lumbopelvic control, restore hip rotation range so the abdominal wall absorbs less shear, and grade cutting and twisting volume | S11: Compression shorts; manual therapy as an adjunct; activity modification | T11: Surgical posterior wall repair or laparoscopic mesh repair for refractory cases; specialist groin surgeon referral | U11: HAGOS; NPRS on sprinting, coughing and sit-ups | V11: Inguinal tenderness; pain on Valsalva and resisted sit-up; sprint and cutting tolerance | W11: 8-12 weeks conservative trial; 6-8 weeks return post surgery | X11: Failure after 8-12 weeks of correct loading in an athlete - refer to a specialist groin surgeon | Y11: Doha agreement (BJSM 2015)
A12: Anterior / Groin | B12: Sprinting, kicking sport, hurdling; explosive hip flexion | C12: Sudden anterior thigh or hip pain during a sprint or kick; local tenderness and possible bruising | D12: 15-35 | E12: Sudden | F12: Male athletes | G12: Rectus Femoris Strain / AIIS Avulsion | H12: Did the front of the hip or thigh give a sharp pain at the moment of a sprint or a kick? | I12: Pain on resisted hip flexion with the knee flexed; tenderness at the AIIS or muscle belly; radiograph in the adolescent to exclude AIIS apophyseal avulsion; ultrasound or MRI to grade | J12: Eccentric overload of the two-joint rectus femoris during the swing phase of sprinting or the kicking follow-through; hip flexor weakness relative to demand, inadequate warm-up, fatigue, restricted hip extension, and a sprint or kicking volume spike | K12: Return to full sprinting and kicking speed without anterior thigh pain and with symmetrical hip flexor strength | L12: Early: pain-free isometric hip flexion and knee extension holds. Then progressive isotonic hip flexion and knee extension loading 3-4 sets 8-12 RM 3x/week; eccentric hip flexor work (slider, band-resisted decline); gluteal and hamstring loading; hip extension mobility; graded sprint progression with kicking last | M12: Nociceptive - acute muscle strain | N12: Anterior group - musculotendinous. In the SKELETALLY IMMATURE athlete this is an AIIS apophyseal avulsion, not a muscle strain | O12: Screen: in an adolescent, image to exclude apophyseal avulsion - management and timeline differ | P12: Progressive loading with a graded sprint and kicking return. Adolescent avulsion: relative rest, protected weight bearing initially, then graded loading; surgery only for significant displacement | Q12: Stage 1-4. Pain-free isometrics days 0-7; progressive isotonic loading; then eccentric and energy-storage work; then sprint and kicking progression | R12: Address the eccentric deficit: build hip flexor and quadriceps eccentric capacity, restore hip extension range, strengthen gluteals and hamstrings for balance, improve warm-up practice, and grade sprint and kicking volume rather than spiking it | S12: Compression; short-term activity modification; manual therapy as an adjunct | T12: Surgical fixation only for a significantly displaced AIIS avulsion (typically over 2 cm) in a young athlete | U12: HAGOS; hip flexor strength LSI; sprint tolerance | V12: Pain on resisted hip flexion; hip flexor strength LSI; sprint speed tolerance; hip extension range | W12: 3-8 weeks by grade; 6-12 weeks for an adolescent avulsion | X12: Significant apophyseal displacement; failure to progress; suspected complete tear | Y12: Muscle injury classification; apophyseal avulsion literature
A13: Anterior / Groin | B13: Any; associated with tight belts, obesity, pregnancy, or prolonged hip flexion | C13: Burning, numbness and tingling over the anterolateral thigh; NO weakness | D13: 30-60 | E13: Slow | F13: Equal | G13: Meralgia Paraesthetica (Lateral Femoral Cutaneous Nerve) | H13: Is it burning or numbness over the outside of the thigh, with no weakness at all? | I13: Sensory change over the anterolateral thigh in the LFCN distribution; Tinel's sign at the ASIS; pelvic compression test; nerve conduction studies if the picture is unclear; MRI only to exclude a mass | J13: Compression of the lateral femoral cutaneous nerve as it passes near the ASIS beneath the inguinal ligament; tight belts and waistbands, body armour or tool belts, raised body mass, pregnancy, prolonged hip flexion, and anterior pelvic tilt increasing tension over the nerve | K13: Resolve the burning and numbness and return to normal daily activity, work clothing and exercise | L13: Remove the compressive source first. Nerve gliding within symptom tolerance; hip extension mobility; anterior pelvic tilt correction with gluteal and abdominal loading; graded reintroduction of prolonged sitting and hip flexion; general conditioning and weight management support where relevant | M13: Neuropathic - purely sensory | N13: Neural group. PURELY SENSORY - any motor weakness means the diagnosis is wrong, so look again | O13: Screen: any weakness, or bilateral symptoms, means this is not meralgia paraesthetica - reconsider lumbar or systemic causes | P13: Remove the compressive source - this is the entire first-line intervention (belts, waistbands, tool belts, body armour). Then nerve mobility, anterior pelvic tilt correction and weight management support. Most resolve spontaneously once the compression is removed | Q13: Loading is secondary. Nerve gliding within tolerance; gluteal and abdominal loading to correct anterior pelvic tilt; graded reintroduction of sitting and hip flexion | R13: Take the tension and compression off the nerve: remove external compression, correct anterior pelvic tilt and hip flexor tightness that increases nerve tension, modify prolonged hip flexion positions, and support weight management where relevant | S13: Clothing and equipment modification is the highest-yield adjunct; nerve gliding; activity modification | T13: Guided local anaesthetic and corticosteroid injection at the ASIS for refractory symptoms; surgical decompression or neurectomy is rarely needed | U13: NPRS; sensory area mapping; LEFS | V13: Sensory area size; burning intensity; sitting and standing tolerance | W13: Weeks to months once the compression is removed | X13: Any motor weakness (reconsider the diagnosis); refractory symptoms after removing compression | Y13: Meralgia paraesthetica literature
A14: Anterior / Groin | B14: Dance, gymnastics, martial arts, yoga; often generalised hypermobility | C14: Vague anterior groin ache with a sense of the hip giving way or shifting, worse in end-range positions | D14: 15-35 | E14: Slow | F14: Female | G14: Hip Microinstability / Capsular Laxity | H14: Does the hip feel loose or like it shifts, especially in end-range positions - and are you generally flexible? | I14: Positive hip dial test and anterior apprehension in extension-external rotation; Beighton score; radiograph to exclude dysplasia (LCEA); MR arthrogram may show capsular attenuation or labral change | J14: Insufficient passive restraint from a lax or attenuated capsule and iliofemoral ligament, with inadequate dynamic control; repetitive end-range rotation in dance, gymnastics and yoga; generalised hypermobility; may coexist with borderline dysplasia | K14: Regain confident, controlled hip function through full sport or dance range without a sense of shifting | L14: Deep external rotator and gluteal strengthening 3-4 sets 8-12 RM 3x/week; lumbopelvic control (dead bug, Pallof press, side plank); closed-chain single-leg control and proprioception; iliopsoas and adductor co-contraction work; AVOID end-range passive stretching, which worsens it; graded return to end-range sport positions | M14: Nociceptive with apprehension and hypervigilance components | N14: Hip-related group; screen the Beighton score and the LCEA - borderline dysplasia (LCEA 20-25 degrees) changes the surgical decision entirely | O14: Screen: exclude frank acetabular dysplasia (LCEA under 20 degrees) - arthroscopy in a dysplastic hip accelerates instability | P14: REHABILITATION IS FIRST-LINE and usually successful. Build dynamic control the capsule cannot provide. Do NOT stretch. Surgery (capsular plication) only after a genuinely prolonged and well-delivered programme fails, and only once dysplasia has been excluded | Q14: Stage 1-4 over 12-24 weeks. Control work without load, then gluteal and deep rotator capacity, then closed-chain and functional loading, then sport or dance-specific range | R14: Build what the capsule cannot provide: deep external rotator and gluteal capacity, lumbopelvic control, closed-chain proprioception, and correct the habit of pushing into end-range passive positions in dance, yoga and gymnastics | S14: Taping for proprioceptive feedback; AVOID stretching and end-range mobilisation - the capsule is already lax | T14: Arthroscopic capsular plication with labral repair only after prolonged rehabilitation fails; PAO if borderline dysplasia is the dominant driver | U14: iHOT-33; HAGOS; Beighton score | V14: Dial test and apprehension response; single-leg control; gluteal and deep rotator strength; end-range tolerance | W14: 12-24 weeks minimum | X14: Confirmed dysplasia (refer for PAO opinion, not arthroscopy); failure after prolonged well-delivered rehabilitation | Y14: Hip microinstability literature; dysplasia and arthroscopy cautions
... A41: Systemic / Referred | B41: Post-arthroplasty patient of any activity level | C41: New or worsening hip pain after arthroplasty; may include instability, start-up pain, or systemic features | D41: 60+ | E41: Slow/Sudden | F41: Equal | G41: Post-Arthroplasty Complication | H41: Since the hip replacement, has NEW pain developed, or does the hip feel like it wants to give way or come out? | I41: Assess for infection (warmth, fever, wound issues, raised CRP and ESR), loosening (start-up pain, thigh pain, radiographic lucency), dislocation (sudden pain, deformity, shortening) and periprosthetic fracture. Radiograph; bloods; refer to the operating surgeon | J41: Not a rehabilitation problem in itself - infection, aseptic loosening, dislocation, periprosthetic fracture or abductor deficiency. Abductor weakness and violation of positional precautions contribute to dislocation risk | K41: Identify the complication, protect the prosthesis, and restore safe function | L41: NONE until the complication is identified. Post-management: abductor and quadriceps strengthening, gait retraining, balance work and adherence to any positional precautions | M41: Nociceptive; inflammatory if infected | N41: Systemic group; distinguish infection, loosening, dislocation, periprosthetic fracture and abductor deficiency - the management differs completely | O41: YES for suspected infection (warmth, fever, raised inflammatory markers), dislocation (sudden pain and deformity) or periprosthetic fracture - urgent surgical referral | P41: New pain after arthroplasty is a REFERRAL, not a rehabilitation problem, until the cause is established. Contact the operating surgeon. Once cleared, rehabilitation focuses on abductor strength, gait and balance | Q41: None until cleared. Post-clearance: progressive abductor, quadriceps and gluteal loading; balance and gait retraining | R41: Where abductor deficiency is the issue: progressive abductor loading, gait retraining to eliminate Trendelenburg, balance work; reinforce positional precautions relevant to the surgical approach | S41: Walking aid; positional precautions per approach (posterior approach: avoid flexion beyond 90 degrees with adduction and internal rotation) | T41: Revision surgery for loosening, infection or recurrent dislocation; two-stage revision for infection | U41: Oxford Hip Score; HOOS; Timed Up and Go | V41: Pain pattern; walking tolerance; abductor strength; Trendelenburg sign; inflammatory markers | W41: Determined by the complication and its management | X41: Any new post-arthroplasty pain - contact the operating surgeon before rehabilitating | Y41: Periprosthetic infection and loosening pathways

Sheet Rx Generator
A1: PRESCRIPTION GENERATOR
A2: Select a condition in the yellow cell. Every field below is pulled live from the Master Matrix.
A4: SELECT CONDITION → | B4: Greater Trochanteric Pain Syndrome (Gluteal Tendinopathy)
A6: Region | B6: =IFERROR(INDEX('Master Matrix'!A$4:A$41,MATCH($B$4,'Master Matrix'!$G$4:$G$41,0)),"") -> Lateral
A7: Activity level | B7: =IFERROR(INDEX('Master Matrix'!B$4:B$41,MATCH($B$4,'Master Matrix'!$G$4:$G$41,0)),"") -> Any activity level; walking, stairs and side-lying loaded. Peak incidence in post-menopausal women
A8: Common symptoms | B8: =IFERROR(INDEX('Master Matrix'!C$4:C$41,MATCH($B$4,'Master Matrix'!$G$4:$G$41,0)),"") -> Lateral hip pain, worse lying on the side, climbing stairs and single-leg standing
A9: Age group | B9: =IFERROR(INDEX('Master Matrix'!D$4:D$41,MATCH($B$4,'Master Matrix'!$G$4:$G$41,0)),"") -> 40-65
A10: Onset | B10: =IFERROR(INDEX('Master Matrix'!E$4:E$41,MATCH($B$4,'Master Matrix'!$G$4:$G$41,0)),"") -> Slow
A11: Predominance | B11: =IFERROR(INDEX('Master Matrix'!F$4:F$41,MATCH($B$4,'Master Matrix'!$G$4:$G$41,0)),"") -> Female
A12: High-yield diagnostic question | B12: =IFERROR(INDEX('Master Matrix'!H$4:H$41,MATCH($B$4,'Master Matrix'!$G$4:$G$41,0)),"") -> Does it hurt to lie on that side at night, and to climb stairs or stand on one leg?
A13: Special test + imaging | B13: =IFERROR(INDEX('Master Matrix'!I$4:I$41,MATCH($B$4,'Master Matrix'!$G$4:$G$41,0)),"") -> Tenderness over the greater trochanter PLUS pain on single-leg stance held for 30 seconds; positive FADER-R and ADD-R; ultrasound or MRI only if a tear is suspected or surgery is considered
A14: Underlying biomechanical cause | B14: =IFERROR(INDEX('Master Matrix'!J$4:J$41,MATCH($B$4,'Master Matrix'!$G$4:$G$41,0)),"") -> COMPRESSIVE plus tensile overload of the gluteus medius and minimus tendons against the greater trochanter, driven by hip ADDUCTION: standing in hip-hanging posture, crossing legs, side-lying without a pillow, and Trendelenburg gait from abductor weakness. Compression - not friction - is the mechanism, which is why the bursitis label misleads
A15: DESIRED ACTIVITY GOAL | B15: =IFERROR(INDEX('Master Matrix'!K$4:K$41,MATCH($B$4,'Master Matrix'!$G$4:$G$41,0)),"") -> Sleep on the affected side, climb stairs and stand on one leg without lateral hip pain
A16: PHYSIOTHERAPY SPECIFIC EXERCISE | B16: =IFERROR(INDEX('Master Matrix'!L$4:L$41,MATCH($B$4,'Master Matrix'!$G$4:$G$41,0)),"") -> ISOMETRIC abductor holds (supine isometric abduction) 5 x 30-45 s for analgesia; progressive abductor loading in NEUTRAL, avoiding adduction (supine isometric abduction, side-lying abduction to neutral only, standing hip hitch, offset squat, single-leg bridge) 3-4 sets 8-12 RM 3x/week; gluteus maximus loading; gait and standing posture retraining; sleeping position with a pillow between the knees
A17: Pain mechanism | B17: =IFERROR(INDEX('Master Matrix'!M$4:M$41,MATCH($B$4,'Master Matrix'!$G$4:$G$41,0)),"") -> Nociceptive - compressive plus tensile tendon load
A18: Classification / cluster | B18: =IFERROR(INDEX('Master Matrix'!N$4:N$41,MATCH($B$4,'Master Matrix'!$G$4:$G$41,0)),"") -> Cluster - GTPS / gluteal tendinopathy. The term 'trochanteric bursitis' is misleading; bursal change is secondary. Stage on the tendinopathy continuum
A19: RED FLAG STATUS | B19: =IFERROR(INDEX('Master Matrix'!O$4:O$41,MATCH($B$4,'Master Matrix'!$G$4:$G$41,0)),"") -> No
A20: MANAGEMENT EMPHASIS | B20: =IFERROR(INDEX('Master Matrix'!P$4:P$41,MATCH($B$4,'Master Matrix'!$G$4:$G$41,0)),"") -> EDUCATION PLUS PROGRESSIVE ABDUCTOR LOADING with strict avoidance of hip ADDUCTION positions. The LEAP trial showed education plus exercise outperformed corticosteroid injection and wait-and-see at 8 weeks AND at 12 months. Injection gives short-term relief only
A21: Loading stage & entry dose | B21: =IFERROR(INDEX('Master Matrix'!Q$4:Q$41,MATCH($B$4,'Master Matrix'!$G$4:$G$41,0)),"") -> Stage 1-2. Isometric abductor holds for analgesia; progressive abductor loading IN NEUTRAL 3-4 sets 8-12 RM 3x/week; avoid adduction-loaded exercises such as clamshells in adduction and crossed-leg stretching
A22: BIOMECHANICAL CORRECTIONS & KINETIC CHAIN | B22: =IFERROR(INDEX('Master Matrix'!R$4:R$41,MATCH($B$4,'Master Matrix'!$G$4:$G$41,0)),"") -> REMOVE THE COMPRESSION, then load: stop standing in hip-hanging posture and crossing the legs, use a pillow between the knees at night, avoid ITB stretching and foam rolling over the trochanter, correct Trendelenburg gait and pelvic drop with abductor strengthening, address step width and stair strategy
A23: Manual therapy, positional & adjuncts | B23: =IFERROR(INDEX('Master Matrix'!S$4:S$41,MATCH($B$4,'Master Matrix'!$G$4:$G$41,0)),"") -> Sleeping position advice and a pillow between the knees are among the highest-yield interventions; AVOID ITB stretching and rolling over the trochanter; taping is of limited value
A24: Advanced / surgical options | B24: =IFERROR(INDEX('Master Matrix'!T$4:T$41,MATCH($B$4,'Master Matrix'!$G$4:$G$41,0)),"") -> Guided corticosteroid injection gives short-term relief only and is inferior to education plus exercise at 12 months; ESWT as an adjunct in refractory cases; surgical gluteal tendon repair for a confirmed full-thickness tear
A25: Outcome measures | B25: =IFERROR(INDEX('Master Matrix'!U$4:U$41,MATCH($B$4,'Master Matrix'!$G$4:$G$41,0)),"") -> VISA-G; HOOS; Oxford Hip Score; NPRS on side-lying and stairs
A26: Re-testable markers | B26: =IFERROR(INDEX('Master Matrix'!V$4:V$41,MATCH($B$4,'Master Matrix'!$G$4:$G$41,0)),"") -> Side-lying tolerance; single-leg stance time to pain; stair pain; abductor strength LSI; trochanteric tenderness
A27: Expected timeline | B27: =IFERROR(INDEX('Master Matrix'!W$4:W$41,MATCH($B$4,'Master Matrix'!$G$4:$G$41,0)),"") -> 12 weeks for meaningful change; 3-6 months for full resolution
A28: Referral / surgical trigger | B28: =IFERROR(INDEX('Master Matrix'!X$4:X$41,MATCH($B$4,'Master Matrix'!$G$4:$G$41,0)),"") -> Suspected full-thickness gluteal tendon tear (marked weakness, Trendelenburg); failure after a well-delivered 12-week programme
A29: Evidence anchor | B29: =IFERROR(INDEX('Master Matrix'!Y$4:Y$41,MATCH($B$4,'Master Matrix'!$G$4:$G$41,0)),"") -> LEAP trial (Mellor BMJ 2018); Grimaldi & Fearon JOSPT 2015
A31: NOTES
A32: • Green text is pulled from the Master Matrix — edit the matrix, not this sheet.
A33: • Check RED FLAG STATUS first. A crimson entry means screen or refer before rehabilitating.
A34: • The DESIRED ACTIVITY GOAL and PHYSIOTHERAPY SPECIFIC EXERCISE rows are written to be handed straight to the patient.
A35: • Print this sheet (portrait, fit to one page wide) for the patient file.

Sheet Assessment Roadmap
A1: FIVE-GATE ASSESSMENT ROADMAP
A2: Work top to bottom. Gate 3 — pain, stiffness or instability — does most of the diagnostic work.
A3: Gate | B3: Purpose | C3: What You Assess | D3: Findings That Matter | E3: Decision Rule
A4: GATE 1 | B4: Screen for serious pathology | C4: High-risk bone stress; fracture; septic joint; malignancy; AVN; visceral referral; paediatric emergencies | D4: TENSION-side femoral neck stress fracture (groin pain now present on walking) is an emergency. Hip fracture after a fall (shortened, externally rotated leg). Hot, painful hip with fever = sepsis. Constant non-mechanical night pain with systemic features or cancer history = malignancy. Progressive rest and night pain with corticosteroid or alcohol history = AVN. ADOLESCENT WITH HIP OR KNEE PAIN AND A LIMP = SCFE until excluded | E4: If present -> investigate or refer BEFORE local treatment
A5: GATE 2 | B5: Screen the lumbar spine and pelvis | C5: Lumbar range and provocation; straight leg raise and slump; sacroiliac provocation cluster; neurological screen | D5: The lumbar spine refers to the buttock, groin and thigh constantly. Symptoms changed more by SPINE than by HIP movement, with negative hip provocation tests, points to a lumbar source. HIP-SPINE SYNDROME is common - both may be contributing and both may need treatment. Screen for inflammatory back pain features in the young adult | E5: Clear the spine and pelvis BEFORE committing to a hip diagnosis
A6: GATE 3 | B6: Anterior, lateral, posterior or medial? | C6: Localise the pain generator by region, then by structure, then by mechanism | D6: ANTERIOR/GROIN: intra-articular (FAI, labrum, OA, AVN), iliopsoas, adductor, inguinal, pubic, femoral neck. LATERAL: gluteal tendinopathy (GTPS), bursa, snapping ITB, lateral femoral cutaneous nerve. POSTERIOR: proximal hamstring, deep gluteal, ischiofemoral, sacroiliac, lumbar referral. MEDIAL/PUBIC: adductor and pubic-related. The C-SIGN (gripping the hip with a C-shaped hand) suggests an intra-articular source | E6: Map pain to region -> structure -> mechanism
A7: GATE 4 | B7: Cluster to a working diagnosis | C7: History + palpation + provocation + the Doha groin classification | D7: Cluster 1 FAI syndrome (Warwick): symptoms AND clinical signs AND imaging findings - all three. Cluster 2 Adductor-related (Doha): adductor tenderness AND pain on resisted adduction. Cluster 3 GTPS: lateral hip pain + trochanteric tenderness + pain on 30-second single-leg stance. Cluster 4 Sacroiliac: 3 or more of 5 provocation tests positive | E7: Clustering beats any single test. In groin pain, use the Doha entity classification - more than one entity commonly coexists
A8: GATE 5 | B8: Quantify impairments and capacity | C8: Range (especially internal rotation); hip abductor and adductor strength; squeeze test; single-leg control; gait | D8: Hip internal rotation range at 90 degrees flexion (lost early in FAI and OA); ADDUCTOR SQUEEZE FORCE at 0, 45 and 90 degrees; hip abductor strength and the adduction:abduction ratio; 30-second single-leg stance; Trendelenburg sign; single-leg squat and step-down quality; sitting tolerance | E8: These become the baseline re-testable markers that drive the plan and, for athletes, return-to-sport testing
A10: DIAGNOSTIC ALGORITHM — NARRATIVE FLOW
A11: • Hip or groin pain → Red flags? YES: image or refer. NO ↓
A12: • Referred from the lumbar spine? YES: treat the lumbar source (and screen for hip-spine syndrome). NO ↓
A13: • Which region?
A14: • ANTERIOR / GROIN → C-sign with deep flexion and sitting, restricted internal rotation = intra-articular (FAI, labrum, OA, AVN). Resisted adduction pain = adductor-related. Resisted hip flexion pain = iliopsoas-related. Central pubic tenderness = pubic-related. Cough or Valsalva pain = inguinal-related. Pain now on WALKING in a runner = femoral neck stress fracture.
A15: • LATERAL → unable to lie on that side with trochanteric tenderness and positive 30-second single-leg stance = GTPS. Marked weakness with Trendelenburg = gluteal tendon tear. Burning and numbness with no weakness = meralgia paraesthetica.
A16: • POSTERIOR → ischial pain worst on SITTING = proximal hamstring tendinopathy. Deep buttock pain with leg symptoms and negative lumbar screen = deep gluteal syndrome. Pain on LONG STRIDES = ischiofemoral impingement. Three or more provocation tests positive = sacroiliac.
A17: • PAEDIATRIC → adolescent with hip or knee pain and a limp = SCFE. Child with a limp and limited abduction = Perthes. Unwell febrile child = septic arthritis. Sudden pop in an adolescent = apophyseal avulsion.
A18: • Confirm with the impairment and capacity profile → set baseline markers → enter the Phased Programme.
A20: CLINICAL PEARL
A21: • Convert every diagnosis into two or three re-testable markers BEFORE you treat — hip internal rotation range, adductor squeeze figure, 30-second single-leg stance, or sitting tolerance.
A22: • If those markers do not improve over 4-6 weeks of appropriate loading, revisit the diagnosis, re-screen the lumbar spine, and check whether a compressive position is still being loaded.

Sheet Subjective Exam
A1: SUBJECTIVE EXAMINATION TEMPLATE
A2: Yellow column is the input column. A structured history alone points to the diagnosis in most shoulder presentations.
A3: Domain | B3: What to Ask | C3: Why It Matters | D3: Findings (fill in)
A4: Onset & mechanism | B4: Insidious/overuse or traumatic? Kicking, cutting, sprinting, a fall, or no clear event? | C4: Insidious points to FAI, tendinopathy, OA or bone stress; sudden points to strain, avulsion or fracture | D4: e.g. insidious over 3 months, after increasing running from 20 to 45 km/week
A5: Age & context | B5: Age; occupation; sport and level; training volume and recent change | C5: Age transforms the differential: SCFE and Perthes in children, FAI and groin pain in young adults, OA and gluteal tendinopathy in the older adult
A6: Pain location | B6: Point with one finger. Groin / lateral / posterior / pubic. Do they grip the hip in a C-shape? | C6: The C-SIGN suggests an intra-articular source. Groin = intra-articular or muscle-related. Lateral = gluteal tendon. Posterior = hamstring, deep gluteal or lumbar
A7: Radiation | B7: Does it travel down the leg? Any numbness or pins and needles? | C7: Leg symptoms with a positive lumbar screen point to the spine, not the hip; burning over the outer thigh with no weakness suggests meralgia paraesthetica
A8: Aggravating movements | B8: Deep squatting, prolonged sitting, kicking, cutting, stairs, single-leg standing, lying on the side, long strides | C8: Sitting = FAI or proximal hamstring. Lying on the side = GTPS. Kicking = adductor or iliopsoas. Long strides = ischiofemoral
A9: SITTING TOLERANCE | B9: How long can you sit before it hurts? Hard or soft chair? Car journeys? | C9: The defining functional limitation in proximal hamstring tendinopathy, and a major one in FAI
A10: NIGHT PAIN & SIDE-LYING | B10: Can you lie on that side? Do you sleep with a pillow between the knees? | C10: Inability to lie on the side is the hallmark of GTPS; the pillow question leads straight into the highest-yield early intervention
A11: Load & training change | B11: Recent change in running volume, cutting or kicking load, gym content, or walking volume | C11: Almost every atraumatic hip and groin presentation is a load change on an unprepared hip
A12: LUMBAR SCREEN | B12: Any back pain or stiffness? Does moving your back change the hip pain? Any leg symptoms? | C12: GATE 2 — the lumbar spine refers to the buttock, groin and thigh constantly. Hip-spine syndrome is common
A13: RED FLAG SCREEN | B13: Groin pain now present on walking? Constant night pain unrelated to movement? Weight loss or cancer history? Fever or unwell? Corticosteroid or alcohol history? A fall with inability to weight-bear? Bladder or bowel change? | C13: GATE 1 — bone stress, fracture, sepsis, malignancy, AVN and cauda equina all present as hip pain
A14: PAEDIATRIC SCREEN | B14: In a child or adolescent: is there a limp? Any KNEE pain? Recent illness? Is the child systemically well? | C14: AN ADOLESCENT WITH HIP OR KNEE PAIN AND A LIMP IS SCFE UNTIL EXCLUDED. A febrile child refusing to weight-bear is septic until excluded
A15: Bone health & energy availability | B15: In athletes: menstrual history, dietary intake relative to training, previous bone stress injury, stress fracture history | C15: Low energy availability is the central driver of bone stress injury and is highly prevalent in running, dance and gymnastics
A16: Hypermobility | B16: Do your joints feel loose? Were you very flexible as a child? Any dance, gymnastics or yoga background? | C16: Hypermobility REVERSES the approach in microinstability and dysplasia — stretching makes it worse. Record a Beighton score
... A19: Goals | B19: What do you want to get back to — specifically? | C19: Feeds directly into the DESIRED ACTIVITY GOAL column of the Master Matrix
A21: HOW TO FILL THIS SHEET
A22: • Row 4 shows an example entry in grey — overwrite it.
A23: • Three questions triage most hip and groin pain fast: "Can you point to it with one finger?", "What brings it on — sitting, kicking, standing on one leg, lying on it?", and "Does moving your back change it?"
A24: • In anyone under 18 with hip OR knee pain and a limp, stop and consider SCFE and Perthes before anything else.

Sheet Objective Exam
A1: PHYSICAL EXAMINATION TEMPLATE
A2: Yellow columns are input columns. Two distinctions organise the whole examination — see the note at the foot of the sheet.
A3: Section | B3: Item | C3: How to Test / What to Look For | D3: Involved (fill in) | E3: Uninvolved (fill in) | F3: Interpretation
A4: Observation | B4: Standing posture & pelvic position | C4: Anterior pelvic tilt, pelvic obliquity, lumbar lordosis, standing on one hip | D4: e.g. anterior tilt, stands on right hip | E4: similar | F4: Standing hanging on one hip is a direct compressive driver in GTPS
A5: Observation | B5: Muscle bulk | C5: Gluteal bulk and symmetry; quadriceps and hamstring bulk | F5: Gluteal wasting is common and is the main rehabilitation target across most hip diagnoses
A6: Observation | B6: GAIT | C6: Antalgia, Trendelenburg or compensated Trendelenburg, stride length, step width, foot progression angle | F6: Trendelenburg indicates abductor deficiency; a long stride pattern provokes ischiofemoral impingement
A7: Observation | B7: Leg length | C7: Real and apparent leg length | F7: Relevant post-arthroplasty and in sacroiliac and pelvic girdle presentations
A8: Palpation | B8: Greater trochanter | C8: Focal tenderness over the gluteal tendon insertion | F8: GTPS — cluster with the 30-second single-leg stance test
A9: Palpation | B9: Adductor longus origin | C9: Focal tenderness at the enthesis | F9: Adductor-related groin pain (Doha criterion)
A10: Palpation | B10: Pubic symphysis & adjacent bone | C10: Central tenderness | F10: Pubic-related groin pain (Doha criterion)
A11: Palpation | B11: Inguinal canal | C11: Tenderness; NO palpable hernia | F11: Inguinal-related groin pain (Doha criterion)
A12: Palpation | B12: Iliopsoas | C12: Tenderness lateral to the femoral pulse | F12: Iliopsoas-related groin pain (Doha criterion)
A13: Palpation | B13: Ischial tuberosity | C13: Focal tenderness | F13: Proximal hamstring tendinopathy
A14: Palpation | B14: Sacroiliac region / PSIS | C14: Tenderness; Fortin finger test | F14: Sacroiliac joint-related pain
A15: Range (passive) | B15: Hip flexion (degrees) | C15: Supine, pelvis stabilised | F15: Compare sides
A16: Range (passive) | B16: INTERNAL ROTATION at 90 deg flexion | C16: Supine, hip and knee at 90 degrees, pelvis stabilised | D16: e.g. 15 | E16: 35 | F16: THE most important single measurement — lost earliest in FAI and hip OA
A17: Range (passive) | B17: External rotation at 90 deg flexion | C17: Supine, pelvis stabilised | F17: Excess rotation suggests capsular laxity or microinstability
A18: Range (passive) | B18: Hip extension (Thomas test) | C18: Thomas test position; note hip flexor and rectus femoris length | F18: Restricted extension drives anterior pelvic tilt and iliopsoas overload
A19: Range (passive) | B19: Abduction (degrees) | C19: Supine, pelvis stabilised | F19: THE key measure in Perthes and in paediatric DDH
A20: Strength | B20: ADDUCTOR SQUEEZE (0, 45, 90 deg) | C20: Sphygmomanometer or dynamometer between the knees — RECORD THE FIGURE | F20: Simultaneously diagnostic, the treatment target and the discharge criterion in all groin presentations
A21: Strength | B21: Hip abduction (kg) | C21: Handheld dynamometry in side-lying or supine | F21: Feeds the LSI and the adduction:abduction ratio in the Progress Tracker
A22: Strength | B22: Hip adduction (kg) | C22: Handheld dynamometry | F22: Feeds the adduction:abduction ratio — a low ratio predicts groin injury
A23: Strength | B23: Hip extension (kg) | C23: Handheld dynamometry or single-leg bridge repetitions | F23: Gluteus maximus capacity
A24: Strength | B24: Hip flexion (kg) | C24: Handheld dynamometry | F24: Iliopsoas capacity; also relevant post-psoas surgery
A25: Control | B25: 30-SECOND SINGLE-LEG STANCE | C25: Time to pain onset; observe for pelvic drop | F25: The primary GTPS test AND the primary re-test marker
A26: Control | B26: Single-leg squat / step-down quality | C26: Pelvic drop, dynamic valgus, trunk lean; grade good / fair / poor | F26: Frontal-plane control — the treatment target across most hip diagnoses
A27: Control | B27: Trendelenburg sign | C27: Pelvic drop on the contralateral side in single-leg stance | F27: Marked drop with weakness suggests a gluteal tendon tear rather than tendinopathy
A28: Special tests | B28: FADIR (anterior impingement) | C28: See Special Tests sheet | F28: Highly SENSITIVE — a negative test makes intra-articular pathology unlikely
