Workbook

Sheet Read Me
A1: KNEE ASSESSMENT & MANAGEMENT PROGRAMME
A2: A single clinical-reasoning workbook: screen → cluster → diagnose → load → progress → discharge on capacity.
A4: SHEET | B4: WHAT IT DOES | C4: WHEN TO USE IT | D4: SOURCE
A5: Master Matrix | B5: 40 knee conditions with the full reasoning chain: presentation → differentiating question → confirmatory test → biomechanical cause → management emphasis → loading dose → biomechanical corrections → adjuncts → advanced options → outcome measures → referral triggers. | C5: The core reference. Start here once you have a working diagnosis. | D5: Diagnostics algorithm + Course Manual Modules 10-15
A6: Rx Generator | B6: Pick a diagnosis from the dropdown and the full management prescription is pulled automatically from the Master Matrix. | C6: In clinic, to build a plan in seconds or print a plan for a patient file. | D6: Live INDEX/MATCH from Master Matrix
A7: Assessment Roadmap | B7: The five-gate reasoning sequence from red-flag screen to capacity profiling. | C7: Every new patient, in order, top to bottom. | D7: Module 9
A8: Subjective Exam | B8: Fillable history template with the screening questions built in. | C8: First consultation. | D8: Module 4
A9: Objective Exam | B9: Fillable physical examination template: observation, palpation, ROM, strength, control, special tests. | C9: First consultation and every re-assessment. | D9: Module 5
A10: Special Tests | B10: Ligament, meniscal, patellofemoral, effusion and screening tests with what a positive means. | C10: During the physical examination. | D10: Module 6
A11: Diagnostic Clusters | B11: The three high-yield clusters and the one-line differentiators. | C11: When the picture is not yet clear. | D11: Modules 6, 7 and 10
A12: Imaging Guide | B12: When to image, which modality answers which question, and how to interpret it. | C12: Before requesting or when reviewing a report. | D12: Module 8
A13: Phased Programme | B13: Phase 0-4 management structure with entry criteria, content and exit criteria. | C13: Building and progressing every treatment plan. | D13: Modules 11 and 15
A14: Exercise & Dosage | B14: Loading library: stage, purpose, exercises, dose, and which conditions it suits. | C14: Writing the actual programme. | D14: Module 11 and Appendix B
A15: Adjuncts & Advanced | B15: Taping, bracing, orthoses, ESWT, PEMF, electrotherapy, injectables and surgery, with the sequencing rule. | C15: When loading alone is not enough. | D15: Modules 12 and 13
... A22: References | B22: Guideline and primary-source list. | C22: Verifying or citing. | D22: Manual reference list
A25: HOW TO USE THIS WORKBOOK
A26: • Cells shaded pale yellow are the ones you fill in. Everything else is reference content or a formula — leave it alone.
A27: • Green text = a value pulled from another sheet. Black text = a formula. Do not overwrite formula cells.
A28: • The Progress Tracker and Rx Generator contain live formulas. Enter data only in the yellow input cells.
A29: • ASSUMPTION: the "Typical Activity Level" column in the Master Matrix was blank in the source algorithm and has been populated from the presentation profile of each condition. Review and adjust to your caseload.
A30: • This workbook supports clinical reasoning — it does not replace individualised assessment, local protocols or professional judgement. Post-operative restrictions ALWAYS defer to the operating surgeon's protocol.

Sheet Master Matrix
A1: MASTER DIAGNOSTIC & MANAGEMENT MATRIX — 40 KNEE CONDITIONS
A2: Columns A–J: the diagnostic algorithm. Columns K–W: the management programme. Filter column A by region or column G by diagnosis.
A3: Region / Site of Pain | B3: Typical Activity Level | C3: Signs & Symptoms | D3: Age (yrs) | E3: Onset | F3: Sex Predominance | G3: Provisional Diagnosis | H3: One Question That Best Discriminates | I3: Confirmatory Test / Imaging | J3: Underlying Biomechanical Cause | K3: Pain Mechanism | L3: Diagnostic Cluster / Classification | M3: Red Flag Status | N3: MANAGEMENT EMPHASIS | O3: Loading Stage & Entry Dose | P3: BIOMECHANICAL CORRECTIONS & KINETIC CHAIN | Q3: Manual Therapy, Taping, Bracing & Orthoses | R3: Advanced / Adjunct Options (if stalled 8-12 wks) | S3: Outcome Measures | T3: Re-testable Markers | U3: Expected Timeline | V3: Referral / Surgical Trigger | W3: Evidence Anchor
A4: Anterior | B4: Recreational runner / stair- and squat-loaded daily activity | C4: Pain while stairs, sitting, squatting | D4: 10-30 | E4: Slow | F4: Female | G4: Patellofemoral Pain Syndrome | H4: Is pain worse while climbing down stairs or after prolonged sitting? | I4: Patellar grind test + MRI/Xray | J4: VMO Weakness, IT Band tightness, Recture femoris tightness, hip external rotators, specifically the Gluteus Medius and Gluteus Maximus weakness | K4: Nociceptive (compressive, load-related); nociplastic if persistent >6 months | L4: Cluster 1 - Patellofemoral pain; JOSPT 2019 impairment subgroups (overuse/overload, muscle performance, movement coordination, mobility) | M4: No | N4: Hip + knee strengthening (JOSPT 2019, BJSM 2024), load management, movement retraining, short-term taping; orthoses if foot-driven | O4: Stage 1-2. Hip posterolateral (abductor/ER) work prioritised early + quadriceps isotonic 3-4 sets, 8-12 RM, 2-3x/week; add CKC in non-provocative range. Pain <=5/10 during loading, settling to baseline within 24 h | P4: Correct dynamic valgus: gluteus medius/maximus strengthening, single-leg squat and step-down retraining, running gait cues (cadence +5-10%, widen narrow step width, reduce overstriding). Restore rectus femoris, ITB, hamstring and gastrocnemius extensibility. Trial OTC foot orthoses where navicular drop / over-pronation drives the knee. Reduce squat depth and stair volume temporarily rather than resting | Q4: McConnell or kinesio patellar taping short-term to open a comfort window for exercise; foot orthoses (OTC comparable to custom short-term); manual therapy as an adjunct combined with exercise, never stand-alone | R4: Rarely required. If stalled >12 weeks, audit dosage, adherence and diagnosis before adding low-risk symptomatic adjuncts (laser, TENS). Imaging only for atypical or refractory presentation | S4: KOOS-PF; Kujala Anterior Knee Pain Scale; NRS on squat and stair descent | T4: Squat pain NRS; single-leg step-down quality (valgus); quadriceps strength LSI; sitting tolerance in minutes | U4: Meaningful change 6-12 weeks; full resolution commonly 3-6 months | V4: No response to 12 weeks of well-delivered loading; mechanical locking; suspected chondral lesion or patellar instability | W4: Willy 2019 JOSPT CPG; Neal 2024 BJSM best-practice guide
A5: Anterior | B5: Active / overtraining recreational athlete | C5: Grinding under patella | D5: 15-40 | E5: Slow | F5: Female | G5: Chondromalacia Patella | H5: Do you feel grinding or crunching under the kneecap? | I5: MRI | J5: Overtraining, VMO Weakness, IT Band tightness, Recture femoris tightness, hip external rotators, specifically the Gluteus Medius and Gluteus Maximus weakness | K5: Nociceptive (articular compressive overload) | L5: Anterior compartment - patellofemoral chondral pathology; overlaps Cluster 1 | M5: No | N5: Treat as patellofemoral pain: load management first, quadriceps and hip strengthening, movement retraining; modify provocative deep-flexion loading; reassure that cartilage signal change does not dictate prognosis | O5: Stage 1-2. Isometric/inner-range quadriceps for irritability, progressing to isotonic loading in a pain-tolerated arc; avoid high patellofemoral joint stress angles (deep squat, prolonged loaded flexion) early | P5: Reduce patellofemoral contact stress: correct dynamic valgus and lateral patellar tracking (VMO/hip control), restore rectus femoris and ITB/lateral retinaculum extensibility, address training volume spikes, modify squat depth and step-down range, correct foot pronation if contributory | Q5: Patellar taping to offload laterally; short-term activity modification; manual therapy for retinacular mobility as an adjunct | R5: If stalled beyond 8-12 weeks with continued loading: consider NMES for marked quadriceps inhibition; imaging (MRI) only if surgical question arises | S5: KOOS-PF; Kujala; NRS on stairs and squat | T5: Loaded flexion range before pain onset; step-down quality; quadriceps LSI | U5: 8-16 weeks; longer where a chondral defect is confirmed | V5: Mechanical symptoms, effusion or failure to progress -> imaging and surgical opinion | W5: JOSPT 2019 CPG (PFP pathway); Manual Module 10/11
A6: Anterior | B6: Young pivoting / cutting athlete; often generalised laxity | C6: Giving way, swelling | D6: 10-25 | E6: Sudden | F6: Female | G6: Patellar Instability | H6: Does your kneecap feel like it slips out? | I6: Apprehension test + MRI | J6: Medial Patellofemoral Ligament (MPFL) torn or stretched, Generalized Ligamentous Laxity, Increase q angle, Bone alligment | K6: Nociceptive with mechanical instability; fear-avoidance component common | L6: Anterior - patellar instability; ESSKA 2024 consensus (first-time dislocation) | M6: Screen: exclude osteochondral fracture and loose body after dislocation | N6: Rehabilitation first for first-time dislocation - VMO and hip control, bracing/taping for confidence; surgical (MPFL) opinion for recurrent instability (ESSKA 2024) | O6: Stage 1-2. Restore quadriceps activation and effusion control; isometric then isotonic quadriceps in protected range; progress to controlled single-leg loading and landing once apprehension settles | P6: Reduce lateral patellar vector: gluteus medius/maximus and hip external rotator strengthening, correct dynamic valgus and knee-in landing, control tibial internal rotation, address foot pronation and increased Q-angle contributors; retrain deceleration and cutting mechanics before return | Q6: Patellar stabilising brace or taping to support activity during rehabilitation - scaffolding, not a substitute for capacity | R6: Recurrent instability, osteochondral fragment or trochlear dysplasia risk factors -> orthopaedic opinion for MPFL reconstruction | S6: Kujala; KOOS; Tegner activity level; patellar instability recurrence count | T6: Apprehension response; single-leg squat and landing control; quadriceps LSI; hop symmetry | U6: 6-12 weeks for first-time; 6-9 months to sport after MPFL reconstruction | V6: Second dislocation, osteochondral fragment, persistent apprehension despite rehabilitation | W6: ESSKA 2024 formal consensus; Manual Module 10 (#8)
A7: Anterior | B7: Jump / court athlete (volleyball, basketball, pickleball); high energy-storage demand | C7: Pain during jumping | D7: 15-40 | E7: Slow | F7: Male | G7: Patellar Tendinopathy | H7: Is pain worse during jumping or landing? | I7: Decline squat test + USG/MRI | J7: Excessive and repetitive deceleration mechanical loading like jumping and landing, | K7: Nociceptive (tensile tendon load) | L7: Anterior - Cook & Purdam tendinopathy continuum: stage as reactive / dysrepair / degenerative | M7: No | N7: Progressive loading (isometric -> heavy slow resistance/eccentric - all comparable), load management, kinetic chain; ESWT adjunct if refractory | O7: Stage the tendon first. Reactive: isometric holds 5 x 30-45 s, 1-2x/day for analgesia + reduce peak energy-storage load. Dysrepair/degenerative: heavy slow resistance 3-4 sets, 6-12 RM, 3 s up / 3 s down, 2-3x/week. Then energy storage (hops, jumps, decelerations) -> sport-specific | P7: Address the spring the tendon sits in: calf and gluteal capacity, ankle dorsiflexion range, landing and deceleration mechanics (soft knee-hip flexion strategy, avoid stiff landing), correct training-volume spikes and jump count, review footwear and surface | Q7: Short-term load modification; patellar strap/taping for symptom relief during loading; manual therapy as adjunct only | R7: If stalled >8-12 weeks while still loading: ESWT (radial or focused, typically 3-5 weekly sessions) as an add-on. Avoid corticosteroid injection into tendon substance. PRP evidence mixed | S7: VISA-P; NRS on decline single-leg squat | T7: Decline single-leg squat pain NRS; single-leg hop and countermovement jump height; VISA-P score | U7: 12 weeks minimum; commonly 3-6 months to full jump load | V7: No response after 12 weeks of correctly dosed loading + adjunct; suspect partial tear on imaging | W7: Cook & Purdam 2009; Kongsgaard 2009; Heliyon 2024 network meta-analysis
A8: Anterior | B8: Middle-aged / strength athlete or sedentary with systemic tendon risk factors | C8: Unable to straighten knee | D8: 40-60 | E8: Sudden | F8: Male | G8: Quadriceps Tendon Tear | H8: Were you suddenly unable to straighten the knee? | I8: SLR failure + MRI | J8: Chronic quadriceps tendon degeneration (pre-existing tendinopathy) failing under sudden eccentric overload on a semi-flexed, weight-bearing knee; poor eccentric quadriceps capacity, deconditioning; systemic tendon-weakening factors (diabetes, chronic kidney disease, steroid or fluoroquinolone use) | K8: Nociceptive - acute structural failure | L8: Anterior extensor mechanism disruption | M8: YES - inability to perform straight leg raise / extension lag = urgent surgical referral | N8: Urgent orthopaedic referral for repair. Post-operative: protected extension, avoid active extension against resistance for approximately 6 weeks, then graded quadriceps loading (see Post-Surgical Protection sheet) | O8: Post-repair only. Weeks 0-6 protected ROM per surgeon, isometric quadriceps at low angles, NMES for inhibition. Weeks 6-12 progressive isotonic. Then energy storage and sport-specific | P8: After healing: rebuild eccentric quadriceps capacity, restore full knee extension and quadriceps bulk, correct step-down and landing mechanics; screen and co-manage systemic tendon-weakening factors (diabetes, chronic kidney disease, steroid or fluoroquinolone use) | Q8: Post-operative brace per surgeon; NMES for quadriceps inhibition; cryotherapy for effusion control | R8: Surgical repair is the primary treatment. NMES strongly indicated where voluntary quadriceps activation is poor | S8: IKDC; Lysholm; quadriceps strength LSI; extension lag in degrees | T8: Extension lag; straight leg raise without lag; quadriceps LSI; step-down control | U8: 6 weeks protection; 4-6 months to full function; 6-9 months to sport | V8: Immediate - suspected extensor mechanism rupture is a surgical presentation | W8: Manual Module 10 (#3 group); Post-surgical protection guide (category 8)
A9: Anterior | B9: Adolescent athlete in growth spurt; jumping / sprinting / kicking sports | C9: Pain below kneecap in sports | D9: 10-15 | E9: Slow | F9: Male | G9: Osgood Schlatter Disease | H9: Does the bump below the kneecap hurt after sports? | I9: X-ray | J9: Traction apophysitis at the tibial tuberosity — growth spurt with relative rectus femoris, quadriceps and hamstring tightness, weak eccentric quadriceps control, and repetitive jumping, sprinting and kicking loads exceeding the capacity of the immature apophysis | K9: Nociceptive - traction apophysitis | L9: Anterior - adolescent apophyseal (with Sinding-Larsen-Johansson) | M9: No - but confirm it is apophysitis, not tumour or infection, if night pain or systemic features | N9: Load management, quadriceps flexibility/strength, reassurance; self-limiting with maturity | O9: Stage 1-2 modified for the immature apophysis. Isometric quadriceps for analgesia; graded isotonic quadriceps and hip loading; reduce jump/sprint volume rather than stopping sport entirely | P9: Restore rectus femoris, quadriceps and hamstring extensibility during growth spurt; build eccentric quadriceps control; modify jumping, sprinting and kicking volume; review training load spikes and multi-sport scheduling; kneeling protection | Q9: Activity modification, ice after sport, infrapatellar strap for symptom relief; education on the self-limiting course | R9: Not indicated. Avoid injections around the apophysis | S9: NRS on sport; Kujala; parent/athlete activity diary | T9: Tibial tubercle tenderness; pain-free jump count; single-leg squat control | U9: Symptom control in weeks; resolves with skeletal maturity | V9: Persistent pain after physeal closure, or an ossicle causing ongoing symptoms -> orthopaedic opinion | W9: Manual Module 10 (#5)
A10: Anterior | B10: Any activity level; often hyperextension postures and prolonged standing | C10: Pain in full extension | D10: 20-50 | E10: Slow | F10: Female | G10: Hoffa Fat Pad Impingement | H10: Does the knee hurt more when fully straightened? | I10: Hoffa test + MRI | J10: Fat pad compression from repeated forced extension — knee hyperextension and anterior pelvic tilt posture, rectus femoris tightness with VMO weakness, patella alta and patellar maltracking, quadriceps dominance over hip extensors; often perpetuated by post-traumatic fat pad inflammation and scarring | K10: Nociceptive - compressive; highly sensitive tissue | L10: Anterior - compressive-load pain subgroup | M10: No | N10: Avoid provocative hyperextension, taping to offload, quadriceps control | O10: Stage 1-2 within a protected range. Isometric quadriceps in mid-range for analgesia; avoid end-range extension loading early; progress isotonic loading through a pain-tolerated arc | P10: Remove the compressive mechanism: correct knee hyperextension and anterior pelvic tilt standing posture, reduce rectus femoris tightness, build VMO and hip extensor capacity to unload quadriceps dominance, modify prolonged standing and terminal-extension loading; address patella alta / maltracking contribution | Q10: Infrapatellar unloading tape (fat pad taping) is the highest-yield adjunct here; short-term activity modification | R10: Refractory cases: consider guided injection only after well-executed conservative care; arthroscopic resection is rarely indicated | S10: Kujala; KOOS-PF; NRS in standing and terminal extension | T10: Pain on forced extension; standing tolerance; step-down control | U10: 6-12 weeks | V10: Persistent after 12 weeks of correct offloading and loading | W10: Manual Module 10 (#4)
A11: Anterior | B11: Cyclist / runner with a recent volume increase | C11: Clicking/snapping knee | D11: 10-30 | E11: Slow | F11: Equal | G11: Plica Syndrome | H11: Do you feel snapping or clicking inside the knee? | I11: MRI | J11: Friction of a thickened medial plica over the femoral condyle during repetitive flexion-extension — VMO weakness with lateral patellar maltracking, quadriceps and hamstring tightness, sudden increase in cycling or running volume; direct trauma or persistent effusion causing plica fibrosis | K11: Nociceptive - mechanical friction | L11: Anterior/medial - mechanical, diagnosis of exclusion | M11: No | N11: Load modification, quadriceps control; surgery rarely needed | O11: Stage 1-2. Isometric then isotonic quadriceps in the non-provocative arc; graded return to repetitive flexion-extension volume | P11: Reduce friction over the femoral condyle: correct lateral patellar maltracking with VMO and hip control work, restore quadriceps and hamstring extensibility, review cycling saddle height and cleat position, moderate cadence and volume, address effusion driving plica fibrosis | Q11: Manual therapy for retinacular and plica mobility; short-term taping; activity modification | R11: Persistent symptomatic plica after 3 months of conservative care -> arthroscopic excision (see Post-Surgical Protection sheet, category 9) | S11: Kujala; KOOS; NRS on repetitive flexion tasks | T11: Clicking/catching frequency; loaded flexion range; step-down control | U11: 6-12 weeks | V11: Persistent mechanical catching after 3 months of conservative care | W11: Manual Module 10 (#13)
A12: Anterior | B12: Occupational or prayer-related kneeling; any activity level | C12: Anterior swelling | D12: 20-60 | E12: Slow | F12: Male | G12: Prepatellar Bursitis | H12: Do you kneel frequently for work or prayer? | I12: Ultrasound | J12: Repetitive direct compression and shear over the prepatellar bursa from prolonged or repeated kneeling — poor hip-hinge and squat strategy (kneeling instead of loading hip and ankle), restricted ankle dorsiflexion and hip mobility, occupational or prayer-related kneeling load | K12: Nociceptive - superficial compressive/inflammatory | L12: Anterior - superficial bursal | M12: Screen: hot, red, systemically unwell = septic bursitis, urgent referral | N12: Reduce friction/kneeling, address swelling; aspirate/antibiotics if septic | O12: Loading is secondary here. Maintain quadriceps and hip capacity while the bursa settles; avoid direct compression | P12: Change the kneeling strategy: teach hip-hinge and squat loading instead of direct kneeling, restore ankle dorsiflexion and hip mobility so squatting is available, prescribe kneeling pads and task rotation, modify occupational and prayer positions | Q12: Kneeling pads, compression, relative rest from direct pressure; ice for swelling | R12: Aspiration and antibiotics if septic; excision is reserved for chronic recalcitrant bursitis | S12: NRS; swelling measurement; kneeling tolerance | T12: Swelling size; kneeling tolerance in minutes; local temperature | U12: 2-6 weeks with load removal | V12: Systemic features, marked warmth or fever -> urgent medical referral for possible septic bursitis | W12: Manual Module 10 (#7)
A13: Anterior | B13: Older adult; stair- and chair-loaded daily activity | C13: Crepitus and stair pain | D13: 50+ | E13: Slow | F13: Female | G13: Patellofemoral Osteoarthritis | H13: Is pain worse while using stairs or getting up from a chair? | I13: X-ray | J13: Long-standing patellofemoral contact stress — VMO weakness with lateral retinaculum and IT band tightness, rectus femoris tightness, gluteus medius and maximus weakness producing dynamic valgus, increased Q angle, trochlear dysplasia or patella alta, and raised body mass increasing joint load | K13: Nociceptive with common nociplastic overlay in long-standing cases | L13: Anterior - degenerative patellofemoral compartment | M13: No | N13: Exercise + education + weight management (first-line: OARSI/ACR/NICE); quadriceps and hip strengthening, load management; taping/bracing as symptomatic adjuncts | O13: Stage 1-2 sustained. Quadriceps and hip strengthening 2-3x/week + aerobic conditioning + neuromuscular training; mode by patient preference. Symptom flares are expected and manageable - do not stop loading | P13: Reduce patellofemoral contact stress across the day: modify stair and deep-squat strategy (hip-dominant chair rise, step-over-step where tolerated), strengthen VMO and gluteals to reduce dynamic valgus and lateral tracking, restore rectus femoris/ITB extensibility, and support weight management to lower joint load | Q13: Patellar taping and kinesiotaping as conditionally recommended symptomatic adjuncts; footwear review; gait aid for offloading in selected cases | R13: If stalled: NMES for marked quadriceps inhibition, TENS/laser/PEMF as low-risk symptomatic adjuncts while continuing to load. Injections and surgical opinion only after well-delivered conservative care | S13: KOOS; KOOS-PF; 30-second sit-to-stand; 40 m walk test | T13: Sit-to-stand repetitions; stair pain NRS; quadriceps LSI; walking tolerance | U13: 12 weeks for meaningful change; ongoing self-management | V13: Persistent disabling symptoms after well-delivered conservative care -> orthopaedic opinion | W13: OARSI 2019; ACR/AF 2019; NICE NG226 2022
A14: Posterior | B14: Any; typically dashboard trauma or fall onto flexed knee | C14: Posterior instability | D14: 20-40 | E14: Sudden | F14: Male | G14: PCL Injury | H14: Did the knee hit the dashboard or bend backward? | I14: Posterior drawer + MRI | J14: Posteriorly directed force on the proximal tibia with the knee flexed (dashboard injury, fall onto flexed knee with plantarflexed foot); quadriceps weakness removes the dynamic anterior restraint, and hamstring dominance increases posterior tibial translation and shear | K14: Nociceptive - traumatic ligamentous | L14: Posterior - cruciate; grade and screen for multi-ligament involvement | M14: Screen: multi-ligament injury and neurovascular compromise | N14: Quadriceps-focused rehab; most isolated PCL injuries managed non-surgically. Grade III or multi-ligament -> surgical opinion | O14: Stage 1-3. Early: effusion control, quadriceps activation (isometric, NMES), protected range, avoid isolated hamstring loading which increases posterior tibial translation. Progress quadriceps-dominant isotonic loading -> neuromuscular control -> sport-specific | P14: Restore the dynamic anterior restraint: prioritise quadriceps strength, avoid open-chain hamstring curls early, retrain deceleration and landing with a knee-forward but controlled strategy, correct posterior tibial sag positioning in sitting and sleeping, rebuild calf and gluteal capacity | Q14: PCL-specific brace with tibial support in early phase; avoid unsupported gravity sag positions | R14: Grade III, multi-ligament or persistent instability -> PCL reconstruction (protection approximately 6-8 weeks; see Post-Surgical Protection sheet, category 1) | S14: IKDC; Lysholm; Tegner; quadriceps LSI | T14: Posterior sag; quadriceps LSI; hop symmetry; single-leg control | U14: 12 weeks core rehabilitation; 4-6 months to sport (non-operative); 6-9 months post reconstruction | V14: Grade III laxity, multi-ligament pattern, or persistent functional instability | W14: Manual Module 10 (#19); Post-surgical protection guide (category 1)
... A43: Central | B43: Any; acute overnight onset | C43: Red hot swollen joint | D43: 40+ | E43: Sudden | F43: Male | G43: Gout/Pseudogout | H43: Did the knee become suddenly red, hot, and swollen overnight? | I43: Joint aspiration | J43: Not biomechanical — metabolic crystal deposition (monosodium urate in gout, calcium pyrophosphate in pseudogout) triggering acute synovitis. Mechanical relevance is secondary: effusion-driven quadriceps inhibition and, with repeated attacks, cartilage damage and reduced joint load tolerance | K43: Inflammatory - crystal-induced | L43: Central - metabolic crystal arthropathy; exclude sepsis | M43: YES - an acute hot swollen knee must be screened for septic arthritis before assuming crystal disease | N43: Medical management of the acute attack (refer for diagnosis and pharmacological treatment). Physiotherapy: offload during the attack, then graded return to loading; address metabolic and whole-person contributors between attacks | O43: No loading through an acutely inflamed joint. Between attacks: graded quadriceps and hip strengthening, aerobic exercise and neuromuscular training as for a degenerative knee | P43: Between attacks, rebuild what the effusion took away: reverse quadriceps inhibition, restore range and shock absorption, and support metabolic co-management (weight, diet, medical review) since repeated attacks reduce joint load tolerance and cause cartilage damage | Q43: Offloading and gait aid during an attack; cryotherapy for symptom relief | R43: Medical pharmacological management (acute and prophylactic). Joint aspiration is both diagnostic and therapeutic | S43: KOOS between attacks; attack frequency; NRS | T43: Effusion; range; quadriceps LSI; walking tolerance between attacks | U43: Attack settles in days to weeks with medical management; capacity rebuild over 6-12 weeks | V43: Acute hot swollen knee -> urgent medical review to exclude sepsis and confirm crystal disease | W43: Manual Module 4 red flags; Module 10 (#24)

Sheet Rx Generator
A1: PRESCRIPTION GENERATOR
A2: Select a diagnosis in the yellow cell. Every field below is pulled live from the Master Matrix.
A4: SELECT DIAGNOSIS → | B4: Bakers Cyst
A6: Region / site of pain | B6: =IFERROR(INDEX('Master Matrix'!A$4:A$43,MATCH($B$4,'Master Matrix'!$G$4:$G$43,0)),"") -> Posterior
A7: Typical activity level | B7: =IFERROR(INDEX('Master Matrix'!B$4:B$43,MATCH($B$4,'Master Matrix'!$G$4:$G$43,0)),"") -> Any; usually secondary to intra-articular pathology
A8: Signs & symptoms | B8: =IFERROR(INDEX('Master Matrix'!C$4:C$43,MATCH($B$4,'Master Matrix'!$G$4:$G$43,0)),"") -> Swelling behind knee
A9: Typical age range | B9: =IFERROR(INDEX('Master Matrix'!D$4:D$43,MATCH($B$4,'Master Matrix'!$G$4:$G$43,0)),"") -> 35-70
A10: Onset | B10: =IFERROR(INDEX('Master Matrix'!E$4:E$43,MATCH($B$4,'Master Matrix'!$G$4:$G$43,0)),"") -> Slow
A11: Sex predominance | B11: =IFERROR(INDEX('Master Matrix'!F$4:F$43,MATCH($B$4,'Master Matrix'!$G$4:$G$43,0)),"") -> Female
A12: Discriminating question | B12: =IFERROR(INDEX('Master Matrix'!H$4:H$43,MATCH($B$4,'Master Matrix'!$G$4:$G$43,0)),"") -> Do you feel fullness or swelling behind the knee?
A13: Confirmatory test / imaging | B13: =IFERROR(INDEX('Master Matrix'!I$4:I$43,MATCH($B$4,'Master Matrix'!$G$4:$G$43,0)),"") -> Ultrasound/MRI
A14: Underlying biomechanical cause | B14: =IFERROR(INDEX('Master Matrix'!J$4:J$43,MATCH($B$4,'Master Matrix'!$G$4:$G$43,0)),"") -> Secondary to intra-articular pathology (meniscal tear, osteoarthritis, synovitis) — persistent effusion forced through a one-way valve into the gastrocnemius-semimembranosus bursa; underlying quadriceps weakness, medial compartment overload and poor joint load absorption
A15: Pain mechanism | B15: =IFERROR(INDEX('Master Matrix'!K$4:K$43,MATCH($B$4,'Master Matrix'!$G$4:$G$43,0)),"") -> Nociceptive - secondary to effusion and underlying joint pathology
A16: Diagnostic cluster / classification | B16: =IFERROR(INDEX('Master Matrix'!L$4:L$43,MATCH($B$4,'Master Matrix'!$G$4:$G$43,0)),"") -> Posterior - secondary/reactive
A17: RED FLAG STATUS | B17: =IFERROR(INDEX('Master Matrix'!M$4:M$43,MATCH($B$4,'Master Matrix'!$G$4:$G$43,0)),"") -> Screen: exclude DVT (calf swelling, warmth, tenderness, risk factors)
A18: MANAGEMENT EMPHASIS | B18: =IFERROR(INDEX('Master Matrix'!N$4:N$43,MATCH($B$4,'Master Matrix'!$G$4:$G$43,0)),"") -> Treat the underlying joint pathology; reassure; aspirate if symptomatic
A19: Loading stage & entry dose | B19: =IFERROR(INDEX('Master Matrix'!O$4:O$43,MATCH($B$4,'Master Matrix'!$G$4:$G$43,0)),"") -> Load per the primary diagnosis (usually OA or meniscal pathology). Quadriceps and hip strengthening plus aerobic and neuromuscular training as for knee OA
A20: BIOMECHANICAL CORRECTIONS & KINETIC CHAIN | B20: =IFERROR(INDEX('Master Matrix'!P$4:P$43,MATCH($B$4,'Master Matrix'!$G$4:$G$43,0)),"") -> Reduce the effusion driver: build quadriceps capacity to restore shock absorption, address medial compartment overload and varus mechanics, correct gait quality, support weight management where relevant, and modify the loads that keep re-provoking the effusion
A21: Manual therapy, taping, bracing & orthoses | B21: =IFERROR(INDEX('Master Matrix'!Q$4:Q$43,MATCH($B$4,'Master Matrix'!$G$4:$G$43,0)),"") -> Compression, effusion-control measures; treat the source pathology rather than the cyst
A22: Advanced / adjunct options if stalled | B22: =IFERROR(INDEX('Master Matrix'!R$4:R$43,MATCH($B$4,'Master Matrix'!$G$4:$G$43,0)),"") -> Aspiration for a large symptomatic cyst; treat the intra-articular cause. Rupture presents like DVT - refer for imaging
A23: Outcome measures | B23: =IFERROR(INDEX('Master Matrix'!S$4:S$43,MATCH($B$4,'Master Matrix'!$G$4:$G$43,0)),"") -> KOOS; NRS; effusion grade (sweep test)
A24: Re-testable markers | B24: =IFERROR(INDEX('Master Matrix'!T$4:T$43,MATCH($B$4,'Master Matrix'!$G$4:$G$43,0)),"") -> Effusion grade; posterior fullness; knee flexion range; quadriceps LSI
A25: Expected timeline | B25: =IFERROR(INDEX('Master Matrix'!U$4:U$43,MATCH($B$4,'Master Matrix'!$G$4:$G$43,0)),"") -> Follows the primary pathology - typically 12 weeks
A26: Referral / surgical trigger | B26: =IFERROR(INDEX('Master Matrix'!V$4:V$43,MATCH($B$4,'Master Matrix'!$G$4:$G$43,0)),"") -> Suspected DVT, or a rapidly enlarging or ruptured cyst
A27: Evidence anchor | B27: =IFERROR(INDEX('Master Matrix'!W$4:W$43,MATCH($B$4,'Master Matrix'!$G$4:$G$43,0)),"") -> Manual Module 10 (#18)
A29: NOTES
A30: • Green text is pulled from the Master Matrix — edit the matrix, not this sheet.
A31: • Print this sheet (fit to one page wide) to drop a management plan straight into the patient file.
A32: • Cross-check post-operative cases against the Post-Surgical Guide sheet and the operating surgeon's protocol.

Sheet Assessment Roadmap
A1: FIVE-GATE ASSESSMENT ROADMAP
A2: Work top to bottom. Each gate narrows the differential before the next one opens.
A3: Gate | B3: Purpose | C3: What You Assess | D3: Findings That Matter | E3: Decision Rule
A4: GATE 1 | B4: Screen for serious pathology | C4: Ottawa Knee Rule; septic knee; DVT; tumour; inflammatory disease | D4: Age >=55; isolated patellar tenderness; fibular head tenderness; unable to flex to 90 degrees; unable to weight-bear 4 steps. Hot swollen knee + fever + unable to weight-bear. Calf swelling/warmth with risk factors. Constant night pain, weight loss, cancer history. Morning stiffness >30 min, polyarticular, systemic features | E4: Any positive -> investigate or refer BEFORE local treatment
A5: GATE 2 | B5: Traumatic or overuse? | C5: Mechanism; audible pop; timing of swelling | D5: Pop + immediate (within hours) haemarthrosis + giving-way = ACL until proven otherwise. Dashboard or fall on flexed knee = PCL. Valgus blow = MCL. Delayed effusion = meniscus or synovitis. No swelling = many PFP and tendon presentations | E5: Traumatic pivot + immediate effusion -> prioritise ligament and osteochondral screen
A6: GATE 3 | B6: Localise the region and the generator | C6: Anterior / Medial / Lateral / Posterior / Intra-articular; palpation map + provocation | D6: Anterior: PFJ, patellar and quadriceps tendon, fat pad, tibial tubercle. Medial: medial meniscus, MCL, medial OA, pes anserine. Lateral: lateral meniscus, ITB, LCL/PLC, lateral OA. Posterior: Baker's cyst, hamstring/gastrocnemius origin, PCL, posterior horn. Intra-articular: cruciates, effusion, osteochondral lesion, synovitis | E6: Map pain to region -> structure -> mechanism
A7: GATE 4 | B7: Cluster to a working diagnosis | C7: History + palpation + special-test cluster | D7: Cluster 1 PFP: insidious anterior pain on squatting, stairs, prolonged sitting; no true locking; quadriceps/hip deficits and dynamic valgus. Cluster 2 ACL: pivot mechanism, pop, immediate haemarthrosis, giving-way, Lachman/pivot-shift positive. Cluster 3 Meniscus: twist or degenerative onset, joint-line tenderness, delayed effusion, catching/locking, McMurray/Thessaly positive | E7: Clustering beats any single test - composite examination outperforms individual tests
A8: GATE 5 | B8: Quantify impairments and capacity | C8: Effusion; ROM; quadriceps and hip capacity; single-leg control; hop symmetry | D8: Sweep/brush test and patellar tap; active and passive flexion-extension with end-feel and extension lag; single-leg squat and step-down quality; strength testing with limb symmetry index; single, triple, crossover and timed hop battery | E8: These become the baseline re-testable markers that drive the plan and, for athletes, return-to-sport testing
A10: DIAGNOSTIC ALGORITHM — NARRATIVE FLOW
A11: • Knee pain → red flags or Ottawa positive? YES: image or refer. NO ↓
A12: • Traumatic with immediate effusion? YES: assess ACL (Lachman, pivot-shift), PCL, osteochondral lesion, patellar dislocation. NO ↓
A13: • ANTERIOR → squat/stairs/sitting pain = patellofemoral pain · localised inferior-pole jump pain = patellar tendinopathy · superior pole = quadriceps tendinopathy · adolescent tubercle pain = Osgood-Schlatter
A14: • MEDIAL → joint line + McMurray positive = medial meniscus · valgus laxity = MCL · older adult with load-related pain and stiffness = medial compartment OA · below joint line = pes anserine
A15: • LATERAL → runner with lateral epicondyle pain = ITB syndrome · joint line = lateral meniscus · varus or rotatory laxity = LCL/PLC
A16: • POSTERIOR → fullness = Baker's cyst (exclude DVT) · posterior sag = PCL · deep flexion pain = posterior horn meniscus
A17: • Then confirm with the impairment and capacity profile, set baseline markers, and enter the Phased Programme.
A19: CLINICAL PEARL
A20: • Convert every diagnosis into two or three re-testable markers BEFORE you treat.
A21: • If those markers do not improve over 4-6 weeks of appropriate loading, revisit the diagnosis rather than adding modalities.

Sheet Subjective Exam
A1: SUBJECTIVE EXAMINATION TEMPLATE
A2: Yellow column is the input column. A structured history alone points to the diagnosis in most knee presentations.
A3: Domain | B3: What to Ask | C3: Why It Matters | D3: Findings (fill in)
A4: Demographics & context | B4: Age; occupation; sport and level; training week; dominant side | C4: Sets the pre-test probability — several conditions are age- and sport-specific | D4: e.g. 22 y recreational runner, 40 km/week, increased mileage 3 weeks ago
A5: Onset & mechanism | B5: Traumatic (pivot, valgus/varus blow, hyperextension, direct impact) or insidious/overuse? Was there a pop? | C5: A pop plus immediate swelling suggests ACL or osteochondral injury
A6: Swelling pattern | B6: Immediate (within hours) or delayed (next day) or none? | C6: Immediate haemarthrosis = ACL, fracture, patellar dislocation. Delayed = meniscus or synovitis
A7: Mechanical symptoms | B7: True locking, catching or giving-way — or pseudo-locking from pain inhibition? | C7: True locking points to meniscus, loose body or instability
A8: Location | B8: Anterior / medial / lateral / posterior / diffuse — point with one finger | C8: Maps pain to region, then structure, then mechanism
A9: Load behaviour | B9: Which movements bring it on? Squats, stairs, prolonged sitting, jumping, running, twisting? | C9: Anterior with squats/stairs/sitting = PFP. Inferior pole with jumping = patellar tendon. Joint line = meniscus or OA
A10: Aggravating & easing | B10: 24-hour pattern; irritability; what settles it and how quickly | C10: Irritability sets the starting dose
A11: Morning stiffness | B11: How long does it last? | C11: <30 min suggests OA; >30 min with polyarticular features suggests inflammatory arthropathy
A12: Load change | B12: Recent change in training volume, intensity, surface, footwear or body weight | C12: Almost every knee presentation is load exceeding capacity
A13: Prior history | B13: Previous injury, surgery, instability episodes, and response to previous treatment | C13: Prior injury changes joint mechanics and raises OA risk
A14: RED FLAG SCREEN | B14: Fever or systemic illness? Unable to weight-bear four steps? Constant or night pain? Unexplained weight loss? Cancer history? Calf swelling and warmth? Prolonged polyarticular morning stiffness? | C14: Gate 1 — any positive means investigate or refer before local treatment
A15: Whole-person screen | B15: Body-mass trajectory; metabolic health (diabetes, dyslipidaemia); inflammatory conditions; activity level; sleep; psychosocial load | C15: These reduce tissue capacity, slow healing and change prognosis
A16: Beliefs & goals | B16: What do you think is wrong? What are you afraid of? What do you want to get back to? | C16: Fear-avoidance and low self-efficacy predict poorer outcomes; goals drive adherence
A17: Patient-reported outcome | B17: Which PROM will you use as a baseline? (see Outcome Measures sheet) | C17: Baseline PROM plus two or three physical markers is the minimum dataset
A19: HOW TO FILL THIS SHEET
A20: • Row 4 shows an example entry in grey — overwrite it. All other yellow cells are blank and ready to fill.
A21: • Three questions triage most knee pain fast: "Was there a specific injury — and did it swell straight away?", "Does it lock, catch or give way?", and "What movements bring it on?"

Sheet Objective Exam
A1: PHYSICAL EXAMINATION TEMPLATE
A2: Yellow columns are input columns. These entries become your baseline re-testable markers.
A3: Section | B3: Item | C3: How to Test / What to Look For | D3: Involved (fill in) | E3: Uninvolved (fill in) | F3: Interpretation
A4: Observation | B4: Standing alignment | C4: Genu varum / valgum / recurvatum; patellar position; foot posture and navicular drop | D4: e.g. mild valgus | E4: neutral | F4: Frontal-plane alignment concentrates compartment load
A5: Observation | B5: Effusion | C5: Sweep/brush test and patellar tap | F5: Grade 0 to 3+. Effusion drives arthrogenic quadriceps inhibition
A6: Observation | B6: Muscle bulk / VMO | C6: Thigh girth and symmetry; VMO wasting; surgical scars | F6: Wasting confirms chronicity and inhibition
A7: Observation | B7: Gait | C7: Antalgia; varus or valgus thrust; stiff-knee pattern | F7: Varus thrust is a strong medial OA progression marker
A8: Palpation | B8: Inferior patellar pole / patellar tendon | C8: Localised tenderness | F8: Patellar tendinopathy
A9: Palpation | B9: Superior pole / quadriceps tendon | C9: Localised tenderness | F9: Quadriceps tendinopathy
A10: Palpation | B10: Medial joint line | C10: Localised tenderness | F10: Medial meniscus or medial compartment OA
A11: Palpation | B11: Lateral joint line | C11: Localised tenderness | F11: Lateral meniscus or lateral compartment OA
A12: Palpation | B12: MCL / LCL | C12: Tenderness along the ligament | F12: Collateral ligament sprain
A13: Palpation | B13: Pes anserine (4-5 cm below medial joint line) | C13: Localised tenderness | F13: Pes anserine bursitis or tendinopathy
A14: Palpation | B14: Lateral femoral epicondyle / ITB | C14: Tenderness at approximately 30 degrees flexion | F14: Iliotibial band syndrome
A15: Palpation | B15: Tibial tubercle | C15: Tenderness and prominence (adolescent) | F15: Osgood-Schlatter
A16: Palpation | B16: Popliteal fossa | C16: Fullness or mass | F16: Baker's cyst — exclude DVT
... A38: Neurovascular | B38: Distal pulses, sensation, myotomes | C38: Screen; add lumbar and hip screen if the pattern is atypical | F38: Always screen hip and spine in atypical knee pain
A40: HOW TO FILL THIS SHEET
A41: • Row 4 shows an example entry in grey — overwrite it.
A42: • Always quantify quadriceps capacity and single-leg control at baseline. They are the most treatment-relevant impairments across PFP, tendinopathy, OA and post-injury knees, and they double as objective re-assessment markers.
A43: • Transfer the strength and hop figures into the Progress Tracker sheet, which calculates limb symmetry automatically.

Sheet Special Tests
A1: SPECIAL TESTS
A2: No single knee test is definitive. Diagnostic confidence comes from clustering — composite examination outperforms any individual test.
A3: Category | B3: Test | C3: Target Structure | D3: Positive Finding | E3: Clinical Note
A4: Ligament | B4: Lachman (20-30 degrees flexion) | C4: ACL | D4: Increased anterior translation with a soft end-feel | E4: Most sensitive and accurate ACL test; assess end-feel
A5: Ligament | B5: Anterior drawer | C5: ACL | D5: Increased anterior tibial translation at 90 degrees | E5: Less sensitive than Lachman; hamstring guarding limits it
A6: Ligament | B6: Pivot-shift | C6: ACL (rotatory) | D6: Reduction clunk on flexion under valgus and internal rotation | E6: Most specific ACL test; reproduces rotatory instability
A7: Ligament | B7: Posterior drawer / sag sign | C7: PCL | D7: Posterior tibial translation or visible sag | E7: Compare tibial step-off with the uninvolved side
A8: Ligament | B8: Valgus stress (0 and 30 degrees) | C8: MCL | D8: Laxity or pain at 30 degrees | E8: Laxity at 30 degrees = MCL; laxity at 0 degrees suggests cruciate involvement
A9: Ligament | B9: Varus stress (0 and 30 degrees) | C9: LCL / PLC | D9: Laxity or pain at 30 degrees | E9: Assess the posterolateral corner; rarely an isolated injury
A10: Ligament | B10: Dial test | C10: Posterolateral corner | D10: Asymmetric external rotation at 30 vs 90 degrees | E10: >10 degrees asymmetry at 30 degrees only = isolated PLC; at both = PLC + PCL
A11: Meniscus | B11: Joint-line tenderness | C11: Meniscus | D11: Localised joint-line pain | E11: Sensitive but non-specific - always cluster it
A12: Meniscus | B12: McMurray | C12: Meniscus | D12: Click or pain on rotation under load | E12: Specific when a true click is reproduced with pain
A13: Meniscus | B13: Thessaly (20 degrees) | C13: Meniscus | D13: Joint-line discomfort or locking on weight-bearing rotation | E13: Useful weight-bearing provocation
A14: Meniscus | B14: Apley grind | C14: Meniscus vs ligament | D14: Pain on compression plus rotation | E14: Distraction pain suggests ligament rather than meniscus
... A23: Screening | B23: Ottawa Knee Rule | C23: Fracture screen | D23: Any one of the five criteria positive | E23: Age >=55, isolated patellar tenderness, fibular head tenderness, unable to flex to 90 degrees, unable to weight-bear 4 steps

Sheet Diagnostic Clusters
A1: DIAGNOSTIC CLUSTERS & ONE-LINE DIFFERENTIATORS
A2: Pattern recognition: combine history, palpation and provocation into a recognisable cluster.
A3: Cluster | B3: Feature 1 | C3: Feature 2 | D3: Feature 3 | E3: Working Diagnosis
A4: CLUSTER 1 | B4: Insidious anterior or retropatellar pain reproduced by squatting | C4: Pain with stairs, prolonged sitting (the "theatre sign"), running and jumping | D4: No true locking; often quadriceps and hip deficits with dynamic valgus | E4: Patellofemoral pain
A5: CLUSTER 2 | B5: Non-contact pivot or deceleration injury with an audible pop | C5: Immediate (within hours) large effusion / haemarthrosis | D5: Giving-way; positive Lachman and/or pivot-shift | E5: ACL rupture
A6: CLUSTER 3 | B6: Twisting mechanism (traumatic) or insidious onset (degenerative, older adults) | C6: Joint-line tenderness, delayed effusion, catching or locking | D6: Positive McMurray or Thessaly; pain in deep flexion and rotation | E6: Meniscal tear
A8: THE ONE-LINE DIFFERENTIATORS
A9: • Anterior pain with squats, stairs and sitting = patellofemoral pain
A10: • Localised inferior-pole jump pain = patellar tendinopathy
A11: • Joint-line pain with catching or locking = meniscal tear
A12: • Pivot injury + immediate effusion + giving-way = ACL until proven otherwise
A13: • Older adult with load-related pain, stiffness and crepitus = osteoarthritis
A14: • Runner with lateral epicondyle pain at approximately 30 degrees = ITB syndrome
A15: • Acute hot swollen knee with systemic upset = exclude septic arthritis urgently
A17: Classification System | B17: Subgroup / Stage | C17: What It Tells You | D17: Loading Implication
A18: PFP impairment subgroups (JOSPT 2019) | B18: Overuse / overload without other impairment | C18: Load exceeded capacity with no clear deficit | D18: Load-management focus
A19: PFP impairment subgroups (JOSPT 2019) | B19: Muscle performance deficits | C19: Hip and quadriceps weakness dominate | D19: Hip and quadriceps strengthening
A20: PFP impairment subgroups (JOSPT 2019) | B20: Movement coordination deficits | C20: Dynamic valgus on single-leg tasks | D20: Gait and movement retraining
A21: PFP impairment subgroups (JOSPT 2019) | B21: Mobility impairments | C21: Restricted quadriceps, hamstrings, ITB, gastrocnemius or foot | D21: Address the restricted structures
A22: Tendinopathy continuum (Cook & Purdam) | B22: Reactive | C22: Acute overload; potentially reversible | D22: Reduce peak load; isometrics for analgesia; relative rest — not complete rest
A23: Tendinopathy continuum (Cook & Purdam) | B23: Dysrepair | C23: Failed healing; matrix disorganisation | D23: Progressive isotonic / heavy slow resistance; address capacity deficits
A24: Tendinopathy continuum (Cook & Purdam) | B24: Degenerative | C24: Disorganised matrix; poor reversibility | D24: Heavy slow resistance; build capacity around the pathology; consider ESWT adjunct
A25: Load-based reasoning | B25: Tensile-load pain (tendon) | C25: Provoked by energy-storage tasks (jump, hop, decline squat) | D25: Responds to progressive loading
A26: Load-based reasoning | B26: Compressive-load pain (fat pad, PFJ in deep flexion) | C26: Provoked by deep flexion or hyperextension | D26: Modify the provocative range early
A27: Load-based reasoning | B27: Articular / impact overload (OA, osteochondral) | C27: Provoked by weight-bearing and impact | D27: Graded loading and symptom-guided modification, not avoidance
A28: Pain mechanism | B28: Nociceptive (mechanical / load-related) | C28: Clear load-pain relationship, localised, mechanically consistent | D28: The majority of knee pain — responds to load management
... A30: Pain mechanism | B30: Nociplastic / centrally sensitised | C30: Disproportionate, spreading, persistent; poor load-pain correlation | D30: Pain education and graded exposure

Sheet Imaging Guide
A1: IMAGING GUIDE
A2: Most knee pain is a clinical diagnosis. Image to answer a specific question — not to confirm an obvious one.
A3: Modality | B3: When to Request | C3: What It Answers | D3: Interpretation Caution
A4: Weight-bearing radiograph (including flexed PA/Rosenberg and skyline) | B4: Suspected OA; fracture screen; alignment; patellar height and tilt; loose bodies | C4: Joint-space narrowing, osteophytes, alignment, patellofemoral position | D4: Radiographic OA correlates poorly with symptoms - treat the patient, not the film
A5: Ultrasound | B5: Patellar and quadriceps tendon, bursae, effusion; guiding tendon-targeted therapy and injections | C5: Tendon thickening, hypoechoic change, neovascularity on Doppler, bursal distension | D5: Excellent dynamic assessment but operator-dependent
A6: MRI | B6: Cruciate ligaments, menisci, cartilage, osteochondral lesions, bone-marrow oedema and stress injury | C6: Reference standard for internal derangement | D6: Reserve for surgical decision-making, diagnostic uncertainty or red flags
A7: Nerve conduction studies | B7: Suspected peroneal nerve entrapment with a motor or sensory deficit | C7: Conduction block or slowing at the fibular neck | D7: Indicated where deficit is progressive or the level is unclear
A8: Joint aspiration | B8: Acute hot swollen knee; suspected sepsis or crystal arthropathy | C8: Cell count, Gram stain, culture, crystal analysis | D8: URGENT where sepsis is suspected - do not delay for imaging
A9: Blood tests (CRP, ESR, WCC, urate, rheumatoid serology) | B9: Suspected inflammatory, infective or crystal disease | C9: Inflammatory markers and disease-specific serology | D9: Refer for medical interpretation and management
A11: WHEN TO IMAGE
A12: • Ottawa Knee Rule positive (fracture screen) or acute significant trauma
A13: • Suspected surgical pathology (ACL/PCL, displaced or locked meniscus, osteochondral lesion)
A14: • Red flags for infection, tumour or inflammatory disease
A15: • Mechanical locking, or failure to respond to appropriate loaded rehabilitation
A17: RED FLAG — IMAGING INTERPRETATION
A18: • Structural findings are extremely common in pain-free knees — degenerative meniscal tears, cartilage change and tendon abnormalities appear on imaging in many asymptomatic people.
A19: • A scan finding does not by itself explain the patient's pain. Reconcile imaging with the clinical picture.
A20: • Beware over-treating incidental findings — treat the patient, not the scan.

Sheet Phased Programme
A1: PHASED MANAGEMENT PROGRAMME
A2: Progress by capacity, not by calendar. Advance only when the exit criteria are met.
A3: Phase | B3: Name | C3: Typical Timing | D3: Goal | E3: Content | F3: Markers Tracked | G3: Exit Criteria
A4: Phase 0 | B4: Screen & Protect | C4: 0 - as required | D4: Rule out serious pathology; settle effusion and irritability; protect healing tissue | E4: Red-flag screen; effusion control (compression, cryotherapy, elevation); protected range and weight bearing per diagnosis or surgeon; isometric quadriceps at low load; NMES where voluntary activation is poor; education on load-capacity model | F4: Effusion grade; extension lag; pain at rest and at night | G4: Effusion controlled; full passive extension achieved or progressing; straight leg raise without lag
A5: Phase 1 | B5: Restore & Activate | C5: Weeks 0-4 | D5: Restore range, reverse arthrogenic inhibition, re-establish basic capacity | E5: Isometric loading 5 x 30-45 s holds, 1-2x/day (analgesic in reactive tendinopathy); range-of-motion work; low-load isotonic quadriceps, hamstring, calf and gluteal work; gait normalisation; aerobic conditioning in a non-provocative mode | F5: ROM in degrees; quadriceps activation; pain NRS on the primary provocative task | G5: Full or near-full range; pain <=5/10 on loading settling within 24 h; no extension lag
A6: Phase 2 | B6: Build Capacity | C6: Weeks 4-12 | D6: Build strength and load tolerance in the knee and the whole kinetic chain | E6: Heavy slow resistance 3-4 sets, 6-12 RM, 3 s up / 3 s down, 2-3x/week; hip posterolateral strengthening; calf and trunk work; closed-chain progressions (split squat, step-up, step-down, leg press); movement retraining for dynamic valgus | F6: Quadriceps and hamstring strength LSI; single-leg squat and step-down quality; primary task NRS | G6: Strength LSI >=80%; controlled single-leg squat and step-down without valgus; pain-free daily tasks
A7: Phase 3 | B7: Energy Storage & Power | C7: Weeks 8-20 | D7: Restore spring, landing and deceleration capacity | E7: Progressive hopping, jumping and landing drills; bilateral to unilateral; deceleration and change-of-direction preparation; running progression; continued heavy strength work 2x/week | F7: Hop battery symmetry; landing quality; running volume tolerance | G7: Hop symmetry >=90%; no dynamic valgus on landing; running progression completed without symptom escalation
A8: Phase 4 | B8: Sport & Discharge | C8: Weeks 12+ (9-12 months post ACL reconstruction) | D8: Replicate sport demands and prove readiness | E8: Sport-specific drills; change of direction; contact and chaos progressions; acute:chronic workload monitoring during graded reintroduction; injury-prevention programme embedded | F8: Full return-to-sport battery; ACL-RSI; acute:chronic workload ratio | G8: Quadriceps and hamstring LSI >=90%; hop battery >=90%; no dynamic valgus; sport progression completed; psychological readiness demonstrated
A10: MASTER TREATMENT ALGORITHM
A11: • CONFIRM the diagnosis and set two or three re-testable markers (pain NRS, single-leg control, strength or hop symmetry).
A12: • EDUCATE: load-capacity model, realistic timelines, safety of loading, activity modification.
A13: • CORE CARE (0-12 weeks): progressive individualised loading plus kinetic-chain work; add taping, bracing or orthoses; weight management and education for OA.
A14: • REASSESS at 4-6 weeks against the baseline markers. Improving → progress toward energy storage and sport. Not improving → audit adherence, dosage and diagnosis.
A15: • STALLED (>8-12 weeks): add ESWT or NMES while continuing to load; re-screen red flags and whole-person factors; image if surgical pathology is suspected.
A16: • REFRACTORY or surgical indication: refer for injectable, regenerative or surgical opinion for defined indications.
A18: PRINCIPLES OF LOAD MANAGEMENT
A19: • Relative, not complete, rest — de-loaded tissue and muscle lose capacity quickly.
A20: • Acceptable symptom window: pain <=5/10 during loading that settles to baseline within 24 hours — not zero pain, especially in tendinopathy and OA.
A21: • Progress by capacity, not calendar: advance when the stage is tolerated and objective markers improve.
A22: • Treat the kinetic chain: address hip and foot contributions, not just the knee.
A23: • Reframe rehabilitation for patients: you are building a stronger, more load-tolerant knee — not resting an injury or wearing out a joint.

Sheet Exercise & Dosage
A1: EXERCISE PRESCRIPTION & DOSAGE LIBRARY
A2: Match the diagnostic label to a loading strategy, not just a name. The stage — not the diagnosis alone — sets the starting dose.
A3: Loading Stage | B3: Purpose | C3: Example Exercises | D3: Dosage | E3: Best Suited To
A4: Isometric | B4: Analgesia; reactive or irritable stage; early capacity | C4: Wall-sit, Spanish squat, isometric leg extension at 60 degrees, long-lever bridge | D4: 5 x 30-45 s holds, 1-2x/day | E4: Reactive tendinopathy, post-injury inhibition, irritable PFP
A5: Heavy slow resistance | B5: Build tendon and muscle capacity | C5: Leg press, squat, split squat, seated knee extension, Romanian deadlift, calf raise | D5: 3-4 sets, 6-12 RM, 3 s concentric / 3 s eccentric, 2-3x/week | E5: Tendinopathy (dysrepair/degenerative), PFP, OA, post-injury
A6: Eccentric | B6: Alternative capacity route; comparable to HSR | C6: Decline single-leg squat, Nordic hamstring curl, eccentric calf lowering | D6: 3 sets x 15, 2x/day or 3-4 sets 6-8 reps, 3x/week | E6: Patellar tendinopathy, hamstring tendinopathy
A7: Hip posterolateral strengthening | B7: Control dynamic valgus; unload the patellofemoral joint | C7: Side-lying abduction, banded lateral walk, hip hitch, single-leg bridge, hip thrust, clamshell | D7: 3-4 sets, 8-12 RM, 3x/week | E7: PFP, ITB syndrome, ACL rehabilitation, OA
A8: Neuromuscular / movement retraining | B8: Correct movement coordination deficits | C8: Single-leg squat, step-down, lateral step-down, running gait cues, landing mechanics drills | D8: 3-5 sets x 6-10 quality repetitions, daily to 3x/week | E8: PFP, ACL, patellar instability, OA
A9: Energy storage / plyometric | B9: Restore spring and landing capacity | C9: Pogo hops, drop jumps, bounding, single-leg hops, decelerations | D9: Progressive volume; 2x/week with 48 h between sessions | E9: Tendinopathy stage 3, ACL phase 3, return to jump sport
A10: Sport-specific | B10: Replicate the individual's demands | C10: Change-of-direction drills, sprint progressions, sport skill circuits, contact and chaos drills | D10: Replicate sport tasks; monitor acute:chronic workload ratio | E10: All athletic knees before discharge
A11: Aerobic conditioning | B11: Guideline first-line component for OA; maintain fitness during protection | C11: Cycling, pool work, cross-trainer, walking programme | D11: 150 min/week moderate intensity, or as tolerated | E11: OA (all compartments), post-surgical protection phases
A12: NMES (adjunct) | B12: Quadriceps activation where voluntary contraction is poor | C12: Superimposed on voluntary contraction, quadriceps | D12: 10-15 contractions, 3-5x/week alongside voluntary strengthening | E12: Post-surgical, post-injury inhibition, OA with marked inhibition
A14: THE GENERIC LOADING PROGRESSION
A15: • Stage 1 — Isometric loading for pain and early capacity (5 x 30-45 s holds).
A16: • Stage 2 — Heavy slow resistance / isotonic strengthening to build capacity.
A17: • Stage 3 — Energy-storage and plyometric loading (hops, jumps, decelerations).
A18: • Stage 4 — Sport or activity-specific loading replicating the individual's demands.
A19: • Isometric, eccentric and heavy slow resistance are broadly comparable for building tendon capacity — choose by patient preference, equipment and response.

Sheet Adjuncts & Advanced
A1: ADJUNCTS, ADVANCED THERAPEUTICS & REFERRAL OPTIONS
A2: These open a comfort window for loading. On their own they build no capacity.
A3: Tier | B3: Intervention | C3: Role | D3: Evidence Position | E3: Practical Note
A4: Adjunct | B4: Patellar taping (McConnell / kinesio) | C4: Short-term anterior-pain relief to enable exercise | D4: Helpful early in PFP; little lasting effect alone (JOSPT 2019) | E4: Use the comfort window to load - taping alone builds no capacity
A5: Adjunct | B5: Manual therapy | C5: Adjunct for pain and mobility | D5: Combine with exercise; not a stand-alone cure | E5: Pair every session with a loading progression
A6: Adjunct | B6: Foot orthoses | C6: Foot-driven PFP or over-pronation | D6: OTC comparable to custom for short-term PFP relief | E6: Trial OTC first; reassess at 4-6 weeks
A7: Adjunct | B7: Knee bracing / offloading | C7: Instability, or medial-compartment OA offloading | D7: Selected cases; supports activity | E7: Scaffolding during rehabilitation, not a substitute for capacity
