Workbook

Sheet Read Me
A1: LUMBAR SPINE & SACROILIAC ASSESSMENT AND MANAGEMENT PROGRAMME
A2: Screen (including the cauda equina questions) → risk-stratify → back-dominant or leg-dominant → identify the mechanism → educate → load → discharge on function.
A4: SHEET | B4: WHAT IT DOES | C4: WHEN TO USE IT | D4: FOCUS
A5: Master Matrix | B5: 38 lumbar and sacroiliac conditions on the established column structure: Region → Activity Level → Common Symptoms → Age → Onset → Predominance → Condition → High-Yield Question → Special Test + Imaging → Biomechanical Cause → Desired Activity Goal → Physiotherapy Specific Exercise, then pain mechanism, classification, red-flag status, management emphasis, loading dose, biomechanical corrections, adjuncts, advanced options, outcomes, markers, timeline and referral triggers. | C5: The core reference. Filter column A by region or column O by red-flag status. | D5: Lumbar spine and SIJ
A6: Rx Generator | B6: Pick a condition from the dropdown and the full prescription is pulled live from the Master Matrix. | C6: In clinic, or to print a plan into the patient file. | D6: Live INDEX/MATCH
A7: Assessment Roadmap | B7: The five-gate sequence, built around red flag screening at Gate 1 and the back-dominant versus leg-dominant branch at Gate 2. | C7: Every new patient, in order. | D7: Clinical reasoning
A8: Subjective Exam | B8: Fillable history template with the CAUDA EQUINA QUESTIONS, red flag screen, STarT Back stratification and psychosocial screening built in. | C8: First consultation. | D8: Fillable
A9: Objective Exam | B9: Fillable examination template: observation, movement testing, neurological examination, SIJ cluster, trunk and HIP capacity, and functional tolerance. | C9: First consultation and every re-assessment. | D9: Fillable
A10: Special Tests | B10: 31 tests grouped by category, with what a positive means and how much weight to give it — including which SIJ tests are unreliable. | C10: During the physical examination. | D10: Reference
A11: Clusters & Classification | B11: Seven diagnostic clusters, sixteen one-line differentiators, and the STarT Back, pain mechanism, directional preference, Meyerding, Laslett and inflammatory back pain frameworks. | C11: When the picture is not yet clear, and when choosing a pathway. | D11: Reference
A12: Imaging Guide | B12: When to image — and, more importantly, when NOT to. Includes the traps and the language problem. | C12: Before requesting or when reading a report. | D12: Reference
A13: Phased Programme | B13: Phase 0-4 with goals, content, markers and exit criteria, plus the master treatment sequence. | C13: Building and progressing every plan. | D13: Reference
A14: Exercise & Dosage | B14: Loading library with dose and indication — trunk and HIP strengthening, endurance, directional preference, hip hinge retraining and graded exposure. | C14: Writing the actual programme. | D14: Reference
A15: Adjuncts & Advanced | B15: Education, manual therapy, belts, injections, surgery and referral — plus an explicit AVOID list. | C15: When exercise and education alone are not enough. | D15: Reference
... A24: References | B24: Guideline and trial sources. | C24: Verifying or citing. | D24: —
A26: CRITICAL POINTS FOR THE LUMBAR SPINE & SIJ
A27: • ASK THE CAUDA EQUINA QUESTIONS OF EVERY PATIENT AND SAFETY-NET IN WRITING. Bladder function, saddle sensation, bilateral leg symptoms. It takes thirty seconds, and a delayed cauda equina diagnosis is the most consequential miss in musculoskeletal practice — for the patient above all.
A28: • THE IMAGING CONVERSATION IS A CLINICAL INTERVENTION. Degenerative change, disc bulges and herniations are present in the majority of ASYMPTOMATIC adults. Telling someone their spine is "crumbling" or "worn out" measurably increases their pain and disability. Reframing that is treatment, not reassurance.
A29: • BACK-DOMINANT VERSUS LEG-DOMINANT directs the entire pathway — different natural histories, treatments and prognoses. Establish it in the first few minutes and record the two pain scores separately.
A30: • RISK-STRATIFY WITH STarT BACK AT FIRST CONTACT. Matching treatment intensity to prognostic risk improves outcomes more than choosing the "right" exercise. Exercise TYPE matters far less than progression, adherence and the beliefs you address alongside it.
A31: • SIJ PALPATION AND MOTION TESTS ARE UNRELIABLE. The joint does not go "out" and does not need putting back. Use the LASLETT PROVOCATION CLUSTER (3 or more of 5) — it is the only validated clinical test set for this region.
A32: • ASSESS THE HIP IN EVERY LUMBAR AND SIJ PRESENTATION. A stiff or weak hip transfers load and range demand straight to the lumbar spine, and it is the most consistently overlooked contributor in this region.
A33: • A FRAGILITY FRACTURE WITHOUT A BONE HEALTH REFERRAL IS AN INCOMPLETE EPISODE OF CARE. This is the most routinely missed action in the lumbar spine.
A34: • WHAT YOU DON'T DO MATTERS AS MUCH AS WHAT YOU DO: no routine imaging, no bed rest, no opioids, no endless passive treatment, no repeated re-investigation in sensitised pain.
A35: • Yellow cells are inputs. Green text is pulled from another sheet. Do not overwrite formula cells.

Sheet Master Matrix
A1: MASTER DIAGNOSTIC & MANAGEMENT MATRIX — 38 LUMBAR & SACROILIAC CONDITIONS
A2: Columns A–L follow the established diagnostics-algorithm structure. Columns M–Y add the management programme. Crimson in column O marks a red-flag or time-sensitive presentation.
A3: Region | B3: Activity Level | C3: Common Symptoms | D3: Age Group | E3: Onset | F3: Predominance | G3: Condition | H3: High-Yield Diagnostic Question | I3: Special Test + Imaging | J3: Underlying Biomechanical Cause | K3: DESIRED ACTIVITY GOAL | L3: PHYSIOTHERAPY SPECIFIC EXERCISE | M3: Pain Mechanism | N3: Classification / Cluster | O3: Red Flag Status | P3: MANAGEMENT EMPHASIS | Q3: Loading Stage & Entry Dose | R3: BIOMECHANICAL CORRECTIONS & KINETIC CHAIN | S3: Adjuncts & Practical Measures | T3: Advanced / Surgical Options | U3: Outcome Measures | V3: Re-testable Markers | W3: Expected Timeline | X3: Referral / Surgical Trigger | Y3: Evidence Anchor
A4: Mechanical / Axial | B4: Any; the commonest cause of disability worldwide | C4: Diffuse low back pain and stiffness without leg symptoms, varying with posture and activity | D4: 25-60 | E4: Slow/Sudden | F4: Equal | G4: Non-Specific Low Back Pain | H4: Is the pain mainly in the back rather than the leg, and does it change with position and activity? | I4: Diffuse rather than focal tenderness; movement-related pain with variable directional response; NEGATIVE neurological examination; NEGATIVE straight leg raise; NO red flags. IMAGING IS NOT INDICATED - it does not improve outcomes and degenerative findings are near-universal in asymptomatic adults | J4: Multifactorial and usually not attributable to a single structure; contributing factors include reduced trunk and hip capacity, sustained postural or loading exposure exceeding tolerance, a sudden change in activity, poor sleep, psychological distress and low physical activity. THE SEARCH FOR A SINGLE STRUCTURAL CAUSE IS USUALLY UNPRODUCTIVE AND OFTEN HARMFUL | K4: Work, lift, sit and exercise normally without disabling back pain | L4: STAY ACTIVE - the single most important message; GRADED EXERCISE of the patient's preference (no exercise type is clearly superior); progressive trunk and HIP strengthening 2-3x/week; aerobic exercise 150 min/week; graded exposure to feared or avoided movements; movement variability and break scheduling; SELF-MANAGEMENT and flare planning | M4: Nociceptive; nociplastic overlay if persistent beyond 3 months | N4: Cluster 1 - Non-specific low back pain: diffuse back-dominant pain + negative neurological examination + no red flags. RISK-STRATIFY WITH STarT BACK to match treatment intensity to prognosis | O4: No | P4: EDUCATION, REASSURANCE AND STAYING ACTIVE ARE FIRST-LINE and supported by every major guideline. Avoid imaging, avoid bed rest, avoid opioids. Use STarT BACK to stratify: low risk needs reassurance and advice, high risk needs psychologically-informed physiotherapy. Exercise type matters far less than doing it | Q4: Stage 1-2 sustained. Graded exercise of the patient's choosing 2-3x/week plus aerobic activity; progress on a schedule rather than waiting for pain to settle | R4: Build capacity and vary exposure: progressive trunk and HIP strengthening, restore hip and thoracic mobility so the lumbar spine compensates less, address sustained sitting or loading exposure with break scheduling, improve general fitness and sleep, and rebuild confidence in bending and lifting | S4: Education and reassurance (the highest-value intervention); manual therapy as a short-term adjunct combined with exercise; heat; AVOID bed rest, imaging and opioids | T4: If persistent and high-impact: multidisciplinary or psychologically-informed rehabilitation. NICE and most guidelines do NOT recommend injections, fusion or disc replacement for non-specific low back pain | U4: OSWESTRY DISABILITY INDEX or Roland-Morris; NPRS; STarT Back; Patient-Specific Functional Scale | V4: ODI or RMDQ; sitting, standing and walking tolerance; FUNCTION-based markers; return to work | W4: Most acute episodes improve substantially within 6 weeks; recurrence is common so self-management is central | X4: Red flag features; progressive neurological deficit; failure to improve with active management | Y4: NICE NG59; Lancet Low Back Pain Series 2018; STarT Back stratified care
A5: Mechanical / Axial | B5: Any; often with extension-rotation loading or degenerative change | C5: Unilateral or bilateral back pain worse with extension and rotation, eased by sitting and flexion | D5: 45-70 | E5: Slow | F5: Equal | G5: Lumbar Facet (Zygapophyseal) Joint Pain | H5: Is the back pain worse when you arch backwards or stand for long, and better when you sit or bend forward? | I5: Pain worse with EXTENSION and extension-rotation; eased by flexion and sitting; paraspinal tenderness over the facet; referral to the buttock and posterior thigh but NOT below the knee; NO single test is diagnostic - REVELS CRITERIA have limited value; DIAGNOSTIC MEDIAL BRANCH BLOCKS are the reference standard. IMAGING CANNOT DIAGNOSE FACET PAIN | J5: Nociception from the zygapophyseal joint capsule and synovium under extension and rotational load; degenerative facet arthrosis, sustained extension postures, and segmental load concentration from adjacent stiffness or hip extension restriction; weak trunk and hip extensor capacity reduces segmental load sharing | K5: Stand, walk and extend the spine without back pain building | L5: FLEXION-BIASED exercise and positioning early where extension is provocative; progressive trunk and HIP extensor strengthening 2-3 sets 3x/week; HIP FLEXOR lengthening and hip extension mobility (a stiff hip forces lumbar extension); segmental motor control; graded exposure to extension and standing tolerance; aerobic exercise | M5: Nociceptive - articular | N5: Mechanical group; facet pain is over-diagnosed clinically and can only be confirmed by diagnostic blocks. Referral does NOT usually extend below the knee | O5: No | P5: Exercise, load management and graded exposure. Where extension is clearly provocative, bias toward flexion early and reintroduce extension progressively. RADIOFREQUENCY MEDIAL BRANCH NEUROTOMY after positive diagnostic blocks has moderate evidence in carefully selected patients - selection is everything | Q5: Stage 1-2. Flexion-biased work early if extension is provocative; progressive trunk and hip loading 3x/week; graded return to extension and standing | R5: Reduce lumbar extension demand: restore HIP EXTENSION range (a stiff hip drives lumbar extension in standing and walking), lengthen hip flexors, build gluteal and trunk extensor capacity, correct sustained standing and overhead postures, and address footwear and standing surfaces | S5: Manual therapy combined with exercise; heat; standing and workstation modification; anti-fatigue matting for standing work | T5: DIAGNOSTIC MEDIAL BRANCH BLOCKS; radiofrequency neurotomy in carefully selected patients with confirmed facet-mediated pain | U5: ODI; RMDQ; NPRS; standing and walking tolerance | V5: Extension tolerance; standing and walking time; ODI; hip extension range | W5: 6-12 weeks conservatively | X5: Failure after 12 weeks of correct conservative care - consider diagnostic blocks in selected patients | Y5: Lumbar facet pain diagnostic block literature; medial branch neurotomy selection criteria
A6: Mechanical / Axial | B6: Any; sustained flexion and lifting exposure | C6: Central back pain worse with sitting, bending and lifting, eased by standing and walking | D6: 30-55 | E6: Slow/Sudden | F6: Male | G6: Lumbar Discogenic Pain | H6: Is the pain worse the longer you sit, and worse bending forward, but easier walking around? | I6: CENTRAL or bilateral back-dominant pain; worse with SUSTAINED FLEXION, sitting and Valsalva; often a DIRECTIONAL PREFERENCE for extension on repeated movement testing; CENTRALISATION on repeated movements supports it; MRI shows disc change BUT DEGENERATION IS NEAR-UNIVERSAL IN ASYMPTOMATIC ADULTS - correlate cautiously | J6: Nociception from the outer annulus and vertebral endplates under compressive and flexion load; sustained flexion raises intradiscal pressure; repeated or sustained loaded flexion, poor hip hinge mechanics, reduced hip and thoracic mobility, and deconditioned trunk capacity all increase discal load | K6: Sit, drive, bend and lift through a normal day without central back pain | L6: DIRECTIONAL PREFERENCE work (usually repeated extension) where a clear preference exists, several times daily; progressive trunk and HIP strengthening 2-3x/week; HIP HINGE and lifting technique retraining; sitting and posture modification with break scheduling; graded exposure to flexion and lifting load; aerobic exercise | M6: Nociceptive - discogenic | N6: Mechanical group; a clinical construct rather than an imaging diagnosis. A clear DIRECTIONAL PREFERENCE and CENTRALISATION on repeated movement testing support it and guide treatment | O6: Screen: leg symptoms below the knee with neurological signs means RADICULOPATHY; bilateral leg symptoms with bladder or saddle change means CAUDA EQUINA | P6: Directional preference exercise where present, plus progressive loading, hip hinge retraining and postural change. EXPLAIN THE IMAGING - disc degeneration is normal ageing and visible in most asymptomatic adults, and telling a patient their disc is 'damaged' measurably worsens outcomes | Q6: Stage 1-2. Directional preference work several times daily; progressive trunk and hip loading 3x/week; graded reintroduction of flexion and lifting | R6: Reduce compressive flexion load and rebuild tolerance: restore HIP and THORACIC mobility so the lumbar spine flexes less, retrain the HIP HINGE for lifting and bending, modify sustained sitting with break scheduling, build trunk and hip capacity, and progressively re-expose to loaded flexion rather than avoiding it permanently | S6: Sitting and workstation modification; lumbar support; break scheduling; heat | T6: Persistent severe symptoms warrant reassessment; discography is contested; fusion and disc replacement are NOT recommended for non-specific discogenic back pain by most guidelines | U6: ODI; RMDQ; NPRS; Patient-Specific Functional Scale | V6: Sitting and driving tolerance; directional preference response; lifting tolerance; ODI | W6: 6-12 weeks | X6: Development of radicular or cauda equina features; refractory severe symptoms | Y6: McKenzie directional preference and centralisation literature; asymptomatic imaging prevalence
A7: Mechanical / Axial | B7: Any; often with hypermobility, post-partum, or after repeated episodes | C7: Recurrent back pain with a sense of giving way, catching, or needing to self-manipulate | D7: 25-50 | E7: Slow | F7: Female | G7: Lumbar Clinical Instability / Motor Control Impairment | H7: Does the back feel like it might give way, catch, or need cracking, and is it worse in the middle of movements rather than at the end? | I7: PAIN IN MID-RANGE rather than end-range; aberrant movement patterns on forward bending (painful arc, instability catch, Gower sign, reversal of lumbopelvic rhythm); POSITIVE PRONE INSTABILITY TEST; excessive segmental mobility on passive testing; generalised hypermobility (Beighton); imaging usually normal - flexion-extension films only if frank instability is suspected | J7: Impaired active segmental control from deficits in deep trunk muscle timing and endurance, combined with passive restraint laxity; post-partum ligamentous change, repeated injury episodes and generalised hypermobility predispose; THE PROBLEM IS CONTROL, NOT STRUCTURE, in the large majority | K7: Move, bend, lift and exercise confidently without catching or a sense of giving way | L7: MOTOR CONTROL TRAINING - segmental control retraining progressing from low-load isolated control to functional and loaded patterns; progressive trunk and HIP strengthening 2-3 sets 3x/week; endurance work (side bridge, prone bridge, bird-dog progressions); HIP HINGE and movement pattern retraining; graded exposure to loaded and end-range positions; AVOID repeated self-manipulation, which reinforces the pattern | M7: Nociceptive - mechanical with motor control impairment | N7: Cluster 2 - Clinical instability: mid-range pain + aberrant movement patterns + positive prone instability test + hypermobility. Note that MOTOR CONTROL TRAINING IS NOT SUPERIOR TO OTHER EXERCISE overall, but may suit this subgroup | O7: Screen: frank structural instability (spondylolisthesis, post-traumatic) needs imaging - this is a different entity from motor control impairment | P7: MOTOR CONTROL AND PROGRESSIVE LOADING. Start with segmental control and endurance, then progress to loaded functional patterns - the endpoint is confident loaded movement, NOT permanent bracing or avoidance. Discourage repeated self-manipulation | Q7: Stage 1-3. Low-load motor control daily; endurance and strengthening 3x/week; progressive loaded and functional patterns; graded end-range exposure | R7: Build active control where passive restraint is insufficient: deep trunk and gluteal endurance, hip hinge and movement pattern retraining, hip and thoracic mobility so the lumbar spine is not the only mobile segment, and graded loaded exposure to rebuild confidence | S7: Short-term taping or a belt for feedback in selected cases (wean it); AVOID long-term bracing and repeated self-manipulation | T7: Imaging for suspected structural instability; fusion is reserved for confirmed structural instability, not motor control impairment | U7: ODI; RMDQ; NPRS; Patient-Specific Functional Scale; Beighton score | V7: Prone instability test; aberrant movement patterns; trunk endurance tests; loaded movement confidence; ODI | W7: 12 weeks minimum for motor control and loading change | X7: Suspected structural instability; progressive neurological features | Y7: Hicks clinical prediction rule for stabilisation exercise; motor control training evidence
A8: Mechanical / Axial | B8: Any; a lifting strain, sudden unguarded movement, or sustained loading | C8: Sudden severe back pain with marked spasm and difficulty straightening up | D8: 20-50 | E8: Sudden | F8: Male | G8: Acute Lumbar Strain / Acute Back Pain Episode | H8: Did the back go suddenly with lifting or twisting, and are you now stuck bent over? | I8: Marked movement restriction with protective guarding; antalgic posture or lateral shift; NEGATIVE neurological examination; NEGATIVE straight leg raise; NO red flags; IMAGING IS NOT INDICATED. THE SPASM AND POSTURE ARE PROTECTIVE RESPONSES, NOT THE PRIMARY LESION | J8: Acute nociceptive irritation of muscular, discal or articular tissue with protective muscle guarding; a lifting strain, a sudden unguarded movement, or a sustained loading exposure exceeding tolerance; reduced baseline trunk and hip capacity and a recent change in activity lower the threshold | K8: Return to normal movement, work and activity as quickly as possible | L8: STAY ACTIVE AND AVOID BED REST - this is the core message and is strongly evidence-based; early gentle movement within tolerance; walking as the primary early activity; simple analgesia; progressive return to normal loading over days to weeks; graded exposure to bending and lifting; build trunk and hip capacity once acute pain settles | M8: Nociceptive - acute with protective guarding | N8: Mechanical group - ACUTE. The natural history is FAVOURABLE; most improve substantially within 2-6 weeks. THE MESSAGING IN THE FIRST CONSULTATION SHAPES THE TRAJECTORY | O8: Screen: apply red flag screening - cauda equina, fracture, infection, malignancy. BILATERAL leg symptoms, saddle anaesthesia or bladder change is an EMERGENCY | P8: REASSURANCE, ANALGESIA AND STAYING ACTIVE. Explain the favourable natural history explicitly. AVOID bed rest, AVOID imaging, AVOID opioids, and AVOID language implying structural damage. Manual therapy is a reasonable short-term adjunct to enable movement | Q8: Early gentle movement and walking within tolerance; progressive normal loading over days to weeks; strengthening once acute pain settles | R8: Once acute pain settles, address recurrence risk: build trunk and hip capacity, retrain the hip hinge and lifting technique, address the loading or activity change that preceded it, and rebuild confidence in bending | S8: Simple analgesia; heat; walking; manual therapy for short-term relief; AVOID bed rest and prolonged rest | T8: Rarely required. Reassess if not improving by 6 weeks or if red flags develop | U8: ODI; RMDQ; NPRS; STarT Back; return to work | V8: Movement restriction; walking tolerance; return to normal activity and work; ODI | W8: Most improve substantially within 2-6 weeks | X8: Red flag features; progressive neurological deficit; failure to improve by 6 weeks | Y8: NICE NG59; acute low back pain natural history; stay-active evidence
A9: Mechanical / Axial | B9: Any; long symptom duration, high distress, poor sleep | C9: Widespread persistent back pain with high disability, poor sleep and sensitivity to light touch | D9: 30-60 | E9: Slow | F9: Female | G9: Chronic Low Back Pain with Central Sensitisation | H9: Is the pain widespread and out of proportion to what you do, and does even light pressure hurt? | I9: Widespread, non-anatomical pain distribution; MECHANICAL HYPERALGESIA and sometimes ALLODYNIA; poor correlation between activity and symptoms; high ODI relative to objective findings; screen with the CENTRAL SENSITISATION INVENTORY; high STarT Back score; NEGATIVE neurological examination; repeated imaging is counterproductive | J9: Altered central pain processing with amplified nociception, reduced descending inhibition and cortical reorganisation; long symptom duration, poor sleep, psychological distress, catastrophising, fear-avoidance, work dissatisfaction and repeated unhelpful clinical messaging all contribute. THE PROBLEM IS NOT PRIMARILY IN THE BACK TISSUE | K9: Increase activity, function, work participation and confidence, and reduce the impact of pain on life | L9: PAIN NEUROSCIENCE EDUCATION FIRST; GRADED ACTIVITY AND GRADED EXPOSURE to feared movements, progressed on a TIME SCHEDULE rather than by pain; AEROBIC EXERCISE (well supported in sensitised states); progressive strengthening at a tolerable starting load; sleep and stress management; pacing and activity scheduling; return-to-work planning | M9: NOCIPLASTIC - the dominant mechanism, with variable nociceptive input | N9: Mechanical group - SENSITISED. Identifying this changes the approach entirely: tissue-focused treatment underperforms and repeated imaging and specialist referral are actively harmful | O9: Screen: exclude serious pathology ONCE, thoroughly, then STOP RE-INVESTIGATING. Repeated imaging reinforces the problem and worsens outcomes | P9: PAIN NEUROSCIENCE EDUCATION, GRADED EXPOSURE AND EXERCISE within a psychologically-informed framework. Set FUNCTION-BASED goals, not pain-based ones. Avoid passive treatments, repeated imaging and opioids. Multidisciplinary rehabilitation for high-impact cases | Q9: TIME-CONTINGENT, not pain-contingent. Start well within tolerance and progress on a schedule regardless of day-to-day pain; aerobic exercise most days | R9: Shift the target from tissue to function: graded exposure to feared and avoided movements (bending, lifting, sitting), aerobic conditioning, sleep and stress management, pacing, work modification and return-to-work planning | S9: Pain neuroscience education (the primary intervention); sleep hygiene; stress management; AVOID passive modalities, repeated imaging and opioids | T9: Multidisciplinary or combined physical and psychological programmes; CBT or ACT; medical review of medication, particularly opioid deprescribing | U9: ODI; RMDQ; Central Sensitisation Inventory; PCS; TSK; STarT Back; Patient-Specific Functional Scale | V9: FUNCTION-BASED markers (PSFS, activity levels, work hours) rather than pain scores; ODI; sleep quality | W9: 3-6 months; progress is measured in function, not pain reduction | X9: High distress or failure to progress - multidisciplinary pain management referral | Y9: Lancet Low Back Pain Series 2018; pain neuroscience education evidence; NICE NG59
A10: Mechanical / Axial | B10: Manual handlers, drivers, desk workers; sustained or repetitive loading | C10: Back pain related clearly to the working day, easing on days off | D10: 25-55 | E10: Slow | F10: Male | G10: Occupational / Load-Related Low Back Pain | H10: Does the back pain build through the working day and settle on days off or holidays? | I10: A clear temporal relationship to work exposure; reduced trunk and hip endurance; assessment of the ACTUAL TASK (loads, frequency, postures, vibration, duration); NEGATIVE neurological examination; imaging not indicated. WORK-RELATED DOES NOT MEAN WORK-CAUSED DAMAGE - the distinction matters for messaging | J10: Cumulative loading exposure exceeding tissue tolerance - lifting frequency and load, sustained flexion or rotation, whole-body vibration in drivers, and prolonged static sitting or standing; low trunk and hip capacity, low general fitness, job dissatisfaction and low perceived control all lower the threshold | K10: Complete a full working week without disabling back pain | L10: PROGRESSIVE TRUNK AND HIP STRENGTHENING to raise capacity 2-3 sets 3x/week; HIP HINGE and manual handling technique retraining; general aerobic fitness; graded exposure to occupational loading; MOVEMENT VARIABILITY and break scheduling; task and workplace modification; graded return-to-work planning where off work | M10: Nociceptive - cumulative loading | N10: Mechanical group; WORK MODIFICATION AND EARLY RETURN TO WORK improve outcomes. Prolonged absence is itself a risk factor for chronicity | O10: No | P10: RAISE CAPACITY AND MANAGE EXPOSURE, and keep the person at work where possible with modified duties. Early return to modified work improves outcomes compared with waiting for full recovery. Address psychosocial workplace factors, which predict outcome more strongly than physical load | Q10: Stage 1-2. Progressive strengthening 3x/week; graded occupational loading exposure; aerobic fitness | R10: Change the exposure and raise the capacity: build trunk and hip strength and endurance, retrain manual handling and the hip hinge, vary posture and schedule breaks, modify task height, load and frequency, address vibration exposure in drivers, and plan a graded return to full duties | S10: Workplace and task modification; break scheduling; graded return-to-work plan; employer liaison | T10: Occupational health referral; vocational rehabilitation for prolonged absence | U10: ODI; RMDQ; work absence days; Work Ability Index; Patient-Specific Functional Scale | V10: Work tolerance and hours; trunk and hip endurance; ODI; days absent | W10: 6-12 weeks with capacity building and work modification | X10: Prolonged work absence - vocational rehabilitation and occupational health input | Y10: Occupational low back pain guidelines; early return-to-work evidence
A11: Radicular / Neural | B11: Any; often after a lifting or flexion strain, or spontaneous | C11: Leg pain BELOW THE KNEE, worse than the back pain, with numbness and sometimes weakness | D11: 30-55 | E11: Sudden/Slow | F11: Male | G11: Lumbar Radiculopathy (Disc Herniation) | H11: Is the LEG pain worse than the back pain, and does it travel below the knee? | I11: LEG-DOMINANT pain below the knee; POSITIVE STRAIGHT LEG RAISE (or slump) reproducing leg symptoms; DERMATOMAL sensory change and MYOTOMAL weakness (L4 knee extension and ankle dorsiflexion, L5 great toe extension, S1 plantarflexion and ankle reflex); reflex change; CROSSED SLR is highly specific; MRI only if surgery is considered or the deficit is progressive | J11: Compression and chemical irritation of a lumbar nerve root by a herniated disc, most commonly L4-5 and L5-S1; sustained flexion and loaded lifting increase discal pressure; THE NATURAL HISTORY IS FAVOURABLE - most herniations resorb and most patients improve without surgery | K11: Resolve the leg pain, restore leg strength, and return to work and normal activity | L11: STAY ACTIVE within tolerance; NEURAL MOBILISATION (glides rather than tensioners early); DIRECTIONAL PREFERENCE work where CENTRALISATION occurs - this is a strong positive prognostic sign; progressive trunk and HIP strengthening as symptoms allow; strengthening of weak myotomes; graded return to sitting, bending, lifting and work; aerobic exercise | M11: Neuropathic with nociceptive components | N11: Cluster 3 - Lumbar radiculopathy: leg-dominant pain below the knee + positive SLR or slump + dermatomal, myotomal or reflex change. CENTRALISATION on repeated movements is a strong positive prognostic indicator | O11: YES - PROGRESSIVE motor weakness, BILATERAL leg symptoms, SADDLE ANAESTHESIA or BLADDER/BOWEL CHANGE means CAUDA EQUINA - a surgical emergency | P11: CONSERVATIVE MANAGEMENT IS FIRST-LINE and the natural history is favourable - most improve over 6-12 weeks and disc herniations commonly resorb. Education about this natural history is itself therapeutic. Surgery gives faster leg pain relief but similar outcomes at 1-2 years, so it is for progressive deficit, refractory severe pain or patient preference after informed discussion | Q11: Stage 1-2. Neural mobilisation and directional preference work within tolerance; progressive loading as symptoms centralise; graded return to functional loading | R11: Address the whole chain and rebuild tolerance: restore HIP and THORACIC mobility, retrain the hip hinge for bending and lifting, build trunk and hip capacity, modify sustained sitting and loaded flexion early, and grade re-exposure rather than permanent avoidance | S11: Simple analgesia and neuropathic agents per medical review; activity modification; AVOID bed rest | T11: Guided transforaminal or epidural injection for severe refractory radicular pain; MICRODISCECTOMY for progressive deficit, cauda equina, or refractory severe pain - faster relief but equivalent medium-term outcomes | U11: ODI; RMDQ; separate NPRS for LEG and BACK pain; Patient-Specific Functional Scale | V11: DISTAL EXTENT OF LEG PAIN (centralisation is the key marker); SLR angle; myotomal strength; ODI; sitting and walking tolerance | W11: Most improve substantially within 6-12 weeks; some take up to 6 months | X11: PROGRESSIVE motor weakness; any cauda equina feature (EMERGENCY); refractory severe pain | Y11: Lumbar disc herniation natural history and resorption literature; SPORT trial; centralisation prognostic evidence
A12: Radicular / Neural | B12: Older adults; walking-limited | C12: Leg pain, heaviness and weakness on WALKING, relieved by SITTING OR BENDING FORWARD | D12: 60+ | E12: Slow | F12: Equal | G12: Lumbar Spinal Stenosis (Neurogenic Claudication) | H12: Does the leg pain come on walking and go when you SIT DOWN or lean forward on a trolley? | I12: SYMPTOMS RELIEVED BY FLEXION - sitting, leaning on a trolley, cycling - and provoked by extension and walking; better walking uphill than downhill; BILATERAL leg symptoms common; NEGATIVE or mildly positive SLR; PEDAL PULSES PRESENT (distinguishing from vascular claudication); MRI confirms canal narrowing. THE RELIEVING FACTOR IS THE DISCRIMINATOR | J12: Central canal narrowing from disc bulging, ligamentum flavum hypertrophy and facet arthrosis, dynamically worsened in EXTENSION which further reduces canal volume and compresses the cauda equina; flexion increases canal volume, which is why sitting and leaning relieve it | K12: Increase pain-free walking distance and maintain independence and function | L12: FLEXION-BIASED exercise and positioning; progressive walking programme using a FLEXED strategy (trolley, walking poles, inclined treadmill) to build distance; CYCLING as an aerobic alternative (tolerated because it is flexed); progressive trunk, HIP and lower limb strengthening 2-3x/week; balance and falls prevention; graded activity pacing | M12: Neuropathic with vascular-like claudication pattern | N12: Cluster 4 - Neurogenic claudication: leg symptoms on walking + RELIEVED BY FLEXION/SITTING + better uphill than downhill + pedal pulses present. DISTINGUISH FROM VASCULAR CLAUDICATION, which is relieved by STANDING STILL | O12: YES - BILATERAL leg symptoms with saddle anaesthesia or bladder change means CAUDA EQUINA. Also exclude VASCULAR claudication by checking pedal pulses and ABPI | P12: CONSERVATIVE MANAGEMENT FIRST: flexion-based exercise, a progressive walking programme with a flexed strategy, strengthening and aerobic conditioning. Surgery (decompression) gives better outcomes than conservative care for moderate to severe symptoms in appropriately selected patients, particularly for walking distance | Q12: Stage 1-2. Flexion-biased loading; progressive walking distance using a flexed strategy; strengthening 3x/week; pacing | R12: Work with the flexion bias rather than against it: use a trolley, poles or an inclined treadmill to build walking distance, use cycling for aerobic fitness, build hip and lower limb strength, maintain balance and reduce falls risk, and pace activity across the day | S12: Walking aid or trolley (a practical and effective adjunct); walking poles; cycling for fitness; activity pacing | T12: Epidural injection gives short-term relief only; SURGICAL DECOMPRESSION (with or without fusion depending on instability) for moderate to severe refractory symptoms - good outcomes for walking distance in selected patients | U12: ODI; Zurich Claudication Questionnaire (Swiss Spinal Stenosis); walking distance; NPRS | V12: PAIN-FREE WALKING DISTANCE (the primary marker); time to symptom onset; ODI; falls frequency | W12: Conservative trial 12 weeks; surgery for refractory moderate to severe symptoms | X12: Cauda equina features (EMERGENCY); progressive deficit; refractory symptoms limiting function | Y12: Lumbar spinal stenosis guidelines; SPORT trial stenosis arm; Zurich Claudication Questionnaire
A13: Radicular / Neural | B13: Any; a surgical emergency at any age | C13: BILATERAL leg symptoms with SADDLE NUMBNESS and BLADDER or BOWEL CHANGE | D13: Any | E13: Sudden/Slow | F13: Equal | G13: CAUDA EQUINA SYNDROME | H13: Any change in bladder control, numbness in the saddle area, or new bilateral leg symptoms? | I13: ASK DIRECTLY IN EVERY LOW BACK PAIN ASSESSMENT: bladder dysfunction (retention with overflow, loss of urge sensation, altered urinary stream), bowel incontinence, SADDLE OR PERINEAL ANAESTHESIA, bilateral leg pain or weakness, sexual dysfunction; POST-VOID BLADDER SCAN; DIGITAL RECTAL EXAMINATION for anal tone where trained; EMERGENCY MRI. DO NOT WAIT FOR RETENTION - by then damage is often established | J13: Compression of the cauda equina, most commonly by a large central disc herniation, but also by tumour, haematoma, infection, fracture or stenosis; the consequence is potentially permanent bladder, bowel, sexual and lower limb dysfunction. TIME TO DECOMPRESSION IS THE MAIN MODIFIABLE DETERMINANT OF OUTCOME | K13: Emergency decompression to preserve bladder, bowel, sexual and lower limb function | L13: NONE - THIS IS A SURGICAL EMERGENCY. Do not treat, do not defer, do not arrange routine follow-up. Post-operatively, rehabilitation follows the surgical team, addressing residual bladder, bowel and lower limb deficits | M13: Neuropathic - acute compressive | N13: Radicular group - SURGICAL EMERGENCY AND THE MOST IMPORTANT RED FLAG IN LUMBAR PRACTICE. Distinguish incomplete (CESI - altered sensation, some function retained) from complete retention (CESR) - CESI has better outcomes with prompt surgery | O13: YES - EMERGENCY. SAME-DAY EMERGENCY REFERRAL. Do not wait for full retention. SAFETY-NET EVERY LOW BACK PAIN PATIENT with clear written and verbal advice on what symptoms mean immediate emergency attendance | P13: IMMEDIATE EMERGENCY REFERRAL for MRI and surgical decompression. The clinical task is ASKING THE QUESTIONS and SAFETY-NETTING every back pain patient. Delayed diagnosis is the commonest source of catastrophic outcome and litigation in musculoskeletal practice | Q13: None. Emergency referral is the only appropriate action | R13: Post-operatively, rehabilitation addresses residual deficits: bladder and bowel management, lower limb strength and gait, sexual function support, and functional independence | S13: None acutely. Written safety-netting advice for EVERY low back pain patient is the key preventive practice | T13: Emergency MRI and surgical decompression; specialist continence and rehabilitation input for residual deficit | U13: Determined by neurological outcome; ODI and bladder function measures post-operatively | V13: Not applicable - this is a referral, not a treatment | W13: Determined by time to decompression and completeness at presentation | X13: IMMEDIATE - same-day emergency referral. ASK THE QUESTIONS AND SAFETY-NET EVERY PATIENT | Y13: Cauda equina syndrome standards of care; CESI versus CESR outcome literature
A14: Radicular / Neural | B14: Older adults; degenerative change with or without spondylolisthesis | C14: Unilateral leg pain in a single dermatome, worse standing and walking, eased by sitting | D14: 60+ | E14: Slow | F14: Equal | G14: Lateral Recess / Foraminal Stenosis | H14: Is the leg pain in one leg only, worse standing and walking, and eased by sitting down? | I14: UNILATERAL dermatomal leg pain; worse with EXTENSION and standing, eased by flexion and sitting; may have a positive SLR; dermatomal and myotomal findings; MRI or CT showing lateral recess or foraminal narrowing; FORAMINAL narrowing is dynamically worsened by extension and ipsilateral side flexion | J14: Narrowing of the lateral recess or intervertebral foramen by facet hypertrophy, disc height loss and uncovertebral or osteophytic change, dynamically worsened in extension; degenerative spondylolisthesis frequently coexists and further narrows the foramen | K14: Increase standing and walking tolerance without leg pain | L14: FLEXION-BIASED exercise and activity strategies; neural mobilisation within tolerance; progressive trunk, HIP and lower limb strengthening 2-3x/week; graded walking programme with a flexed strategy; activity modification to reduce sustained extension; aerobic exercise; falls prevention in older adults | M14: Neuropathic | N14: Radicular group; DYNAMIC - extension and ipsilateral side flexion reduce foraminal volume, which is why symptoms are position-dependent. Frequently coexists with degenerative spondylolisthesis | O14: YES - bilateral symptoms with saddle or bladder change means CAUDA EQUINA. Also screen for vascular claudication | P14: Conservative management with flexion-biased strategies, neural mobilisation, strengthening and activity modification. Surgical decompression (foraminotomy, with fusion where instability or spondylolisthesis coexists) for refractory symptoms or progressive deficit | Q14: Stage 1-2. Flexion-biased loading; neural mobilisation within tolerance; strengthening 3x/week; graded walking progression | R14: Reduce foraminal load: avoid sustained extension and ipsilateral side flexion, use a flexed walking strategy where helpful, restore HIP EXTENSION so the lumbar spine extends less, build trunk and hip capacity, and adapt overhead and standing tasks | S14: Walking aid where helpful; activity and task modification; footwear and standing surface review | T14: Guided transforaminal injection; surgical decompression with or without fusion for refractory symptoms | U14: ODI; Zurich Claudication Questionnaire; NPRS leg and back; walking and standing tolerance | V14: Standing and walking tolerance; distal extent of leg symptoms; myotomal strength; ODI | W14: 12 weeks conservatively | X14: Cauda equina features; progressive deficit; refractory symptoms | Y14: Foraminal stenosis management literature
... A41: Post-Surgical | B41: Any; persistent pain after spinal surgery | C41: Persistent or recurrent back and leg pain after spinal surgery, with high disability and distress | D41: 40-65 | E41: Slow after surgery | F41: Female | G41: Persistent Spinal Pain Syndrome (Failed Back Surgery Syndrome) | H41: Since the surgery, has the pain persisted or returned, and how is it affecting sleep, mood and work? | I41: Persistent pain after technically satisfactory surgery; assess for a TREATABLE STRUCTURAL CAUSE first (recurrent herniation, non-union, adjacent segment disease, stenosis) versus a predominantly NOCIPLASTIC presentation; screen psychological factors, sleep, medication use and work status; Central Sensitisation Inventory; imaging only to answer a specific question | J41: Multifactorial: incomplete decompression, recurrent or adjacent pathology, and epidural fibrosis contribute in some, but CENTRAL SENSITISATION, psychological distress, deconditioning, opioid use and unmet expectations are usually more important. THE TERM 'FAILED BACK SURGERY' IS ITSELF UNHELPFUL and is being replaced | K41: Improve function, work participation, sleep and quality of life, and reduce medication burden | L41: PAIN NEUROSCIENCE EDUCATION; GRADED ACTIVITY AND GRADED EXPOSURE progressed on a TIME SCHEDULE; AEROBIC EXERCISE; progressive strengthening from a low starting load; SLEEP and stress management; pacing; MEDICATION REVIEW with the medical team, particularly opioid deprescribing; return-to-work and role planning | M41: Predominantly NOCIPLASTIC, with variable nociceptive and neuropathic contributions | N41: Post-surgical group; FIRST EXCLUDE A TREATABLE STRUCTURAL CAUSE, then manage as a predominantly nociplastic, high-impact pain state. The two pathways are entirely different | O41: Screen: exclude recurrent herniation, non-union, adjacent segment disease, stenosis and infection ONCE, thoroughly - then stop re-investigating | P41: MULTIDISCIPLINARY, PSYCHOLOGICALLY-INFORMED REHABILITATION with function-based goals. Avoid further surgery unless a clearly treatable structural cause is identified - repeat surgery in the absence of one has poor outcomes. Address medication, sleep, mood and work together | Q41: TIME-CONTINGENT. Start well within tolerance and progress on a schedule; aerobic exercise most days; strengthening 2-3x/week | R41: Shift from tissue to function: graded exposure to feared and avoided activity, aerobic conditioning, sleep and stress management, pacing, medication reduction, and work and role planning | S41: Pain neuroscience education; sleep and stress management; AVOID repeated imaging and passive modalities | T41: Multidisciplinary pain management; CBT or ACT; SPINAL CORD STIMULATION has evidence in selected patients with predominant neuropathic leg pain; opioid deprescribing support | U41: ODI; RMDQ; Central Sensitisation Inventory; PCS; TSK; HADS; medication use; work status | V41: FUNCTION-BASED markers (PSFS, activity, work hours); ODI; sleep; medication burden | W41: 6-12 months; progress is measured in function and participation, not pain reduction | X41: Suspected treatable structural cause; high distress; opioid dependence - multidisciplinary referral | Y41: Persistent spinal pain syndrome terminology; multidisciplinary rehabilitation evidence; spinal cord stimulation selection

Sheet Rx Generator
A1: PRESCRIPTION GENERATOR
A2: Select a condition in the yellow cell. Every field below is pulled live from the Master Matrix.
A4: SELECT CONDITION → | B4: Non-Specific Low Back Pain
A6: Region | B6: =IFERROR(INDEX('Master Matrix'!A$4:A$41,MATCH($B$4,'Master Matrix'!$G$4:$G$41,0)),"") -> Mechanical / Axial
A7: Activity level | B7: =IFERROR(INDEX('Master Matrix'!B$4:B$41,MATCH($B$4,'Master Matrix'!$G$4:$G$41,0)),"") -> Any; the commonest cause of disability worldwide
A8: Common symptoms | B8: =IFERROR(INDEX('Master Matrix'!C$4:C$41,MATCH($B$4,'Master Matrix'!$G$4:$G$41,0)),"") -> Diffuse low back pain and stiffness without leg symptoms, varying with posture and activity
A9: Age group | B9: =IFERROR(INDEX('Master Matrix'!D$4:D$41,MATCH($B$4,'Master Matrix'!$G$4:$G$41,0)),"") -> 25-60
A10: Onset | B10: =IFERROR(INDEX('Master Matrix'!E$4:E$41,MATCH($B$4,'Master Matrix'!$G$4:$G$41,0)),"") -> Slow/Sudden
A11: Predominance | B11: =IFERROR(INDEX('Master Matrix'!F$4:F$41,MATCH($B$4,'Master Matrix'!$G$4:$G$41,0)),"") -> Equal
A12: High-yield diagnostic question | B12: =IFERROR(INDEX('Master Matrix'!H$4:H$41,MATCH($B$4,'Master Matrix'!$G$4:$G$41,0)),"") -> Is the pain mainly in the back rather than the leg, and does it change with position and activity?
A13: Special test + imaging | B13: =IFERROR(INDEX('Master Matrix'!I$4:I$41,MATCH($B$4,'Master Matrix'!$G$4:$G$41,0)),"") -> Diffuse rather than focal tenderness; movement-related pain with variable directional response; NEGATIVE neurological examination; NEGATIVE straight leg raise; NO red flags. IMAGING IS NOT INDICATED - it does not improve outcomes and degenerative findings are near-universal in asymptomatic adults
A14: Underlying biomechanical cause | B14: =IFERROR(INDEX('Master Matrix'!J$4:J$41,MATCH($B$4,'Master Matrix'!$G$4:$G$41,0)),"") -> Multifactorial and usually not attributable to a single structure; contributing factors include reduced trunk and hip capacity, sustained postural or loading exposure exceeding tolerance, a sudden change in activity, poor sleep, psychological distress and low physical activity. THE SEARCH FOR A SINGLE STRUCTURAL CAUSE IS USUALLY UNPRODUCTIVE AND OFTEN HARMFUL
A15: DESIRED ACTIVITY GOAL | B15: =IFERROR(INDEX('Master Matrix'!K$4:K$41,MATCH($B$4,'Master Matrix'!$G$4:$G$41,0)),"") -> Work, lift, sit and exercise normally without disabling back pain
A16: PHYSIOTHERAPY SPECIFIC EXERCISE | B16: =IFERROR(INDEX('Master Matrix'!L$4:L$41,MATCH($B$4,'Master Matrix'!$G$4:$G$41,0)),"") -> STAY ACTIVE - the single most important message; GRADED EXERCISE of the patient's preference (no exercise type is clearly superior); progressive trunk and HIP strengthening 2-3x/week; aerobic exercise 150 min/week; graded exposure to feared or avoided movements; movement variability and break scheduling; SELF-MANAGEMENT and flare planning
A17: Pain mechanism | B17: =IFERROR(INDEX('Master Matrix'!M$4:M$41,MATCH($B$4,'Master Matrix'!$G$4:$G$41,0)),"") -> Nociceptive; nociplastic overlay if persistent beyond 3 months
A18: Classification / cluster | B18: =IFERROR(INDEX('Master Matrix'!N$4:N$41,MATCH($B$4,'Master Matrix'!$G$4:$G$41,0)),"") -> Cluster 1 - Non-specific low back pain: diffuse back-dominant pain + negative neurological examination + no red flags. RISK-STRATIFY WITH STarT BACK to match treatment intensity to prognosis
A19: RED FLAG STATUS | B19: =IFERROR(INDEX('Master Matrix'!O$4:O$41,MATCH($B$4,'Master Matrix'!$G$4:$G$41,0)),"") -> No
A20: MANAGEMENT EMPHASIS | B20: =IFERROR(INDEX('Master Matrix'!P$4:P$41,MATCH($B$4,'Master Matrix'!$G$4:$G$41,0)),"") -> EDUCATION, REASSURANCE AND STAYING ACTIVE ARE FIRST-LINE and supported by every major guideline. Avoid imaging, avoid bed rest, avoid opioids. Use STarT BACK to stratify: low risk needs reassurance and advice, high risk needs psychologically-informed physiotherapy. Exercise type matters far less than doing it
A21: Loading stage & entry dose | B21: =IFERROR(INDEX('Master Matrix'!Q$4:Q$41,MATCH($B$4,'Master Matrix'!$G$4:$G$41,0)),"") -> Stage 1-2 sustained. Graded exercise of the patient's choosing 2-3x/week plus aerobic activity; progress on a schedule rather than waiting for pain to settle
A22: BIOMECHANICAL CORRECTIONS & KINETIC CHAIN | B22: =IFERROR(INDEX('Master Matrix'!R$4:R$41,MATCH($B$4,'Master Matrix'!$G$4:$G$41,0)),"") -> Build capacity and vary exposure: progressive trunk and HIP strengthening, restore hip and thoracic mobility so the lumbar spine compensates less, address sustained sitting or loading exposure with break scheduling, improve general fitness and sleep, and rebuild confidence in bending and lifting
A23: Adjuncts & practical measures | B23: =IFERROR(INDEX('Master Matrix'!S$4:S$41,MATCH($B$4,'Master Matrix'!$G$4:$G$41,0)),"") -> Education and reassurance (the highest-value intervention); manual therapy as a short-term adjunct combined with exercise; heat; AVOID bed rest, imaging and opioids
A24: Advanced / surgical options | B24: =IFERROR(INDEX('Master Matrix'!T$4:T$41,MATCH($B$4,'Master Matrix'!$G$4:$G$41,0)),"") -> If persistent and high-impact: multidisciplinary or psychologically-informed rehabilitation. NICE and most guidelines do NOT recommend injections, fusion or disc replacement for non-specific low back pain
A25: Outcome measures | B25: =IFERROR(INDEX('Master Matrix'!U$4:U$41,MATCH($B$4,'Master Matrix'!$G$4:$G$41,0)),"") -> OSWESTRY DISABILITY INDEX or Roland-Morris; NPRS; STarT Back; Patient-Specific Functional Scale
A26: Re-testable markers | B26: =IFERROR(INDEX('Master Matrix'!V$4:V$41,MATCH($B$4,'Master Matrix'!$G$4:$G$41,0)),"") -> ODI or RMDQ; sitting, standing and walking tolerance; FUNCTION-based markers; return to work
A27: Expected timeline | B27: =IFERROR(INDEX('Master Matrix'!W$4:W$41,MATCH($B$4,'Master Matrix'!$G$4:$G$41,0)),"") -> Most acute episodes improve substantially within 6 weeks; recurrence is common so self-management is central
A28: Referral / surgical trigger | B28: =IFERROR(INDEX('Master Matrix'!X$4:X$41,MATCH($B$4,'Master Matrix'!$G$4:$G$41,0)),"") -> Red flag features; progressive neurological deficit; failure to improve with active management
A29: Evidence anchor | B29: =IFERROR(INDEX('Master Matrix'!Y$4:Y$41,MATCH($B$4,'Master Matrix'!$G$4:$G$41,0)),"") -> NICE NG59; Lancet Low Back Pain Series 2018; STarT Back stratified care
A31: NOTES
A32: • Green text is pulled from the Master Matrix — edit the matrix, not this sheet.
A33: • Check RED FLAG STATUS first. A crimson entry means screen, image or refer before rehabilitating.
A34: • The DESIRED ACTIVITY GOAL and PHYSIOTHERAPY SPECIFIC EXERCISE rows are written to be handed straight to the patient.
A35: • Print this sheet (portrait, fit to one page wide) for the patient file.

Sheet Assessment Roadmap
A1: FIVE-GATE ASSESSMENT ROADMAP
A2: Work top to bottom. Gate 1 includes the cauda equina questions; Gate 2 — back-dominant or leg-dominant — directs the whole pathway.
A3: Gate | B3: Purpose | C3: What You Assess | D3: Findings That Matter | E3: Decision Rule
A4: GATE 1 | B4: Screen for serious pathology — and ASK THE CAUDA EQUINA QUESTIONS | C4: Cauda equina; fracture; infection; malignancy; abdominal aortic aneurysm; visceral referral | D4: ASK EVERY PATIENT ABOUT BLADDER FUNCTION, SADDLE SENSATION AND BILATERAL LEG SYMPTOMS — CAUDA EQUINA SYNDROME is the most consequential miss in lumbar practice and the questions take thirty seconds. CONSTANT non-mechanical NIGHT PAIN with systemic features or a cancer history = malignancy or infection. FOCAL midline tenderness after minor trauma in an older adult = fragility fracture. Deep constant pain with a PULSATILE ABDOMINAL MASS in an older male = AAA. PAIN NOT REPRODUCIBLE ON MOVEMENT TESTING = look outside the musculoskeletal system | E4: Any positive -> refer or image BEFORE any local treatment. SAFETY-NET EVERY PATIENT in writing
A5: GATE 2 | B5: Is this BACK-DOMINANT or LEG-DOMINANT pain? | C5: Relative severity and distribution of back versus leg symptoms | D5: BACK-DOMINANT with no leg symptoms below the knee = non-specific low back pain, facet, discogenic or SIJ. LEG-DOMINANT below the knee with neurological signs = RADICULOPATHY. LEG symptoms on WALKING relieved by SITTING OR FLEXION = neurogenic claudication (STENOSIS). This single question directs the entire subsequent pathway | E5: Back-dominant and leg-dominant presentations have different natural histories, different treatments and different prognoses
A6: GATE 3 | B6: Risk-stratify and identify the DOMINANT PAIN MECHANISM | C6: STarT Back; psychosocial screening; sensitisation features | D6: USE STarT BACK to match treatment intensity to prognosis — low risk needs reassurance and advice, high risk needs psychologically-informed physiotherapy. Identify NOCICEPTIVE (load and position related, clear mechanical pattern), NEUROPATHIC (dermatomal, neurological signs) and NOCIPLASTIC (widespread, disproportionate, sensitised) presentations, because they need fundamentally different approaches | E6: Matching treatment to risk and mechanism improves outcomes more than any specific exercise choice
A7: GATE 4 | B7: Which region and which tissue — LUMBAR or SACROILIAC? | C7: Localise by region, then by tissue | D7: LUMBAR: pain above L5, midline or paraspinal, changed by lumbar movement. SACROILIAC: pain BELOW THE PSIS (Fortin finger test), unilateral, with THREE OR MORE POSITIVE LASLETT TESTS and a negative lumbar examination. Then: extension-provoked = facet or stenosis; flexion-provoked = discogenic; mid-range with aberrant movement = motor control; single-leg loading and transitions = SIJ or pelvic girdle | E7: SIJ pain is over-diagnosed on palpation and motion tests, which are unreliable. The Laslett provocation cluster is the only validated clinical test set
A8: GATE 5 | B8: Quantify function, capacity and the loading exposure | C8: Functional tolerance; trunk and hip capacity; the actual daily and occupational load | D8: SITTING, STANDING AND WALKING TOLERANCE in minutes; ODI or RMDQ; trunk ENDURANCE (side bridge, prone bridge, Biering-Sorensen); HIP strength and mobility (a stiff or weak hip drives lumbar load); SLR and neurological status where leg symptoms are present; and a detailed account of the ACTUAL loading exposure at work and home | E8: These become the baseline re-testable markers. FUNCTIONAL TOLERANCE and HIP CAPACITY are the two highest-yield measures in the lumbar spine
A10: DIAGNOSTIC ALGORITHM — NARRATIVE FLOW
A11: • Low back pain → RED FLAGS INCLUDING THE CAUDA EQUINA QUESTIONS? → YES: refer or image. NO ↓ (and safety-net in writing regardless)
A12: • BACK-DOMINANT or LEG-DOMINANT? ↓
A13: • BACK-DOMINANT → extension-provoked = facet; sustained-flexion-provoked = discogenic; mid-range with aberrant movement = motor control; below the PSIS with 3+ Laslett tests = SACROILIAC; no clear pattern = non-specific.
A14: • LEG-DOMINANT → below the knee with neurological signs = RADICULOPATHY; on walking relieved by SITTING or FLEXION = STENOSIS; relieved by STANDING STILL with absent pulses = VASCULAR; deep buttock with a normal lumbar examination = deep gluteal syndrome.
A15: • RISK-STRATIFY with STarT Back and identify the DOMINANT PAIN MECHANISM (nociceptive, neuropathic, nociplastic). ↓
A16: • SPECIAL POPULATIONS → under 45 with inflammatory features = axSpA (rheumatology); young athlete with extension pain = SPONDYLOLYSIS (MRI); pregnant or postpartum = pelvic girdle pain; older adult with sudden pain after minor trauma = FRAGILITY FRACTURE; child = lower investigation threshold. ↓
A17: • Then quantify FUNCTIONAL TOLERANCE, TRUNK ENDURANCE and HIP CAPACITY → set baseline markers → educate → enter the Phased Programme.
A19: CLINICAL PEARL
A20: • Convert every presentation into two or three FUNCTIONAL re-testable markers BEFORE you treat — sitting, standing and walking tolerance, and the ODI or RMDQ.
A21: • If those markers do not improve over 4-6 weeks, audit adherence, dosage, mechanism and psychosocial factors — do NOT default to adding passive treatment or repeating imaging.

Sheet Subjective Exam
A1: SUBJECTIVE EXAMINATION TEMPLATE
A2: Yellow column is the input column. The cauda equina questions and the psychosocial screen are not optional extras — they are the core of this assessment.
A3: Domain | B3: What to Ask | C3: Why It Matters | D3: Findings (fill in)
A4: Demographics & context | B4: Age; occupation and actual tasks; sport and level; home and caring demands | C4: Occupational and life load is often the exposure that matters, and age shifts the differential | D4: e.g. 38 y, warehouse picker, lifts 15 kg repeatedly
A5: CAUDA EQUINA QUESTIONS | B5: Any change in BLADDER control or sensation? Any BOWEL change? NUMBNESS IN THE SADDLE AREA or when wiping? BILATERAL leg symptoms? Any change in sexual sensation? | C5: ASK EVERY PATIENT, EVERY TIME. This is the most consequential screen in lumbar practice and takes thirty seconds
A6: BACK versus LEG dominance | B6: Which is worse - the back or the leg? How far down the leg does it go? | C6: DIRECTS THE ENTIRE PATHWAY. Record the two pain scores separately
A7: Onset & mechanism | B7: Gradual or sudden? Lifting, twisting, trivial mechanism, or no trigger at all? | C7: A trivial mechanism in an older adult suggests fragility fracture; no mechanical trigger at all raises other questions
A8: Aggravating and easing factors | B8: What makes it worse - sitting, standing, walking, bending, extension? What eases it? | C8: Extension-provoked = facet or stenosis. Sustained-flexion-provoked = discogenic. Relieved by sitting when walking = stenosis
A9: 24-hour pattern | B9: Morning stiffness DURATION? Night pain? Does it ease with movement or worsen? | C9: MORNING STIFFNESS OVER 30 MINUTES improving WITH exercise = INFLAMMATORY. Constant night pain unrelieved by position = serious pathology
A10: RED FLAG SCREEN | B10: Fever, unexplained weight loss, cancer history, steroid use, IV drug use, recent infection or procedure, trauma, age of onset | C10: GATE 1 - infection, malignancy, fracture and inflammatory disease all present here
A11: Neurological screen | B11: Numbness or tingling - WHERE exactly? Any weakness, foot drop, or tripping? | C11: Dermatomal distribution and myotomal weakness define radiculopathy; progressive weakness changes the pathway
A12: Walking and claudication | B12: How far can you walk? What stops you? What relieves it - SITTING or STANDING STILL? | C12: The RELIEVING factor discriminates neurogenic (sitting/flexion) from vascular (standing still) claudication
A13: FUNCTIONAL TOLERANCE | B13: How long can you sit, stand, walk? What can you no longer do that matters to you? | C13: The most useful objective markers and the basis for meaningful goals
A14: OCCUPATIONAL LOAD & SATISFACTION | B14: Tasks, loads, postures, vibration, hours. And: do you enjoy the job? Do you have control over how you work? | C14: JOB SATISFACTION AND CONTROL predict outcome at least as strongly as physical load
A15: BELIEFS & WHAT THEY HAVE BEEN TOLD | B15: What do you think is wrong? What have you been told? Have you had a scan, and what did it say? | C15: THE IMAGING CONVERSATION IS A CLINICAL INTERVENTION - "crumbling" and "wear and tear" create disability
A16: Fear and avoidance | B16: What are you avoiding? What are you afraid might happen if you bend or lift? | C16: Fear-avoidance is a major modifiable predictor of persistent disability
