Workbook

Sheet Read Me
A1: BONE STRESS, CARTILAGE & MENISCAL INJURY — LOAD-BASED ALGORITHM
A2: Sport-specific load reasoning: what load caused it → is the site high-risk → how much load must come off → how it goes back on.
A4: SHEET | B4: WHAT IT DOES | C4: WHEN TO USE IT | D4: FOCUS
A5: Master Matrix | B5: 41 conditions across bone stress injury, cartilage and meniscus — sport and load pattern, discriminating question, imaging, grading, load driver, management emphasis, weight-bearing status, loading progression, biomechanical and technique corrections, training-load prescription, timeline, referral trigger and the consequence if missed. | C5: The core reference. Filter column A by tissue or column C by risk class. | D5: All three tissues
A6: Risk Stratification | B6: High-risk versus low-risk bone stress sites, why each is high-risk, and the action required. | C6: The moment you suspect a BSI — before anything else. | D6: Bone stress
A7: Grading Systems | B7: Fredericson, Kaeding-Miller, ICRS, Outerbridge, meniscal vascular zones and tear patterns. | C7: Interpreting a radiology report. | D7: All three tissues
A8: Sport Load Profiles | B8: 10 sport and occupational profiles: load characteristics, the injuries each produces, the load errors that cause them, and the load rules that prevent them. | C8: Understanding why THIS athlete broke. | D8: Sport-specific load
A9: Load Rules | B9: ACWR, weekly progression ceilings, jump counts, bowling workloads, symptom and effusion windows. | C9: Writing the load prescription. | D9: Sport-specific load
A10: Load Calculator | B10: Live 12-week acute:chronic workload calculator with automatic flagging of spikes and undertraining. | C10: Weekly, with any athlete returning from a load-related injury. | D10: Sport-specific load
A11: Return to Run | B11: Nine-stage graded return-to-run programme with an explicit entry gate. | C11: Every lower-limb BSI once the entry gate is met. | D11: Bone stress
A12: Rx Generator | B12: Pick a condition from the dropdown; the whole management prescription is pulled from the Master Matrix. | C12: In clinic, or to print a plan into the patient file. | D12: All three tissues
A13: Progress Tracker | B13: Live tracker: entry-gate checks, limb symmetry, load tolerance and an automatic return-to-sport verdict. | C13: Every re-assessment. | D13: All three tissues
A14: Bone Health Screen | B14: Energy availability, menstrual status, BMD, vitamin D, prior injury and load history — with the referral pathway for each. | C14: Every BSI, and mandatory in any recurrent case. | D14: Bone stress
A15: Imaging Guide | B15: Which modality answers which question, and the traps in each. | C15: Before requesting, and when reading a report. | D15: All three tissues
... A17: References | B17: Classification and guideline sources. | C17: Verifying or citing. | D17: —
A19: HOW TO USE THIS WORKBOOK
A20: • THE CENTRAL QUESTION in all three tissues is the same: what changed in the load, and what reduced the tissue's capacity to accept it?
A21: • Bone stress differs from soft tissue in one crucial way — the acceptable symptom window is pain-FREE impact loading, not the usual "≤5/10 settling within 24 hours". Applying the soft-tissue rule to a BSI is the commonest management error.
A22: • In cartilage and meniscal injury, effusion after loading is a more reliable tolerance signal than pain.
A23: • Check the Risk Stratification sheet BEFORE starting any rehabilitation. Ten sites change the whole plan.
A24: • Yellow cells are inputs. Green text is pulled from another sheet. Do not overwrite formula cells.
A25: • This workbook supports clinical reasoning; it does not replace individualised assessment, imaging interpretation, local protocols or the operating surgeon's protocol.

Sheet Master Matrix
A1: MASTER MATRIX — BONE STRESS, CARTILAGE & MENISCAL INJURY (41 CONDITIONS)
A2: Columns A–L: load-based diagnosis. Columns M–W: the management programme. Red rows in column C are high-risk sites or surgical urgencies.
A3: Tissue | B3: Site / Condition | C3: Risk Class | D3: Sport & Load Pattern | E3: Athlete Profile | F3: Hallmark Presentation | G3: One Question That Best Discriminates | H3: Key Examination Findings | I3: Confirmatory Imaging | J3: Grading / Classification | K3: LOAD & BIOMECHANICAL DRIVER | L3: Non-Mechanical Contributors | M3: MANAGEMENT EMPHASIS | N3: Weight-Bearing / Protection Status | O3: Loading Progression & Dose | P3: BIOMECHANICAL & TECHNIQUE CORRECTIONS | Q3: TRAINING-LOAD PRESCRIPTION | R3: Adjuncts / Advanced Options | S3: Re-test Markers & Outcomes | T3: Timeline to Return to Sport | U3: Referral / Surgical Trigger | V3: Consequence if Missed | W3: Evidence Anchor
A4: Bone Stress | B4: Femoral neck — tension side (superolateral) | C4: HIGH RISK | D4: Distance running, military recruit training, sudden mileage escalation | E4: Female distance runner or recruit; often low energy availability | F4: Deep groin or anterior hip pain with running, progressing to pain at rest and night pain; antalgic gait | G4: Is the groin pain now present when you walk, not just when you run? | H4: Pain at end-range hip internal rotation; positive fulcrum test; pain on single-leg hop (do NOT hop-test if suspicion is high); antalgic gait | I4: URGENT MRI (X-ray insensitive early). Do not delay for radiographs | J4: Kaeding-Miller I-V; tension-side lucency or fracture line on the superolateral cortex | K4: Cumulative compressive and tensile load through the femoral neck from running volume escalation without adaptation; hip abductor weakness, reduced step rate, long stride and stiff landing | L4: Low energy availability, menstrual dysfunction, low bone mineral density, vitamin D insufficiency, prior BSI | M4: URGENT orthopaedic referral. Strict non-weight-bearing pending surgical opinion — tension-side lesions progress to complete fracture with catastrophic consequence. Prophylactic fixation is often indicated | N4: NON-WEIGHT-BEARING on crutches from the moment of suspicion until cleared by the surgeon | O4: No lower-limb impact loading. Preserve capacity with upper-body and core work; pool and cycling ONLY once cleared. Post-clearance: graded weight bearing → walking → anti-gravity or pool running → return-to-run programme | P4: Rebuild after healing: hip abductor and extensor strength, step rate +5-10%, reduce overstriding and vertical oscillation, soft-landing strategy, surface and footwear review | Q4: Complete rest from impact; rebuild via the Return-to-Run programme with weekly increments and a strict acute:chronic workload ceiling of 1.3 | R4: Surgical fixation as indicated. Nutrition and endocrine co-management; vitamin D and calcium optimisation via medical referral | S4: Pain-free walking; pain-free single-leg stance and hop (only when cleared); imaging evidence of healing; hip abductor strength LSI | T4: 4-6 months to full sport; longer if fixation or displacement | U4: IMMEDIATE — any suspicion of a tension-side femoral neck BSI is an emergency referral | V4: Displacement, avascular necrosis, non-union, and a career-ending or life-altering outcome | W4: Kaeding-Miller classification; high-risk BSI consensus (BJSM)
A5: Bone Stress | B5: Femoral neck — compression side (inferomedial) | C5: HIGH RISK | D5: Distance running, recruit training, rapid volume increase | E5: Endurance athlete; both sexes; frequently with energy deficit | F5: Groin or anterior thigh ache with running that eases with rest; less aggressive course than tension side | G5: Does the groin ache start at a predictable distance and settle with rest? | H5: Pain at end-range internal rotation; positive fulcrum test; often able to weight-bear | I5: MRI (marrow oedema on the inferomedial cortex) | J5: Kaeding-Miller I-V; compression-side lesion | K5: Repetitive axial compressive loading beyond bone remodelling capacity; volume escalation, hip abductor and extensor weakness, poor shock attenuation | L5: Low energy availability, menstrual dysfunction, low BMD, vitamin D insufficiency | M5: Protected weight bearing and complete removal of impact load; orthopaedic review to confirm the lesion is compression-side and stable; conservative management is usual | N5: Protected or partial weight bearing until pain-free walking, then progress as symptoms allow, per orthopaedic advice | O5: Non-impact aerobic conditioning (pool, cycling, upper body); hip and trunk strengthening once pain-free; then graded weight bearing → walk-run programme | P5: Hip abductor and extensor strengthening, increase step rate, reduce stride length and vertical oscillation, address stiff landing and low cadence | Q5: Zero impact until pain-free walking; then structured return-to-run with weekly increments and ACWR ceiling of 1.3 | R5: Nutrition and endocrine co-management; vitamin D and calcium optimisation | S5: Pain-free walking; pain-free hop; imaging healing; hip strength LSI; running volume tolerance | T5: 3-4 months to full sport | U5: Any femoral neck BSI requires orthopaedic review to grade and confirm the side | V5: Progression to a complete or displaced fracture | W5: Kaeding-Miller; high-risk BSI consensus
A6: Bone Stress | B6: Femoral shaft | C6: Low risk | D6: Distance running, recruit training, high-volume field sport | E6: Endurance athlete or recruit | F6: Diffuse deep thigh ache with running; poorly localised; often mistaken for a quadriceps strain | G6: Is the thigh pain deep and hard to point to, and worse the further you run? | H6: Pain on fulcrum test; percussion tenderness; pain on single-leg hop; no muscle-specific pain on resisted testing | I6: MRI; X-ray usually normal early | J6: Fredericson-type marrow oedema grading; Kaeding-Miller | K6: High-volume running load exceeding remodelling capacity; poor shock absorption, hip and quadriceps weakness | L6: Low energy availability, low BMD, vitamin D insufficiency | M6: Relative rest from impact, protected loading, then graded return to running with load monitoring; conservative management | N6: Weight bearing as tolerated, pain-free walking is the requirement | O6: Non-impact conditioning → pain-free walking → walk-run progression → continuous running → speed and hills last | P6: Hip and quadriceps strengthening, step-rate increase, running gait review, surface and footwear progression | Q6: Return to run at approximately 50% of pre-injury volume, increasing 10-15% weekly with ACWR maintained under 1.3-1.5 | R6: Nutrition, vitamin D and calcium review; bone-health screen if recurrent | S6: Pain-free hop; pain-free 20-minute run; hip strength LSI | T6: 8-12 weeks | U6: Failure to settle, or a second BSI → bone-health and endocrine work-up | V6: Progression to a complete fracture with high-energy loading | W6: Fredericson grading; BJSM BSI consensus
A7: Bone Stress | B7: Pubic ramus / inferior pubic ramus | C7: Low risk | D7: Distance running, military marching, field sport with high change-of-direction volume | E7: Female distance runner (classic), recruit | F7: Groin or perineal ache with running and single-leg loading; may radiate to the adductor region | G7: Does the pain sit in the groin and worsen with running rather than with a specific kicking or cutting movement? | H7: Local tenderness over the ramus; pain on single-leg stance and hop; resisted adduction may be uncomfortable but is not the primary source | I7: MRI | J7: Kaeding-Miller | K7: Repetitive running and marching load with poor lumbopelvic control; adductor and hip abductor imbalance; volume escalation | L7: Low energy availability, menstrual dysfunction, low BMD | M7: Relative rest from impact, lumbopelvic and hip strengthening, then graded return to running | N7: Weight bearing as tolerated; pain-free walking gate | O7: Non-impact conditioning → pain-free walking → walk-run progression; adductor and lumbopelvic loading throughout | P7: Lumbopelvic control, adductor and abductor balance, running gait and step-rate review, cutting mechanics | Q7: Return to run at reduced volume with 10-15% weekly increments and ACWR under 1.3 | R7: Nutrition and bone-health review; endocrine referral if amenorrhoeic | S7: Pain-free single-leg hop; pain-free running distance; adductor strength ratio | T7: 8-12 weeks | U7: Recurrent or bilateral presentation → bone-health work-up | V7: Prolonged disability and recurrence; missed differential of athletic groin pain | W7: BJSM BSI consensus
A8: Bone Stress | B8: Sacrum / sacral ala | C8: Low risk | D8: Distance running, long-course triathlon, marching | E8: Female distance runner; often postpartum or in energy deficit | F8: Deep unilateral buttock or low back pain with running and prolonged standing; hard to localise | G8: Is the buttock pain worse the longer you run, and does it linger after you stop? | H8: Tenderness over the sacral sulcus; pain on single-leg stance and hop; sacroiliac provocation tests may be positive but are non-specific | I8: MRI (X-ray and bone scan are inadequate) | J8: Kaeding-Miller | K8: Repetitive running load through the sacroiliac complex; poor lumbopelvic control, hip abductor weakness, volume escalation | L8: Low energy availability, menstrual dysfunction, low BMD, postpartum bone turnover | M8: Relative rest from impact, lumbopelvic and hip strengthening, bone-health work-up (this presentation should always trigger one) | N8: Weight bearing as tolerated; pain-free walking gate | O8: Non-impact conditioning → pain-free walking → walk-run progression, with lumbopelvic and gluteal loading throughout | P8: Gluteal and lumbopelvic strengthening, step-rate increase, load distribution in gait, address stiff running pattern | Q8: Zero impact until pain-free walking; then graded return with ACWR under 1.3 | R8: Nutrition, endocrine and DXA review; vitamin D and calcium optimisation | S8: Pain-free hop; pain-free running distance; gluteal strength LSI | T8: 8-12 weeks | U8: Always refer for a bone-health and energy-availability assessment | V8: Recurrence and progression to a more extensive sacral fracture | W8: BJSM BSI consensus; RED-S clinical assessment
A9: Bone Stress | B9: Lumbar pars interarticularis (spondylolysis) | C9: HIGH RISK | D9: Cricket fast bowling, gymnastics, dance, tennis serve, javelin, rowing — repetitive extension and rotation | E9: Adolescent athlete in a growth spurt; fast bowlers and gymnasts over-represented | F9: Unilateral low back pain with extension and rotation; worse with the sport-specific action; eases with rest | G9: Does the back pain come on with arching or rotating, and is it on one side only? | H9: Pain on single-leg extension (stork) test; tenderness over the affected level; hip flexor and hamstring tightness; poor lumbopelvic control | I9: MRI (STIR sequences) is first-line in the adolescent; CT for bony detail and healing assessment | J9: Stage: stress reaction → incomplete fracture → complete fracture → non-union (terminal). Early stages heal, terminal ones do not | K9: Repetitive lumbar extension with rotation and axial load; in bowlers, a mixed action with counter-rotation, excessive shoulder-pelvis separation and high over volume; hip extension and thoracic rotation restriction forces the lumbar spine to compensate | L9: Growth spurt, low bone mineral density, energy deficit, rapid workload escalation | M9: Cease the provocative action completely for the healing window (typically 3 months for an early lesion); lumbopelvic and hip control programme; graded staged return; technique remodelling is mandatory before return | N9: Weight bearing normal. Brace use varies by protocol — follow local guidance | O9: Phase 1: pain-free neutral-spine core and hip work. Phase 2: progressive lumbopelvic strengthening and hip mobility. Phase 3: reintroduce extension and rotation. Phase 4: staged sport-specific volume | P9: Restore hip extension and thoracic rotation so the lumbar spine stops compensating; correct a mixed bowling action; reduce shoulder-pelvis counter-rotation; build anterior chain and gluteal capacity; retrain the landing and follow-through | Q9: Follow age-appropriate bowling workload limits (overs per spell, per day and per week) on return; cap jump and extension volume in gymnasts; log every session | R9: Bone-health review; vitamin D and calcium optimisation; dietitian referral where energy availability is a concern | S9: Pain-free stork test; pain-free sport-specific action; imaging healing on CT or MRI; lumbopelvic endurance tests | T9: 3-6 months; terminal-stage lesions may return sooner but will not heal bony union | U9: Adolescent unilateral extension-related back pain lasting more than 2 weeks warrants imaging, not reassurance | V9: Progression to a complete fracture, spondylolisthesis and a chronic career-limiting back | W9: ECB / cricket bowling workload guidance; adolescent spondylolysis consensus
A10: Bone Stress | B10: Patella | C10: HIGH RISK | D10: Jumping and landing sport — volleyball, basketball, high jump; heavy squat and plyometric loading | E10: Jump athlete; often with a history of patellar tendinopathy | F10: Anterior knee pain with jumping and landing that does not behave like tendinopathy (does not warm up); localised patellar tenderness | G10: Does the anterior knee pain fail to warm up with activity, unlike the usual jumper's knee pattern? | H10: Localised patellar bone tenderness rather than tendon tenderness; pain on hop and landing; effusion may be present | I10: MRI | J10: Kaeding-Miller; vertical fracture lines carry higher displacement risk | K10: High patellofemoral joint reaction force from repetitive energy-storage loading; jump volume escalation, stiff landing, quadriceps dominance, poor hip and ankle absorption | L10: Low energy availability, low BMD, vitamin D insufficiency | M10: Orthopaedic review — the patella is a high-risk site with displacement potential. Remove jump and impact load entirely; conservative management with protection, or fixation for a displaced or vertical lesion | N10: Protected weight bearing; brace or immobilisation per surgeon in higher-grade lesions | O10: No jumping or impact. Non-impact conditioning → pain-free walking → progressive quadriceps loading → controlled landing → graded plyometric reintroduction | P10: Rebuild the landing chain: hip and ankle absorption strategy, calf and gluteal capacity, ankle dorsiflexion range, soft knee-hip flexion landing rather than a stiff quadriceps-dominant one; cap jump counts | Q10: Count jumps. Return via a graded plyometric ladder — bilateral low-amplitude → bilateral high → unilateral low → unilateral high → sport | R10: Orthopaedic fixation where indicated; bone-health and nutrition review | S10: Pain-free hop; jump count tolerance; countermovement jump height; quadriceps LSI | T10: 3-6 months | U10: Any suspected patellar BSI — high-risk site | V10: Displacement, non-union and extensor mechanism compromise | W10: Kaeding-Miller; high-risk BSI consensus
A11: Bone Stress | B11: Tibia — posteromedial (compression side) | C11: Low risk | D11: Distance running, field sport, recruit marching; the commonest BSI site overall | E11: Runner or recruit; often a recent surface, footwear or volume change | F11: Localised posteromedial shin pain that began diffuse (MTSS-like) and became focal; worse with impact, eases with rest early on | G11: Can you point to the sore spot with one finger, and is it worse now than when it started? | H11: Focal bony tenderness over a small area (versus the diffuse tenderness of MTSS); pain on single-leg hop; pain on percussion or tuning fork | I11: MRI is the reference standard; X-ray insensitive for 2-3 weeks | J11: Fredericson grade 1 (periosteal oedema) to 4b (multiple cortical lines) | K11: Repetitive compressive tibial loading beyond remodelling capacity; volume or intensity spike, low step rate with overstriding, high vertical loading rate, calf weakness reducing shock attenuation, hard surface or worn footwear | L11: Low energy availability, menstrual dysfunction, low BMD, vitamin D insufficiency, prior BSI, smoking | M11: Relative rest from impact until pain-free walking and hopping, then a structured graded return-to-run programme; correct the load error that caused it — this is the whole intervention | N11: Weight bearing as tolerated; walking boot only if walking is painful | O11: Phase 1: non-impact aerobic (pool, bike, anti-gravity treadmill) plus calf, glute and foot strengthening. Phase 2: pain-free walking. Phase 3: walk-run intervals. Phase 4: continuous running, then speed and hills | P11: Increase step rate by 5-10%, reduce overstriding and vertical oscillation, build calf and intrinsic foot capacity, review footwear age and surface, address hip abductor weakness and crossover gait | Q11: Restart at approximately 50% of pre-injury volume, increase 10-15% weekly, hold ACWR between 0.8 and 1.3, and reintroduce speed and hills only in the final phase | R11: Nutrition, vitamin D and calcium review; DXA if recurrent or if RED-S features are present | S11: Focal tenderness; pain-free single-leg hop x10; pain-free 20-minute run; calf endurance repetitions | T11: 6-12 weeks depending on Fredericson grade | U11: Failure to progress, a second BSI, or any RED-S feature → bone-health work-up | V11: Progression up the Fredericson grades to a frank cortical fracture and a much longer lay-off | W11: Fredericson MRI grading; BJSM BSI consensus
A12: Bone Stress | B12: Tibia — anterior cortex (“dreaded black line”) | C12: HIGH RISK | D12: Jumping and leaping sport — basketball, volleyball, dance, triple jump; also distance runners | E12: Jump athlete or runner; often a long history of ignored shin pain | F12: Persistent anterior mid-shin pain, present at rest and at night, that has failed conservative management | G12: Has the shin pain been going on for months and is it there when you are not training? | H12: Focal anterior mid-tibial tenderness; pain on hop; often minimal swelling despite significant pathology | I12: X-ray may show the anterior cortical lucency (the “black line”); MRI or CT to characterise | J12: Fredericson 4b / Kaeding-Miller high grade; tension-side lesion on the convex anterior cortex | K12: Repetitive tensile loading on the anterior tibial cortex in a poorly vascularised region; high jump and leap volume, stiff landing, calf weakness | L12: Low energy availability, low BMD, vitamin D insufficiency | M12: Orthopaedic referral. This is a tension-side, poorly vascularised, notoriously slow-healing lesion. Prolonged offloading, and intramedullary nailing is often required in athletes who need a reliable timeline | N12: Protected weight bearing or boot immobilisation; NO impact loading | O12: Non-impact conditioning only for a prolonged period. Post-clearance or post-fixation: graded weight bearing → walking → walk-run → jumping last of all | P12: After healing, rebuild the landing chain: calf capacity, ankle dorsiflexion, hip absorption, soft landing strategy; cap jump volume permanently and monitor | Q12: Very conservative graded return; jump counts logged; ACWR ceiling of 1.2 during the reintroduction phase | R12: Surgical fixation (intramedullary nail) shortens an otherwise 6-12 month conservative course; bone-health and nutrition work-up | S12: Pain-free walking and hopping; radiographic healing; calf endurance; jump tolerance | T12: 6-12 months conservatively; 3-6 months with fixation | U12: IMMEDIATE orthopaedic referral — high-risk tension-side lesion | V12: Non-union, delayed union and complete tibial fracture | W12: High-risk BSI consensus; Fredericson grading
A13: Bone Stress | B13: Medial malleolus | C13: HIGH RISK | D13: Running, jumping and cutting sport; repetitive ankle dorsiflexion loading | E13: Runner or field-sport athlete | F13: Medial ankle pain with running and push-off; localised to the malleolus rather than the tendon | G13: Is the pain on the bone at the inside of the ankle rather than along a tendon? | H13: Focal tenderness over the medial malleolus; pain on hop and on forced dorsiflexion; tibialis posterior testing is unremarkable | I13: MRI or CT (X-ray may show a vertical lucency) | J13: Kaeding-Miller; vertical fracture line at the plafond junction is the high-risk pattern | K13: Repetitive impaction of the talus against the medial malleolus in dorsiflexion; high running and cutting volume, over-pronation, ankle dorsiflexion restriction | L13: Low energy availability, low BMD, vitamin D insufficiency | M13: Orthopaedic referral — high-risk site with displacement and non-union potential. Conservative offloading for a low-grade lesion; fixation for a visible fracture line or a competitive athlete needing a reliable timeline | N13: Boot immobilisation or protected weight bearing per surgeon | O13: No impact. Non-impact conditioning → protected walking → pain-free walking → walk-run → cutting last | P13: Restore ankle dorsiflexion range, control over-pronation with orthoses where indicated, build calf and tibialis posterior capacity, retrain cutting and deceleration mechanics | Q13: Zero impact until cleared; then graded return with weekly increments and an ACWR ceiling of 1.3 | R13: Surgical fixation where indicated; bone-health and nutrition review | S13: Pain-free walking and hopping; imaging healing; calf endurance; cutting tolerance | T13: 3-6 months | U13: Any suspected medial malleolar BSI — high-risk site | V13: Displacement, non-union and post-traumatic ankle degeneration | W13: High-risk BSI consensus
A14: Bone Stress | B14: Talus | C14: HIGH RISK | D14: Jumping, landing and marching load; recruit training | E14: Jump athlete or military recruit | F14: Deep, poorly localised ankle pain with impact; stiffness; pain on landing | G14: Is the ankle pain deep inside the joint rather than on a specific bone edge or tendon? | H14: Diffuse deep ankle tenderness; pain on hop and landing; restricted and painful end-range dorsiflexion | I14: MRI (X-ray insensitive) | J14: Kaeding-Miller | K14: Repetitive high-impact axial loading through a bone with a precarious blood supply; jump and landing volume, stiff landing, restricted dorsiflexion | L14: Low energy availability, low BMD, vitamin D insufficiency | M14: Orthopaedic referral — high-risk site given the tenuous vascular supply. Offloading and protected weight bearing; conservative management with close imaging follow-up | N14: Boot immobilisation and protected or non-weight bearing per surgeon | O14: No impact. Non-impact conditioning → protected walking → pain-free walking → walk-run → jumping last | P14: Restore ankle dorsiflexion, rebuild calf and foot intrinsic capacity, retrain soft landing with hip and knee absorption, cap jump volume | Q14: Zero impact until cleared; very graded reintroduction with jump counts logged | R14: Bone-health and nutrition work-up; surgical opinion if healing stalls | S14: Pain-free walking and hopping; imaging healing; dorsiflexion range; jump tolerance | T14: 3-6 months | U14: Any suspected talar BSI — high-risk site with avascular necrosis potential | V14: Avascular necrosis, non-union and post-traumatic ankle arthritis | W14: High-risk BSI consensus
... A42: Meniscus | B42: Post-meniscectomy compartment overload | C42: Long-term sequela | D42: Return to impact and pivoting sport after meniscal resection | E42: Athlete or active adult months to years after a partial meniscectomy | F42: Compartment pain and swelling on returning to impact load; the knee tolerates less than it used to | G42: Since the meniscal surgery, does the knee swell and ache with volumes of running it used to handle easily? | H42: Compartment-specific joint-line tenderness; effusion after loading; possible early varus or valgus change | I42: Weight-bearing radiographs to assess joint space and alignment; MRI for cartilage status | J42: Early degenerative change proportional to the volume of meniscus resected | K42: Loss of load distribution over a reduced meniscal surface — contact stress rises sharply after resection; malalignment concentrating load, quadriceps and hip weakness reducing absorption, and a return to pre-surgery impact volumes the joint can no longer distribute | L42: Raised body mass, metabolic factors, malalignment | M42: Set a realistic long-term load ceiling and build capacity around it: quadriceps and hip strengthening, impact volume modification, offloading where malaligned, weight management. Educate that the joint now distributes load differently and needs a permanently different load profile | N42: Full weight bearing | O42: Progressive quadriceps, hip and calf strengthening; graded and capped impact loading; substitute some running volume with non-impact conditioning | P42: Restore shock absorption and redistribute load: quadriceps and hip abductor capacity, correct malalignment with wedging or an unloader brace, soft landing strategy, cap impact volume permanently, cross-train | Q42: Set a sustainable weekly impact ceiling; use effusion after loading as the primary tolerance signal; ACWR under 1.3 | R42: Unloader brace or wedging; osteotomy for correctable malalignment in a younger patient; meniscal allograft transplantation in selected cases | S42: Effusion after loading; impact volume tolerance; quadriceps LSI; radiographic joint space over time | T42: Ongoing self-management; capacity building over 3-6 months | U42: Progressive compartment narrowing in a younger patient → osteotomy or meniscal allograft opinion | V42: Accelerated compartment osteoarthritis and early arthroplasty | W42: Post-meniscectomy degeneration literature; OARSI 2019

Sheet Risk Stratification
A1: BONE STRESS INJURY — RISK STRATIFICATION
A2: Check this sheet the moment you suspect a BSI. Ten high-risk sites change the entire plan, and several are emergencies.
A3: Risk Class | B3: Site | C3: Why It Is Classified This Way | D3: Action Required | E3: Consequence if Managed as Low Risk
A4: HIGH RISK | B4: Femoral neck — tension side | C4: Tensile side of a critically loaded bone; displacement risk | D4: URGENT referral; non-weight-bearing pending surgical opinion | E4: Displacement, avascular necrosis, career-ending
A5: HIGH RISK | B5: Anterior tibial cortex | C5: Tension side, poorly vascularised, notoriously slow to heal | D5: Orthopaedic referral; prolonged offloading or intramedullary nailing | E5: Non-union, complete fracture
A6: HIGH RISK | B6: Tarsal navicular | C6: Watershed vascular zone; the most commonly missed high-risk site | D6: STRICT non-weight-bearing cast 6 weeks, or fixation | E6: Non-union, recurrence
A7: HIGH RISK | B7: Medial malleolus | C7: Vertical fracture line at the plafond junction | D7: Orthopaedic referral; boot or fixation | E7: Displacement, ankle degeneration
A8: HIGH RISK | B8: Talus | C8: Tenuous blood supply | D8: Orthopaedic referral; protected weight bearing | E8: Avascular necrosis
A9: HIGH RISK | B9: Proximal fifth metatarsal (Jones, zone 2) | C9: Watershed zone with the highest refracture rate | D9: Intramedullary screw fixation is standard in athletes | E9: Non-union, refracture
A10: HIGH RISK | B10: Sesamoid (hallux) | C10: Poor blood supply; prone to osteonecrosis | D10: Strict offloading; orthotic cut-out | E10: Non-union, osteonecrosis
A11: HIGH RISK | B11: Base of second metatarsal | C11: Adjacent to the Lisfranc complex | D11: Orthopaedic referral; boot; no pointe work | E11: Lisfranc compromise
A12: HIGH RISK | B12: Patella | C12: Displacement risk; vertical lines are worse | D12: Orthopaedic referral; no jumping | E12: Displacement, extensor failure
A13: HIGH RISK | B13: Lumbar pars interarticularis | C13: Progresses to non-union and spondylolisthesis if loaded | D13: Cease the provocative action 3 months; image early in adolescents | E13: Complete fracture, spondylolisthesis
A14: Low risk | B14: Posteromedial tibia | C14: Compression side; reliable healing | D14: Relative rest, graded return-to-run | E14: Progression up the Fredericson grades
... A21: Low risk | B21: Ulna | C21: Heals with removal of the action | D21: Cease the provocative loading; technique review | E21: Olecranon non-union
A23: THE RULE
A24: • HIGH RISK sites are on the tension side of the bone, in a watershed vascular zone, or carry a displacement risk. They need imaging and an orthopaedic opinion, not a rehabilitation trial.
A25: • LOW RISK sites are on the compression side and heal reliably with load removal and a graded return.
A26: • A normal X-ray NEVER excludes a bone stress injury. MRI is the first-line investigation for almost every site; CT is superior for the navicular, the pars and assessing union.
A27: • The three most commonly missed: the tarsal navicular (vague midfoot ache in a sprinter), the tension-side femoral neck (groin pain now present at rest), and the adolescent pars lesion (unilateral extension-related back pain).

Sheet Grading Systems
A1: GRADING & CLASSIFICATION SYSTEMS
A2: Translating a radiology report into a load decision.
A3: System | B3: Grade / Category | C3: What It Means | D3: Management Implication | E3: Note
A4: Fredericson (tibial BSI, MRI) | B4: Grade 1 | C4: Periosteal oedema only | D4: Relative rest; 2-4 weeks | E4: Bone stress reaction
A5: Fredericson (tibial BSI, MRI) | B5: Grade 2 | C5: Marrow oedema on T2/STIR only | D5: Relative rest; 4-6 weeks | E5: Bone stress reaction
A6: Fredericson (tibial BSI, MRI) | B6: Grade 3 | C6: Marrow oedema on T1 and T2 | D6: Offload; 6-9 weeks | E6: Bone stress injury
A7: Fredericson (tibial BSI, MRI) | B7: Grade 4a | C7: Multiple focal marrow signal changes | D7: Offload; 9-12 weeks | E7: Bone stress injury
A8: Fredericson (tibial BSI, MRI) | B8: Grade 4b | C8: Cortical fracture line visible | D8: Offload / immobilise; 12+ weeks | E8: Stress fracture
A9: Kaeding-Miller (any BSI) | B9: Grade I | C9: Imaging change, asymptomatic | D9: Load modification | E9: Applies to any site
A10: Kaeding-Miller (any BSI) | B10: Grade II | C10: Imaging change with pain, no fracture line | D10: Relative rest | E10: Applies to any site
A11: Kaeding-Miller (any BSI) | B11: Grade III | C11: Non-displaced fracture line with pain | D11: Offload; consider immobilisation | E11: Applies to any site
A12: Kaeding-Miller (any BSI) | B12: Grade IV | C12: Displaced fracture (<2 mm) with pain | D12: Surgical opinion | E12: Applies to any site
A13: Kaeding-Miller (any BSI) | B13: Grade V | C13: Non-union with pain | D13: Surgical management | E13: Applies to any site
A14: ICRS (cartilage) | B14: Grade 0 | C14: Normal cartilage | D14: No treatment | E14: Arthroscopic or MRI grading
... A28: Meniscal tear pattern | B28: Horizontal cleavage / degenerative | C28: Age-related tissue failure | D28: Exercise-based rehabilitation first-line | E28: Arthroscopy not indicated without locking

Sheet Sport Load Profiles
A1: SPORT-SPECIFIC LOAD PROFILES
A2: Every one of these injuries is a load story. Find the load error and you have found the diagnosis and the treatment.
A3: Sport / Population | B3: Load Characteristics | C3: Injuries It Produces | D3: Typical Load Error | E3: LOAD RULES FOR THIS SPORT
A4: Distance running | B4: High-volume repetitive tibial and metatarsal impact; 2-3x body weight per step | C4: Posteromedial tibia, metatarsal shafts, femoral neck, sacrum, pubic ramus, navicular, calcaneus | D4: Weekly mileage spike; return after a lay-off; surface or footwear change; low step rate with overstriding; energy deficit | E4: Increase volume 10-15% weekly; hold ACWR 0.8-1.3; step rate +5-10%; rotate footwear and surfaces; separate hard days; screen energy availability in every female runner and in any recurrent case
A5: Sprinting & track jumps | B5: Explosive push-off and high-magnitude landing forces | C5: Navicular, anterior tibial cortex, sesamoid, metatarsal base, lumbar pars | D5: Spike volume on hard tracks; sudden block or plyometric loading; high jump and bound counts | E5: Cap spike-shod volume and bound counts; progress plyometrics in a ladder; log take-off repetitions; strict recovery between explosive sessions
A6: Basketball & volleyball | B6: High jump and landing volume; repeated deceleration and cutting | C6: Navicular, anterior tibial cortex, patella, fifth metatarsal (Jones), talus; chondral and meniscal injury from landing and pivoting | D6: Pre-season jump volume spikes; court surface change; congested fixture periods | E6: Count jumps as the primary load metric; progress the plyometric ladder bilateral-low → bilateral-high → unilateral-low → unilateral-high; monitor ACWR across a congested schedule
A7: Football / soccer & field sport | B7: Cutting, pivoting, deceleration and sprint volume | C7: Fifth metatarsal, pubic ramus, tibia; meniscal tears (longitudinal, ramp, bucket-handle), chondral lesions | D7: Pre-season loading spikes; boot change; hard or artificial surfaces; congested fixtures | E7: Monitor high-speed running distance and acceleration/deceleration counts, not just total distance; hold ACWR 0.8-1.3; embed a neuromuscular prevention programme
A8: Cricket — fast bowling | B8: Repetitive lumbar extension, rotation and high ground reaction force at front-foot impact | C8: Lumbar pars interarticularis (dominant), ribs, tibia | D8: Overs bowled per spell, per day and per week; a mixed action with excessive counter-rotation; adolescent growth spurt | E8: Apply age-appropriate over limits per spell, per day and per week; remodel a mixed action; log every over; strict rest days between bowling days
A9: Gymnastics & dance | B9: Upper-limb weight bearing, repetitive extension, and extreme forefoot loading | C9: Lumbar pars, distal radial physis, ulna, second metatarsal base, sesamoid, talus | D9: Year-round single-sport specialisation; pointe volume; skill repetition counts; low energy availability is highly prevalent | E9: Cap skill repetitions and pointe minutes; build in off-season; screen energy availability and menstrual status routinely; progress pointe readiness by criteria not age
A10: Rowing | B10: Repetitive rib loading through the drive phase; high ergometer volume | C10: Ribs (posterolateral 4-9), lumbar spine, sacrum | D10: Ergometer volume blocks; poor stroke sequencing with early trunk opening; rig changes | E10: Cap ergometer volume in favour of on-water work; correct sequencing; screen energy availability routinely in this population
A11: Military & occupational recruits | B11: High-volume marching with load carriage on hard surfaces | C11: Femoral neck, calcaneus, metatarsals, tibia, pubic ramus | D11: Rapid escalation from a sedentary baseline; boot fit; load carriage weight; hard surfaces | E11: Graded entry programme; progressive load carriage; footwear and insole provision; early reporting culture for shin and groin pain
A12: Racquet sport (tennis, badminton, squash) | B12: Repetitive serve extension and rotation; forearm load; court cutting | C12: Lumbar pars, ulna, tibia; meniscal and chondral injury from cutting | D12: Tournament congestion; grip size and string tension; double-handed backhand load; court surface | E12: Monitor serve and match volume; review grip size and string tension; cap consecutive tournament days
A13: Pickleball & recreational court sport | B13: Rapid lateral movement and deceleration in a frequently deconditioned or older population | C13: Meniscal tears (degenerative and traumatic), chondral lesions, metatarsal and calcaneal BSI | D13: Rapid uptake with high weekly play volume from a low baseline; court shoe absent; age-related tissue change | E13: Graded entry to weekly play hours; proper court footwear; build quadriceps and hip capacity before increasing play volume; expect degenerative meniscal presentations in this group and manage them conservatively

Sheet Load Rules
A1: TRAINING-LOAD RULES & THRESHOLDS
A2: Pragmatic ceilings, not proven laws. Use alongside symptoms, never instead of them.
A3: Rule / Metric | B3: Definition | C3: Target or Threshold | D3: Practical Note
A4: Acute:chronic workload ratio (ACWR) | B4: Acute (7-day) load divided by chronic (rolling 28-day average) load | C4: Sweet spot approximately 0.8-1.3; risk rises above 1.5 | D4: Use the calculator sheet. Treat it as one signal among several, not a rule — the evidence is contested and it should not override symptoms
A5: Weekly volume progression | B5: Increase total volume by no more than 10-15% per week | C5: A pragmatic ceiling rather than a proven threshold | D5: Especially important when returning from a BSI or after any lay-off
A6: Return to run after BSI | B6: Restart at approximately 50% of pre-injury volume | C6: Walk-run intervals before continuous running | D6: Add speed and hills only in the final phase
A7: Jump counts | B7: Count take-offs and landings as the load metric in jump sport | C7: Progress via the plyometric ladder | D7: Bilateral low → bilateral high → unilateral low → unilateral high → sport
A8: Bowling workload | B8: Overs per spell, per day and per week, with mandatory rest days | C8: Age-banded limits | D8: Follow current national governing-body guidance for the athlete's age group
A9: Hard-easy alternation | B9: Avoid consecutive high-impact days | C9: Bone remodelling needs a recovery window | D9: 48 hours between high-impact sessions during a return
A10: Symptom window | B10: Pain ≤5/10 during loading that settles to baseline within 24 hours | C10: Applies to soft tissue and to graded cartilage loading | D10: For an ACUTE BSI the window is different — impact loading should be pain-FREE, not merely tolerable
A11: Effusion as a signal | B11: In cartilage and meniscal injury, effusion after loading is the tolerance signal | C11: Swelling that persists beyond 24 hours means the dose was too high | D11: More reliable than pain in these tissues
A13: IMPORTANT CAVEATS
A14: • The acute:chronic workload ratio is contested in the literature. It is a useful conversation tool and a spike detector, not a rule that overrides what the athlete reports.
A15: • For an ACUTE bone stress injury, impact loading must be pain-FREE. The usual soft-tissue window of "≤5/10 settling within 24 hours" does not apply and applying it prolongs the injury.
A16: • Never add volume and intensity in the same week.
A17: • Downhill running and plyometric landings load bone heavily — add them last.

Sheet Load Calculator
A1: ACUTE:CHRONIC WORKLOAD CALCULATOR
A2: Enter a weekly load figure in the yellow column. Chronic load, ACWR and the risk flag calculate automatically.
A4: Load metric used (e.g. weekly km, total jumps, overs bowled, sRPE minutes) | D4: Weekly running km
A6: Week | B6: Acute load (this week) | C6: Chronic load (4-wk avg) | D6: ACWR | E6: Flag | F6: Interpretation
A7: 1 | B7: 40 | C7: =IF(COUNT($B$7:B7)=0,"",AVERAGE($B$7:B7)) -> 40 | D7: =IF(OR(C7="",N(C7)=0,B7=""),"",B7/C7) -> 1 | E7: =IF(D7="","",IF(D7>$C$22,"SPIKE",IF(D7<$C$23,"DETRAINING","OK"))) -> OK | F7: =IF(E7="","",IF(E7="SPIKE","Load rose faster than the athlete has adapted to — hold or reduce this week",IF(E7="DETRAINING","Load has dropped below the chronic base — capacity is being lost","Within the target range"))) -> Within the target range
A8: 2 | B8: 44 | C8: =IF(COUNT($B$7:B8)=0,"",AVERAGE($B$7:B8)) -> 42 | D8: =IF(OR(C8="",N(C8)=0,B8=""),"",B8/C8) -> 1.047619 | E8: =IF(D8="","",IF(D8>$C$22,"SPIKE",IF(D8<$C$23,"DETRAINING","OK"))) -> OK | F8: =IF(E8="","",IF(E8="SPIKE","Load rose faster than the athlete has adapted to — hold or reduce this week",IF(E8="DETRAINING","Load has dropped below the chronic base — capacity is being lost","Within the target range"))) -> Within the target range
A9: 3 | B9: 46 | C9: =IF(COUNT($B$7:B9)=0,"",AVERAGE($B$7:B9)) -> 43.333333 | D9: =IF(OR(C9="",N(C9)=0,B9=""),"",B9/C9) -> 1.0615385 | E9: =IF(D9="","",IF(D9>$C$22,"SPIKE",IF(D9<$C$23,"DETRAINING","OK"))) -> OK | F9: =IF(E9="","",IF(E9="SPIKE","Load rose faster than the athlete has adapted to — hold or reduce this week",IF(E9="DETRAINING","Load has dropped below the chronic base — capacity is being lost","Within the target range"))) -> Within the target range
A10: 4 | B10: 48 | C10: =IF(COUNT(B7:B10)<4,"",AVERAGE(B7:B10)) -> 44.5 | D10: =IF(OR(C10="",N(C10)=0,B10=""),"",B10/C10) -> 1.0786517 | E10: =IF(D10="","",IF(D10>$C$22,"SPIKE",IF(D10<$C$23,"DETRAINING","OK"))) -> OK | F10: =IF(E10="","",IF(E10="SPIKE","Load rose faster than the athlete has adapted to — hold or reduce this week",IF(E10="DETRAINING","Load has dropped below the chronic base — capacity is being lost","Within the target range"))) -> Within the target range
A11: 5 | B11: 52 | C11: =IF(COUNT(B8:B11)<4,"",AVERAGE(B8:B11)) -> 47.5 | D11: =IF(OR(C11="",N(C11)=0,B11=""),"",B11/C11) -> 1.0947368 | E11: =IF(D11="","",IF(D11>$C$22,"SPIKE",IF(D11<$C$23,"DETRAINING","OK"))) -> OK | F11: =IF(E11="","",IF(E11="SPIKE","Load rose faster than the athlete has adapted to — hold or reduce this week",IF(E11="DETRAINING","Load has dropped below the chronic base — capacity is being lost","Within the target range"))) -> Within the target range
A12: 6 | C12: =IF(COUNT(B9:B12)<4,"",AVERAGE(B9:B12)) | D12: =IF(OR(C12="",N(C12)=0,B12=""),"",B12/C12) | E12: =IF(D12="","",IF(D12>$C$22,"SPIKE",IF(D12<$C$23,"DETRAINING","OK"))) | F12: =IF(E12="","",IF(E12="SPIKE","Load rose faster than the athlete has adapted to — hold or reduce this week",IF(E12="DETRAINING","Load has dropped below the chronic base — capacity is being lost","Within the target range")))
A13: 7 | C13: =IF(COUNT(B10:B13)<4,"",AVERAGE(B10:B13)) | D13: =IF(OR(C13="",N(C13)=0,B13=""),"",B13/C13) | E13: =IF(D13="","",IF(D13>$C$22,"SPIKE",IF(D13<$C$23,"DETRAINING","OK"))) | F13: =IF(E13="","",IF(E13="SPIKE","Load rose faster than the athlete has adapted to — hold or reduce this week",IF(E13="DETRAINING","Load has dropped below the chronic base — capacity is being lost","Within the target range")))
A14: 8 | C14: =IF(COUNT(B11:B14)<4,"",AVERAGE(B11:B14)) | D14: =IF(OR(C14="",N(C14)=0,B14=""),"",B14/C14) | E14: =IF(D14="","",IF(D14>$C$22,"SPIKE",IF(D14<$C$23,"DETRAINING","OK"))) | F14: =IF(E14="","",IF(E14="SPIKE","Load rose faster than the athlete has adapted to — hold or reduce this week",IF(E14="DETRAINING","Load has dropped below the chronic base — capacity is being lost","Within the target range")))
A15: 9 | C15: =IF(COUNT(B12:B15)<4,"",AVERAGE(B12:B15)) | D15: =IF(OR(C15="",N(C15)=0,B15=""),"",B15/C15) | E15: =IF(D15="","",IF(D15>$C$22,"SPIKE",IF(D15<$C$23,"DETRAINING","OK"))) | F15: =IF(E15="","",IF(E15="SPIKE","Load rose faster than the athlete has adapted to — hold or reduce this week",IF(E15="DETRAINING","Load has dropped below the chronic base — capacity is being lost","Within the target range")))
A16: 10 | C16: =IF(COUNT(B13:B16)<4,"",AVERAGE(B13:B16)) | D16: =IF(OR(C16="",N(C16)=0,B16=""),"",B16/C16) | E16: =IF(D16="","",IF(D16>$C$22,"SPIKE",IF(D16<$C$23,"DETRAINING","OK"))) | F16: =IF(E16="","",IF(E16="SPIKE","Load rose faster than the athlete has adapted to — hold or reduce this week",IF(E16="DETRAINING","Load has dropped below the chronic base — capacity is being lost","Within the target range")))
A17: 11 | C17: =IF(COUNT(B14:B17)<4,"",AVERAGE(B14:B17)) | D17: =IF(OR(C17="",N(C17)=0,B17=""),"",B17/C17) | E17: =IF(D17="","",IF(D17>$C$22,"SPIKE",IF(D17<$C$23,"DETRAINING","OK"))) | F17: =IF(E17="","",IF(E17="SPIKE","Load rose faster than the athlete has adapted to — hold or reduce this week",IF(E17="DETRAINING","Load has dropped below the chronic base — capacity is being lost","Within the target range")))
A18: 12 | C18: =IF(COUNT(B15:B18)<4,"",AVERAGE(B15:B18)) | D18: =IF(OR(C18="",N(C18)=0,B18=""),"",B18/C18) | E18: =IF(D18="","",IF(D18>$C$22,"SPIKE",IF(D18<$C$23,"DETRAINING","OK"))) | F18: =IF(E18="","",IF(E18="SPIKE","Load rose faster than the athlete has adapted to — hold or reduce this week",IF(E18="DETRAINING","Load has dropped below the chronic base — capacity is being lost","Within the target range")))
A22: Upper ACWR threshold (spike) | C22: 1.3 | D22: Risk rises above approximately 1.5; 1.3 is a conservative working ceiling
A23: Lower ACWR threshold (detraining) | C23: 0.8 | D23: Below this the athlete is losing chronic capacity
A25: Weeks flagged as a spike | C25: =COUNTIF(E7:E18,"SPIKE") -> 0
A26: Weeks flagged as detraining | C26: =COUNTIF(E7:E18,"DETRAINING") -> 0
A27: Largest week-on-week increase | C27: =IF(COUNT(B7:B18)<2,"",SUMPRODUCT(MAX((B8:B18>0)*(B7:B17>0)*(B8:B18-B7:B17)/IF(B7:B17=0,1,B7:B17)))) -> #VALUE!
A29: HOW TO USE THIS CALCULATOR
A30: • Enter one figure per week in the yellow column B — use whichever metric matches the sport (weekly km, total jumps, overs bowled, session-RPE minutes). Be consistent.
A31: • Chronic load is a rolling 4-week average; the first three weeks use whatever data exist, so treat early ACWR values as indicative only.
A32: • Thresholds in C22 and C23 are editable. The default ceiling of 1.30 is deliberately conservative for an athlete returning from a bone stress injury.
A33: • ACWR is a spike detector and a conversation tool, not a rule. A "SPIKE" flag means look at the week and ask why — it does not by itself mean stop.
A34: • Example values are pre-filled in weeks 1-5 to show the expected format. Overwrite them.

Sheet Return to Run
A1: GRADED RETURN-TO-RUN PROGRAMME
A2: For lower-limb bone stress injury. Do not begin until every entry-gate criterion in Stage 0 is met.
A3: Stage | B3: Focus | C3: Session Content | D3: Running Volume | E3: Progression Rule
A4: Stage 0 | B4: Gate to enter | C4: Pain-free walking for 30 minutes AND pain-free single-leg hop x10 AND no focal bony tenderness | D4: — | E4: Do not begin until all three are met
A5: Stage 1 | B5: Walk-run intervals | C5: 1 min run / 4 min walk x 6, alternate days | D5: Approx. 6 min running | E5: Progress only if pain-free during and for 24 hours after
A6: Stage 2 | B6: Walk-run intervals | C6: 2 min run / 3 min walk x 6, alternate days | D6: Approx. 12 min running | E6: Any focal pain = drop back one stage
A7: Stage 3 | B7: Walk-run intervals | C7: 4 min run / 2 min walk x 5, alternate days | D7: Approx. 20 min running | E7: Add calf and gluteal loading on non-running days
A8: Stage 4 | B8: Continuous running | C8: 20 min continuous, alternate days | D8: 20 min | E8: Hold for at least 2 sessions before progressing
A9: Stage 5 | B9: Volume build | C9: Increase continuous time by 10-15% per week | D9: 25-40 min | E9: Keep ACWR between 0.8 and 1.3
A10: Stage 6 | B10: Introduce intensity | C10: Add strides, then tempo work — one quality session per week | D10: Volume held constant | E10: Never add volume and intensity in the same week
A11: Stage 7 | B11: Introduce terrain | C11: Add hills and undulating surfaces | D11: Volume held constant | E11: Downhill running loads the tibia heavily — add last
A12: Stage 8 | B12: Sport-specific | C12: Change of direction, sprint work, full training | D12: Sport demands | E12: Criteria-based clearance before competition
A14: RULES THAT APPLY AT EVERY STAGE
A15: • The rule at every stage: impact loading must be PAIN-FREE, both during the session and for the 24 hours after. Any focal bony pain means drop back one stage.
A16: • Run on alternate days through stages 1-4. Bone remodelling needs the recovery day.
A17: • Maintain calf, gluteal and foot intrinsic strengthening on non-running days throughout.
A18: • Never add volume and intensity in the same week. Hills and downhill running come last because they load the tibia most.
A19: • Track weekly volume in the Load Calculator sheet and keep the ACWR under 1.30 during the return.
A20: • High-risk-site injuries (navicular, femoral neck, anterior tibial cortex, fifth metatarsal) enter this programme only after explicit orthopaedic clearance.

Sheet Rx Generator
A1: PRESCRIPTION GENERATOR
A2: Select a condition in the yellow cell. Every field is pulled live from the Master Matrix.
A4: SELECT CONDITION → | B4: Meniscal root tear
A6: Tissue | B6: =IFERROR(INDEX('Master Matrix'!A$4:A$42,MATCH($B$4,'Master Matrix'!$B$4:$B$42,0)),"") -> Meniscus
A7: RISK CLASS | B7: =IFERROR(INDEX('Master Matrix'!C$4:C$42,MATCH($B$4,'Master Matrix'!$B$4:$B$42,0)),"") -> SURGICAL URGENCY
A8: Sport & load pattern | B8: =IFERROR(INDEX('Master Matrix'!D$4:D$42,MATCH($B$4,'Master Matrix'!$B$4:$B$42,0)),"") -> Deep squatting and floor-rising load; also acute in athletes
A9: Athlete profile | B9: =IFERROR(INDEX('Master Matrix'!E$4:E$42,MATCH($B$4,'Master Matrix'!$B$4:$B$42,0)),"") -> Middle-aged patient with deep-squat habits; or a young athlete with a concurrent ACL injury
A10: Hallmark presentation | B10: =IFERROR(INDEX('Master Matrix'!F$4:F$42,MATCH($B$4,'Master Matrix'!$B$4:$B$42,0)),"") -> Sudden posteromedial pain during a simple squat or getting up from the floor, often with an audible pop; rapid effusion
A11: Discriminating question | B11: =IFERROR(INDEX('Master Matrix'!G$4:G$42,MATCH($B$4,'Master Matrix'!$B$4:$B$42,0)),"") -> Did the pain start suddenly during an ordinary squat or getting up off the floor?
A12: Key examination findings | B12: =IFERROR(INDEX('Master Matrix'!H$4:H$42,MATCH($B$4,'Master Matrix'!$B$4:$B$42,0)),"") -> Posteromedial joint-line tenderness; effusion; pain on deep flexion; often surprisingly few mechanical symptoms
A13: Confirmatory imaging | B13: =IFERROR(INDEX('Master Matrix'!I$4:I$42,MATCH($B$4,'Master Matrix'!$B$4:$B$42,0)),"") -> MRI (ghost sign, meniscal extrusion on coronal views)
A14: Grading / classification | B14: =IFERROR(INDEX('Master Matrix'!J$4:J$42,MATCH($B$4,'Master Matrix'!$B$4:$B$42,0)),"") -> Root avulsion — functionally equivalent to a total meniscectomy if untreated
A15: LOAD & BIOMECHANICAL DRIVER | B15: =IFERROR(INDEX('Master Matrix'!K$4:K$42,MATCH($B$4,'Master Matrix'!$B$4:$B$42,0)),"") -> Failure of hoop tension under high compressive and shear load in deep flexion; degenerative meniscus, varus malalignment, raised body mass, weak quadriceps and gluteals, and a squat or floor-rising strategy that loads deep knee flexion instead of hip and ankle
A16: Non-mechanical contributors | B16: =IFERROR(INDEX('Master Matrix'!L$4:L$42,MATCH($B$4,'Master Matrix'!$B$4:$B$42,0)),"") -> Raised body mass, degenerative change, varus malalignment
A17: MANAGEMENT EMPHASIS | B17: =IFERROR(INDEX('Master Matrix'!M$4:M$42,MATCH($B$4,'Master Matrix'!$B$4:$B$42,0)),"") -> PROMPT surgical opinion — root repair preserves hoop tension and slows compartment degeneration in suitable candidates (younger, correctable alignment, limited cartilage loss). This is a time-sensitive opportunity that is routinely missed
A18: WEIGHT-BEARING / PROTECTION STATUS | B18: =IFERROR(INDEX('Master Matrix'!N$4:N$42,MATCH($B$4,'Master Matrix'!$B$4:$B$42,0)),"") -> Post-repair: protected or non-weight bearing with restricted flexion for approximately 6 weeks per surgeon
A19: Loading progression & dose | B19: =IFERROR(INDEX('Master Matrix'!O$4:O$42,MATCH($B$4,'Master Matrix'!$B$4:$B$42,0)),"") -> Post-repair: protected range and weight bearing → progressive quadriceps and hip loading in shallow flexion → deeper flexion → functional loading
A20: BIOMECHANICAL & TECHNIQUE CORRECTIONS | B20: =IFERROR(INDEX('Master Matrix'!P$4:P$42,MATCH($B$4,'Master Matrix'!$B$4:$B$42,0)),"") -> Take load out of deep flexion: retrain floor-rising and squat strategy to a hip-dominant pattern, restore ankle dorsiflexion and hip mobility, strengthen quadriceps and gluteals, correct varus malalignment with wedging or an unloader brace, support weight management
A21: TRAINING-LOAD PRESCRIPTION | B21: =IFERROR(INDEX('Master Matrix'!Q$4:Q$42,MATCH($B$4,'Master Matrix'!$B$4:$B$42,0)),"") -> Zero deep-flexion loading for 6 weeks; graded return over 4-6 months with squat depth progressed last
A22: Adjuncts / advanced options | B22: =IFERROR(INDEX('Master Matrix'!R$4:R$42,MATCH($B$4,'Master Matrix'!$B$4:$B$42,0)),"") -> Root repair; concurrent high tibial osteotomy where varus malalignment coexists
A23: Re-test markers & outcomes | B23: =IFERROR(INDEX('Master Matrix'!S$4:S$42,MATCH($B$4,'Master Matrix'!$B$4:$B$42,0)),"") -> Effusion; deep flexion pain and range; floor-rise ability; quadriceps LSI
A24: Timeline to return to sport | B24: =IFERROR(INDEX('Master Matrix'!T$4:T$42,MATCH($B$4,'Master Matrix'!$B$4:$B$42,0)),"") -> 4-6 months
A25: Referral / surgical trigger | B25: =IFERROR(INDEX('Master Matrix'!U$4:U$42,MATCH($B$4,'Master Matrix'!$B$4:$B$42,0)),"") -> Acute root tear with preserved cartilage and correctable alignment → prompt referral
A26: Consequence if missed | B26: =IFERROR(INDEX('Master Matrix'!V$4:V$42,MATCH($B$4,'Master Matrix'!$B$4:$B$42,0)),"") -> Rapid meniscal extrusion, loss of load distribution and accelerated osteoarthritis — equivalent to having no meniscus
A27: Evidence anchor | B27: =IFERROR(INDEX('Master Matrix'!W$4:W$42,MATCH($B$4,'Master Matrix'!$B$4:$B$42,0)),"") -> Meniscal root repair literature; post-surgical protection guide (category 2)
A29: NOTES
A30: • Green text is pulled from the Master Matrix — edit the matrix, not this sheet.
A31: • Check the RISK CLASS field first. HIGH RISK or SURGICAL URGENCY means refer before rehabilitating.
A32: • Print this sheet (fit to one page wide) to drop a management plan straight into the patient file.

Sheet Progress Tracker
A1: PROGRESS TRACKER & RETURN-TO-SPORT CALCULATOR
A2: Enter values in the yellow cells only. Entry gates, limb symmetry and readiness status calculate automatically.
A4: PATIENT & CASE DETAILS
A5: Patient ID / initials | B5: e.g. PR-021 | F5: Risk class / management emphasis:
A6: Condition (as listed in Master Matrix) | B6: Tibia — posteromedial (compression side) | F6: =IFERROR(INDEX('Master Matrix'!C$4:C$42,MATCH($B$6,'Master Matrix'!$B$4:$B$42,0))&" — "&INDEX('Master Matrix'!M$4:M$42,MATCH($B$6,'Master Matrix'!$B$4:$B$42,0)),"Enter a condition exactly as listed in the Master Matrix") -> Low risk — Relative rest from impact until pain-free walking and hopping, then a structured graded return-to-run programme; correct the load error that caused it — this is the whole intervention
A7: Sport / load metric used | B7: Distance running — weekly km
A8: Assessment date
A10: ENTRY GATES — ALL MUST READ YES BEFORE IMPACT LOADING BEGINS
A11: Gate | B11: YES / NO | G11: Why it matters
A12: No focal bony tenderness at the injury site | B12: NO | G12: The most sensitive clinical sign that the lesion is still active
A13: Pain-free walking for 30 minutes | B13: NO | G13: Walking must be comfortable before running is even considered
A14: Pain-free single-leg hop x10 | B14: NO | G14: The functional gate for impact readiness
A15: Orthopaedic clearance obtained (HIGH RISK sites only) | B15: NO | G15: Mandatory for navicular, femoral neck, anterior tibial cortex, fifth metatarsal, talus, medial malleolus, sesamoid, patella, second metatarsal base and pars lesions
A16: CLEARED TO BEGIN IMPACT LOADING? → | C16: =IF(COUNTIF(B12:B15,"YES")=4,"YES — begin the Return-to-Run programme at Stage 1","NO — continue non-impact loading; gates outstanding") -> NO — continue non-impact loading; gates outstanding
A18: CAPACITY — LIMB SYMMETRY INDEX
A19: Measure | B19: Involved | C19: Uninvolved | D19: Unit | E19: LSI | F19: Status | G19: Note
A20: Calf endurance (single-leg heel raises) | B20: 18 | C20: 25 | D20: reps | E20: =IF(N(C20)=0,"",B20/C20) -> 0.72 | F20: =IF(E20="","",IF(E20>=$B$35,"PASS","NOT YET")) -> NOT YET
A21: Quadriceps strength | D21: kg | E21: =IF(N(C21)=0,"",B21/C21) | F21: =IF(E21="","",IF(E21>=$B$35,"PASS","NOT YET"))
A22: Hip abductor strength | D22: kg | E22: =IF(N(C22)=0,"",B22/C22) | F22: =IF(E22="","",IF(E22>=$B$35,"PASS","NOT YET"))
A23: Single hop for distance | D23: cm | E23: =IF(N(C23)=0,"",B23/C23) | F23: =IF(E23="","",IF(E23>=$B$35,"PASS","NOT YET"))
A24: Triple hop for distance | D24: cm | E24: =IF(N(C24)=0,"",B24/C24) | F24: =IF(E24="","",IF(E24>=$B$35,"PASS","NOT YET"))
A26: LOAD TOLERANCE
A27: Marker | B27: Baseline | C27: Current | D27: Unit | E27: Change | F27: % Change | G27: Direction of improvement
